-- Duane's mapgen default_biomes.lua

-- This information was adapted from Minetest Game, distributed
--  under the LGPLv2.1, and copyrighted by:

-- Originally by celeron55, Perttu Ahola <celeron55@gmail.com> (LGPLv2.1+)
-- Various Minetest developers and contributors (LGPLv2.1+)


local mod = mapgen
local mod_name = 'mapgen'


mod.register_biome({
	y_min = 4,
	source = "default",
	node_dust = "default:snow",
	depth_filler = 3,
	node_filler = "default:dirt",
	depth_top = 1,
	y_max = 31000,
	name = "taiga",
	node_top = "default:dirt_with_snow",
	node_riverbed = "default:sand",
	heat_point = 25,
	depth_riverbed = 2,
	humidity_point = 70
})
mod.register_biome({
	humidity_point = 50,
	name = "underground",
	source = "default",
	y_min = -31000,
	y_max = -113,
	heat_point = 50
})
mod.register_biome({
	y_min = -112,
	source = "default",
	depth_filler = 3,
	vertical_blend = 1,
	node_filler = "default:sand",
	depth_top = 1,
	humidity_point = 65,
	heat_point = 86,
	node_top = "default:sand",
	node_riverbed = "default:sand",
	y_max = -2,
	depth_riverbed = 2,
	name = "rainforest_ocean"
})
mod.register_biome({
	y_min = -8,
	depth_water_top = 10,
	node_dust = "default:snowblock",
	depth_filler = 3,
	node_filler = "default:snowblock",
	depth_top = 1,
	node_top = "default:snowblock",
	node_water_top = "default:ice",
	node_river_water = "default:ice",
	node_stone = "default:cave_ice",
	y_max = 31000,
	heat_point = 0,
	source = "default",
	node_riverbed = "default:gravel",
	humidity_point = 73,
	depth_riverbed = 2,
	name = "icesheet"
})
mod.register_biome({
	y_min = -112,
	source = "default",
	depth_filler = 3,
	node_filler = "default:sand",
	humidity_point = 35,
	y_max = 3,
	name = "grassland_ocean",
	node_top = "default:sand",
	node_riverbed = "default:sand",
	heat_point = 50,
	depth_riverbed = 2,
	depth_top = 1
})
mod.register_biome({
	y_min = 4,
	node_stone = "default:desert_stone",
	depth_filler = 1,
	source = "default",
	node_filler = "default:desert_sand",
	depth_top = 1,
	y_max = 31000,
	name = "desert",
	node_top = "default:desert_sand",
	node_riverbed = "default:sand",
	heat_point = 92,
	depth_riverbed = 2,
	humidity_point = 16
})
mod.register_biome({
	y_min = -112,
	source = "default",
	depth_filler = 3,
	vertical_blend = 1,
	node_filler = "default:sand",
	depth_top = 1,
	humidity_point = 40,
	heat_point = 0,
	node_top = "default:sand",
	node_riverbed = "default:gravel",
	y_max = -4,
	depth_riverbed = 2,
	name = "tundra_ocean"
})
mod.register_biome({
	y_min = -112,
	node_stone = "default:desert_stone",
	source = "default",
	depth_filler = 3,
	vertical_blend = 1,
	node_filler = "default:sand",
	depth_top = 1,
	humidity_point = 16,
	heat_point = 92,
	node_top = "default:sand",
	node_riverbed = "default:sand",
	y_max = 3,
	depth_riverbed = 2,
	name = "desert_ocean"
})
mod.register_biome({
	y_min = -112,
	depth_water_top = 10,
	node_dust = "default:snowblock",
	depth_filler = 3,
	node_filler = "default:sand",
	depth_top = 1,
	source = "default",
	name = "icesheet_ocean",
	node_top = "default:sand",
	node_water_top = "default:ice",
	y_max = -9,
	heat_point = 0,
	humidity_point = 73
})
mod.register_biome({
	y_min = -1,
	source = "default",
	depth_filler = 3,
	node_filler = "default:dirt",
	humidity_point = 65,
	y_max = 0,
	name = "rainforest_swamp",
	node_top = "default:dirt",
	node_riverbed = "default:sand",
	heat_point = 86,
	depth_riverbed = 2,
	depth_top = 1
})
mod.register_biome({
	y_min = 2,
	source = "default",
	depth_filler = 1,
	vertical_blend = 4,
	node_filler = "default:permafrost",
	depth_top = 1,
	humidity_point = 40,
	heat_point = 0,
	node_top = "default:permafrost_with_stones",
	node_riverbed = "default:gravel",
	y_max = 46,
	depth_riverbed = 2,
	name = "tundra"
})
mod.register_biome({
	y_min = 1,
	source = "default",
	depth_filler = 3,
	node_filler = "default:dirt",
	humidity_point = 65,
	y_max = 31000,
	name = "rainforest",
	node_top = "default:dirt_with_rainforest_litter",
	node_riverbed = "default:sand",
	heat_point = 86,
	depth_riverbed = 2,
	depth_top = 1
})
mod.register_biome({
	y_min = -112,
	source = "default",
	depth_filler = 3,
	vertical_blend = 1,
	node_filler = "default:sand",
	depth_top = 1,
	humidity_point = 0,
	heat_point = 40,
	node_top = "default:sand",
	node_riverbed = "default:sand",
	y_max = 3,
	depth_riverbed = 2,
	name = "cold_desert_ocean"
})
mod.register_biome({
	y_min = 4,
	source = "default",
	node_dust = "default:snow",
	depth_filler = 1,
	node_filler = "default:dirt",
	depth_top = 1,
	y_max = 31000,
	name = "snowy_grassland",
	node_top = "default:dirt_with_snow",
	node_riverbed = "default:sand",
	heat_point = 20,
	depth_riverbed = 2,
	humidity_point = 35
})
mod.register_biome({
	y_min = 1,
	source = "default",
	depth_filler = 1,
	node_filler = "default:dirt",
	humidity_point = 42,
	y_max = 31000,
	name = "savanna",
	node_top = "default:dirt_with_dry_grass",
	node_riverbed = "default:sand",
	heat_point = 89,
	depth_riverbed = 2,
	depth_top = 1
})
mod.register_biome({
	y_min = -112,
	source = "default",
	depth_filler = 3,
	vertical_blend = 1,
	node_filler = "default:sand",
	depth_top = 1,
	humidity_point = 42,
	heat_point = 89,
	node_top = "default:sand",
	node_riverbed = "default:sand",
	y_max = -2,
	depth_riverbed = 2,
	name = "savanna_ocean"
})
mod.register_biome({
	y_min = 6,
	source = "default",
	depth_filler = 3,
	node_filler = "default:dirt",
	humidity_point = 70,
	y_max = 31000,
	name = "coniferous_forest",
	node_top = "default:dirt_with_coniferous_litter",
	node_riverbed = "default:sand",
	heat_point = 45,
	depth_riverbed = 2,
	depth_top = 1
})
mod.register_biome({
	y_min = 4,
	source = "default",
	depth_filler = 1,
	node_filler = "default:silver_sand",
	humidity_point = 0,
	y_max = 31000,
	name = "cold_desert",
	node_top = "default:silver_sand",
	node_riverbed = "default:sand",
	heat_point = 40,
	depth_riverbed = 2,
	depth_top = 1
})
mod.register_biome({
	y_min = 4,
	source = "default",
	depth_filler = 2,
	vertical_blend = 1,
	node_filler = "default:sand",
	depth_top = 1,
	humidity_point = 35,
	heat_point = 50,
	node_top = "default:sand",
	node_riverbed = "default:sand",
	y_max = 5,
	depth_riverbed = 2,
	name = "grassland_dunes"
})
mod.register_biome({
	y_min = -112,
	node_stone = "default:sandstone",
	depth_filler = 3,
	source = "default",
	node_filler = "default:sand",
	depth_top = 1,
	y_max = 3,
	name = "sandstone_desert_ocean",
	node_top = "default:sand",
	node_riverbed = "default:sand",
	heat_point = 60,
	depth_riverbed = 2,
	humidity_point = 0
})
mod.register_biome({
	y_min = 4,
	source = "default",
	depth_filler = 3,
	vertical_blend = 1,
	node_filler = "default:sand",
	depth_top = 1,
	humidity_point = 70,
	heat_point = 45,
	node_top = "default:sand",
	node_riverbed = "default:sand",
	y_max = 5,
	depth_riverbed = 2,
	name = "coniferous_forest_dunes"
})
mod.register_biome({
	y_min = -112,
	source = "default",
	depth_filler = 3,
	node_filler = "default:sand",
	humidity_point = 70,
	y_max = 3,
	name = "coniferous_forest_ocean",
	node_top = "default:sand",
	node_riverbed = "default:sand",
	heat_point = 45,
	depth_riverbed = 2,
	depth_top = 1
})
mod.register_biome({
	y_min = 1,
	source = "default",
	depth_filler = 3,
	node_filler = "default:dirt",
	humidity_point = 68,
	y_max = 31000,
	name = "deciduous_forest",
	node_top = "default:dirt_with_grass",
	node_riverbed = "default:sand",
	heat_point = 60,
	depth_riverbed = 2,
	depth_top = 1
})
mod.register_biome({
	y_min = 4,
	node_stone = "default:sandstone",
	depth_filler = 1,
	source = "default",
	node_filler = "default:sand",
	depth_top = 1,
	y_max = 31000,
	name = "sandstone_desert",
	node_top = "default:sand",
	node_riverbed = "default:sand",
	heat_point = 60,
	depth_riverbed = 2,
	humidity_point = 0
})
mod.register_biome({
	y_min = -3,
	source = "default",
	depth_filler = 2,
	vertical_blend = 1,
	node_filler = "default:gravel",
	depth_top = 1,
	humidity_point = 40,
	heat_point = 0,
	node_top = "default:gravel",
	node_riverbed = "default:gravel",
	y_max = 1,
	depth_riverbed = 2,
	name = "tundra_beach"
})
mod.register_biome({
	y_min = -1,
	source = "default",
	depth_filler = 3,
	node_filler = "default:dirt",
	humidity_point = 68,
	y_max = 0,
	name = "deciduous_forest_shore",
	node_top = "default:dirt",
	node_riverbed = "default:sand",
	heat_point = 60,
	depth_riverbed = 2,
	depth_top = 1
})
mod.register_biome({
	y_min = 6,
	source = "default",
	depth_filler = 1,
	node_filler = "default:dirt",
	humidity_point = 35,
	y_max = 31000,
	name = "grassland",
	node_top = "default:dirt_with_grass",
	node_riverbed = "default:sand",
	heat_point = 50,
	depth_riverbed = 2,
	depth_top = 1
})
mod.register_biome({
	y_min = -1,
	source = "default",
	depth_filler = 3,
	node_filler = "default:dirt",
	humidity_point = 42,
	y_max = 0,
	name = "savanna_shore",
	node_top = "default:dirt",
	node_riverbed = "default:sand",
	heat_point = 89,
	depth_riverbed = 2,
	depth_top = 1
})
mod.register_biome({
	y_min = -112,
	source = "default",
	depth_filler = 3,
	vertical_blend = 1,
	node_filler = "default:sand",
	depth_top = 1,
	humidity_point = 68,
	heat_point = 60,
	node_top = "default:sand",
	node_riverbed = "default:sand",
	y_max = -2,
	depth_riverbed = 2,
	name = "deciduous_forest_ocean"
})
mod.register_biome({
	y_min = -112,
	source = "default",
	node_dust = "default:snow",
	depth_filler = 3,
	vertical_blend = 1,
	node_filler = "default:sand",
	humidity_point = 70,
	name = "taiga_ocean",
	heat_point = 25,
	node_top = "default:sand",
	node_riverbed = "default:sand",
	y_max = 3,
	depth_riverbed = 2,
	depth_top = 1
})
mod.register_biome({
	y_min = -112,
	source = "default",
	node_dust = "default:snow",
	depth_filler = 3,
	vertical_blend = 1,
	node_filler = "default:sand",
	humidity_point = 35,
	name = "snowy_grassland_ocean",
	heat_point = 20,
	node_top = "default:sand",
	node_riverbed = "default:sand",
	y_max = 3,
	depth_riverbed = 2,
	depth_top = 1
})
mod.register_decoration({
	y_min = -1,
	biomes = {
		"rainforest",
		"rainforest_swamp"
	},
	schematic = mod.path.."/schematics/jungle_tree.mts",
	y_max = 31000,
	source = "default",
	rotation = "random",
	place_on = {
		"default:dirt_with_rainforest_litter",
		"default:dirt"
	},
	name = "default:jungle_tree",
	fill_ratio = 0.1,
	sidelen = 80,
	deco_type = "schematic",
	flags = "place_center_x, place_center_z",
	schematic_array = {
		yslice_prob = {
			{
				prob = 254,
				ypos = 0
			},
			{
				prob = 254,
				ypos = 1
			},
			{
				prob = 254,
				ypos = 2
			},
			{
				prob = 254,
				ypos = 3
			},
			{
				prob = 254,
				ypos = 4
			},
			{
				prob = 254,
				ypos = 5
			},
			{
				prob = 190,
				ypos = 6
			},
			{
				prob = 190,
				ypos = 7
			},
			{
				prob = 190,
				ypos = 8
			},
			{
				prob = 190,
				ypos = 9
			},
			{
				prob = 190,
				ypos = 10
			},
			{
				prob = 254,
				ypos = 11
			},
			{
				prob = 254,
				ypos = 12
			},
			{
				prob = 254,
				ypos = 13
			},
			{
				prob = 254,
				ypos = 14
			},
			{
				prob = 254,
				ypos = 15
			},
			{
				prob = 254,
				ypos = 16
			}
		},
		data = {
			{
				param2 = 0,
				name = "air",
				prob = 0
			},
			{
				param2 = 0,
				name = "air",
				prob = 0
			},
			{
				param2 = 0,
				name = "air",
				prob = 0
			},
			{
				param2 = 0,
				name = "air",
				prob = 0
			},
			{
				param2 = 0,
				name = "air",
				prob = 0
			},
			{
				param2 = 0,
				name = "air",
				prob = 0
			},
			{
				param2 = 0,
				name = "air",
				prob = 0
			},
			{
				param2 = 0,
				name = "air",
				prob = 0
			},
			{
				param2 = 0,
				name = "air",
				prob = 0
			},
			{
				param2 = 0,
				name = "air",
				prob = 0
			},
			{
				param2 = 0,
				name = "air",
				prob = 0
			},
			{
				param2 = 0,
				name = "air",
				prob = 0
			},
			{
				param2 = 0,
				name = "air",
				prob = 0
			},
			{
				param2 = 0,
				name = "air",
				prob = 0
			},
			{
				param2 = 0,
				name = "air",
				prob = 0
			},
			{
				param2 = 0,
				name = "air",
				prob = 0
			},
			{
				param2 = 0,
				name = "air",
				prob = 0
			},
			{
				param2 = 0,
				name = "air",
				prob = 0
			},
			{
				param2 = 0,
				name = "air",
				prob = 0
			},
			{
				param2 = 0,
				name = "air",
				prob = 0
			},
			{
				param2 = 0,
				name = "air",
				prob = 0
			},
			{
				param2 = 0,
				name = "air",
				prob = 0
			},
			{
				param2 = 0,
				name = "air",
				prob = 0
			},
			{
				param2 = 0,
				name = "air",
				prob = 0
			},
			{
				param2 = 0,
				name = "air",
				prob = 0
			},
			{
				param2 = 0,
				name = "air",
				prob = 0
			},
			{
				param2 = 0,
				name = "air",
				prob = 0
			},
			{
				param2 = 0,
				name = "air",
				prob = 0
			},
			{
				param2 = 0,
				name = "air",
				prob = 0
			},
			{
				param2 = 0,
				name = "air",
				prob = 0
			},
			{
				param2 = 0,
				name = "air",
				prob = 0
			},
			{
				param2 = 0,
				name = "air",
				prob = 0
			},
			{
				param2 = 0,
				name = "air",
				prob = 0
			},
			{
				param2 = 0,
				name = "air",
				prob = 0
			},
			{
				param2 = 0,
				name = "air",
				prob = 0
			},
			{
				param2 = 0,
				name = "air",
				prob = 0
			},
			{
				param2 = 0,
				name = "air",
				prob = 0
			},
			{
				param2 = 0,
				name = "air",
				prob = 0
			},
			{
				param2 = 0,
				name = "air",
				prob = 0
			},
			{
				param2 = 0,
				name = "air",
				prob = 0
			},
			{
				param2 = 0,
				name = "air",
				prob = 0
			},
			{
				param2 = 0,
				name = "air",
				prob = 0
			},
			{
				param2 = 0,
				name = "air",
				prob = 0
			},
			{
				param2 = 0,
				name = "air",
				prob = 0
			},
			{
				param2 = 0,
				name = "air",
				prob = 0
			},
			{
				param2 = 0,
				name = "air",
				prob = 0
			},
			{
				param2 = 0,
				name = "air",
				prob = 0
			},
			{
				param2 = 0,
				name = "air",
				prob = 0
			},
			{
				param2 = 0,
				name = "air",
				prob = 0
			},
			{
				param2 = 0,
				name = "air",
				prob = 0
			},
			{
				param2 = 0,
				name = "default:jungleleaves",
				prob = 94
			},
			{
				param2 = 0,
				name = "default:jungleleaves",
				prob = 126
			},
			{
				param2 = 0,
				name = "default:jungleleaves",
				prob = 94
			},
			{
				param2 = 0,
				name = "air",
				prob = 0
			},
			{
				param2 = 0,
				name = "air",
				prob = 0
			},
			{
				param2 = 0,
				name = "air",
				prob = 0
			},
			{
				param2 = 0,
				name = "air",
				prob = 0
			},
			{
				param2 = 0,
				name = "default:jungleleaves",
				prob = 94
			},
			{
				param2 = 0,
				name = "default:jungleleaves",
				prob = 126
			},
			{
				param2 = 0,
				name = "default:jungleleaves",
				prob = 94
			},
			{
				param2 = 0,
				name = "air",
				prob = 0
			},
			{
				param2 = 0,
				name = "air",
				prob = 0
			},
			{
				param2 = 0,
				name = "air",
				prob = 0
			},
			{
				param2 = 0,
				name = "air",
				prob = 0
			},
			{
				param2 = 0,
				name = "air",
				prob = 0
			},
			{
				param2 = 0,
				name = "air",
				prob = 0
			},
			{
				param2 = 0,
				name = "air",
				prob = 0
			},
			{
				param2 = 0,
				name = "air",
				prob = 0
			},
			{
				param2 = 0,
				name = "air",
				prob = 0
			},
			{
				param2 = 0,
				name = "air",
				prob = 0
			},
			{
				param2 = 0,
				name = "default:jungleleaves",
				prob = 62
			},
			{
				param2 = 0,
				name = "default:jungleleaves",
				prob = 94
			},
			{
				param2 = 0,
				name = "default:jungleleaves",
				prob = 94
			},
			{
				param2 = 0,
				name = "default:jungleleaves",
				prob = 94
			},
			{
				param2 = 0,
				name = "default:jungleleaves",
				prob = 62
			},
			{
				param2 = 0,
				name = "default:jungleleaves",
				prob = 62
			},
			{
				param2 = 0,
				name = "default:jungleleaves",
				prob = 94
			},
			{
				param2 = 0,
				name = "default:jungleleaves",
				prob = 94
			},
			{
				param2 = 0,
				name = "default:jungleleaves",
				prob = 94
			},
			{
				param2 = 0,
				name = "default:jungleleaves",
				prob = 62
			},
			{
				param2 = 0,
				name = "air",
				prob = 0
			},
			{
				param2 = 0,
				name = "air",
				prob = 0
			},
			{
				param2 = 0,
				name = "air",
				prob = 0
			},
			{
				param2 = 0,
				name = "air",
				prob = 0
			},
			{
				param2 = 0,
				name = "air",
				prob = 0
			},
			{
				param2 = 0,
				name = "air",
				prob = 0
			},
			{
				param2 = 0,
				name = "air",
				prob = 0
			},
			{
				param2 = 0,
				prob = 254,
				name = "default:jungletree",
				force_place = true
			},
			{
				param2 = 0,
				name = "air",
				prob = 0
			},
			{
				param2 = 0,
				name = "air",
				prob = 0
			},
			{
				param2 = 0,
				name = "air",
				prob = 0
			},
			{
				param2 = 0,
				name = "air",
				prob = 0
			},
			{
				param2 = 0,
				prob = 254,
				name = "default:jungletree",
				force_place = true
			},
			{
				param2 = 0,
				name = "air",
				prob = 0
			},
			{
				param2 = 0,
				name = "air",
				prob = 0
			},
			{
				param2 = 0,
				name = "air",
				prob = 0
			},
			{
				param2 = 0,
				name = "air",
				prob = 0
			},
			{
				param2 = 0,
				prob = 126,
				name = "default:jungletree",
				force_place = true
			},
			{
				param2 = 0,
				name = "air",
				prob = 0
			},
			{
				param2 = 0,
				name = "air",
				prob = 0
			},
			{
				param2 = 0,
				name = "air",
				prob = 0
			},
			{
				param2 = 0,
				name = "air",
				prob = 0
			},
			{
				param2 = 0,
				name = "air",
				prob = 0
			},
			{
				param2 = 0,
				name = "air",
				prob = 0
			},
			{
				param2 = 0,
				name = "air",
				prob = 0
			},
			{
				param2 = 0,
				name = "air",
				prob = 0
			},
			{
				param2 = 0,
				name = "air",
				prob = 0
			},
			{
				param2 = 0,
				name = "air",
				prob = 0
			},
			{
				param2 = 0,
				name = "air",
				prob = 0
			},
			{
				param2 = 0,
				name = "air",
				prob = 0
			},
			{
				param2 = 0,
				name = "air",
				prob = 0
			},
			{
				param2 = 0,
				name = "air",
				prob = 0
			},
			{
				param2 = 0,
				name = "air",
				prob = 0
			},
			{
				param2 = 0,
				name = "air",
				prob = 0
			},
			{
				param2 = 0,
				name = "air",
				prob = 0
			},
			{
				param2 = 0,
				name = "air",
				prob = 0
			},
			{
				param2 = 0,
				name = "air",
				prob = 0
			},
			{
				param2 = 0,
				name = "air",
				prob = 0
			},
			{
				param2 = 0,
				name = "air",
				prob = 0
			},
			{
				param2 = 0,
				name = "air",
				prob = 0
			},
			{
				param2 = 0,
				name = "air",
				prob = 0
			},
			{
				param2 = 0,
				name = "air",
				prob = 0
			},
			{
				param2 = 0,
				name = "air",
				prob = 0
			},
			{
				param2 = 0,
				name = "air",
				prob = 0
			},
			{
				param2 = 0,
				name = "air",
				prob = 0
			},
			{
				param2 = 0,
				name = "air",
				prob = 0
			},
			{
				param2 = 0,
				name = "air",
				prob = 0
			},
			{
				param2 = 0,
				name = "air",
				prob = 0
			},
			{
				param2 = 0,
				name = "air",
				prob = 0
			},
			{
				param2 = 0,
				name = "air",
				prob = 0
			},
			{
				param2 = 0,
				name = "air",
				prob = 0
			},
			{
				param2 = 0,
				name = "air",
				prob = 0
			},
			{
				param2 = 0,
				name = "air",
				prob = 0
			},
			{
				param2 = 0,
				name = "air",
				prob = 0
			},
			{
				param2 = 0,
				name = "air",
				prob = 0
			},
			{
				param2 = 0,
				name = "default:jungleleaves",
				prob = 126
			},
			{
				param2 = 0,
				prob = 254,
				name = "default:jungletree",
				force_place = true
			},
			{
				param2 = 0,
				name = "default:jungleleaves",
				prob = 126
			},
			{
				param2 = 0,
				name = "air",
				prob = 0
			},
			{
				param2 = 0,
				name = "air",
				prob = 0
			},
			{
				param2 = 0,
				name = "air",
				prob = 0
			},
			{
				param2 = 0,
				name = "air",
				prob = 0
			},
			{
				param2 = 0,
				name = "default:jungleleaves",
				prob = 126
			},
			{
				param2 = 0,
				prob = 254,
				name = "default:jungletree",
				force_place = true
			},
			{
				param2 = 0,
				name = "default:jungleleaves",
				prob = 126
			},
			{
				param2 = 0,
				name = "air",
				prob = 0
			},
			{
				param2 = 0,
				name = "air",
				prob = 0
			},
			{
				param2 = 0,
				name = "air",
				prob = 0
			},
			{
				param2 = 0,
				name = "air",
				prob = 0
			},
			{
				param2 = 0,
				name = "air",
				prob = 0
			},
			{
				param2 = 0,
				name = "air",
				prob = 0
			},
			{
				param2 = 0,
				name = "air",
				prob = 0
			},
			{
				param2 = 0,
				name = "air",
				prob = 0
			},
			{
				param2 = 0,
				name = "air",
				prob = 0
			},
			{
				param2 = 0,
				name = "air",
				prob = 0
			},
			{
				param2 = 0,
				name = "default:jungleleaves",
				prob = 94
			},
			{
				param2 = 0,
				prob = 254,
				name = "default:jungletree",
				force_place = true
			},
			{
				param2 = 0,
				name = "default:jungleleaves",
				prob = 126
			},
			{
				param2 = 0,
				prob = 254,
				name = "default:jungletree",
				force_place = true
			},
			{
				param2 = 0,
				name = "default:jungleleaves",
				prob = 94
			},
			{
				param2 = 0,
				name = "default:jungleleaves",
				prob = 94
			},
			{
				param2 = 0,
				name = "default:jungleleaves",
				prob = 126
			},
			{
				param2 = 0,
				name = "default:jungleleaves",
				prob = 126
			},
			{
				param2 = 0,
				name = "default:jungleleaves",
				prob = 126
			},
			{
				param2 = 0,
				name = "default:jungleleaves",
				prob = 94
			},
			{
				param2 = 0,
				name = "air",
				prob = 0
			},
			{
				param2 = 0,
				name = "default:jungleleaves",
				prob = 94
			},
			{
				param2 = 0,
				name = "default:jungleleaves",
				prob = 94
			},
			{
				param2 = 0,
				name = "default:jungleleaves",
				prob = 94
			},
			{
				param2 = 0,
				name = "air",
				prob = 0
			},
			{
				param2 = 0,
				name = "air",
				prob = 0
			},
			{
				param2 = 0,
				prob = 254,
				name = "default:jungletree",
				force_place = true
			},
			{
				param2 = 0,
				prob = 254,
				name = "default:jungletree",
				force_place = true
			},
			{
				param2 = 0,
				prob = 254,
				name = "default:jungletree",
				force_place = true
			},
			{
				param2 = 0,
				name = "air",
				prob = 0
			},
			{
				param2 = 0,
				name = "air",
				prob = 0
			},
			{
				param2 = 0,
				prob = 254,
				name = "default:jungletree",
				force_place = true
			},
			{
				param2 = 0,
				prob = 254,
				name = "default:jungletree",
				force_place = true
			},
			{
				param2 = 0,
				prob = 254,
				name = "default:jungletree",
				force_place = true
			},
			{
				param2 = 0,
				name = "air",
				prob = 0
			},
			{
				param2 = 0,
				name = "air",
				prob = 0
			},
			{
				param2 = 0,
				prob = 126,
				name = "default:jungletree",
				force_place = true
			},
			{
				param2 = 0,
				prob = 254,
				name = "default:jungletree",
				force_place = true
			},
			{
				param2 = 0,
				prob = 126,
				name = "default:jungletree",
				force_place = true
			},
			{
				param2 = 0,
				name = "air",
				prob = 0
			},
			{
				param2 = 0,
				name = "air",
				prob = 0
			},
			{
				param2 = 0,
				name = "air",
				prob = 0
			},
			{
				param2 = 0,
				prob = 254,
				name = "default:jungletree",
				force_place = true
			},
			{
				param2 = 0,
				name = "air",
				prob = 0
			},
			{
				param2 = 0,
				name = "air",
				prob = 0
			},
			{
				param2 = 0,
				name = "air",
				prob = 0
			},
			{
				param2 = 0,
				name = "air",
				prob = 0
			},
			{
				param2 = 0,
				prob = 254,
				name = "default:jungletree",
				force_place = true
			},
			{
				param2 = 0,
				name = "air",
				prob = 0
			},
			{
				param2 = 0,
				name = "air",
				prob = 0
			},
			{
				param2 = 0,
				name = "air",
				prob = 0
			},
			{
				param2 = 0,
				name = "air",
				prob = 0
			},
			{
				param2 = 0,
				prob = 254,
				name = "default:jungletree",
				force_place = true
			},
			{
				param2 = 0,
				name = "air",
				prob = 0
			},
			{
				param2 = 0,
				name = "air",
				prob = 0
			},
			{
				param2 = 0,
				name = "air",
				prob = 0
			},
			{
				param2 = 0,
				name = "air",
				prob = 0
			},
			{
				param2 = 0,
				prob = 254,
				name = "default:jungletree",
				force_place = true
			},
			{
				param2 = 0,
				name = "air",
				prob = 0
			},
			{
				param2 = 0,
				name = "air",
				prob = 0
			},
			{
				param2 = 0,
				name = "air",
				prob = 0
			},
			{
				param2 = 0,
				name = "air",
				prob = 0
			},
			{
				param2 = 0,
				prob = 254,
				name = "default:jungletree",
				force_place = true
			},
			{
				param2 = 0,
				name = "air",
				prob = 0
			},
			{
				param2 = 0,
				name = "air",
				prob = 0
			},
			{
				param2 = 0,
				name = "air",
				prob = 0
			},
			{
				param2 = 0,
				name = "air",
				prob = 0
			},
			{
				param2 = 0,
				prob = 254,
				name = "default:jungletree",
				force_place = true
			},
			{
				param2 = 0,
				name = "default:jungleleaves",
				prob = 126
			},
			{
				param2 = 0,
				name = "default:jungleleaves",
				prob = 94
			},
			{
				param2 = 0,
				name = "default:jungleleaves",
				prob = 94
			},
			{
				param2 = 0,
				name = "default:jungleleaves",
				prob = 126
			},
			{
				param2 = 0,
				prob = 254,
				name = "default:jungletree",
				force_place = true
			},
			{
				param2 = 0,
				name = "air",
				prob = 0
			},
			{
				param2 = 0,
				name = "air",
				prob = 0
			},
			{
				param2 = 0,
				name = "default:jungleleaves",
				prob = 94
			},
			{
				param2 = 0,
				name = "default:jungleleaves",
				prob = 126
			},
			{
				param2 = 0,
				prob = 254,
				name = "default:jungletree",
				force_place = true
			},
			{
				param2 = 0,
				name = "air",
				prob = 0
			},
			{
				param2 = 0,
				name = "air",
				prob = 0
			},
			{
				param2 = 0,
				name = "air",
				prob = 0
			},
			{
				param2 = 0,
				name = "air",
				prob = 0
			},
			{
				param2 = 0,
				prob = 254,
				name = "default:jungletree",
				force_place = true
			},
			{
				param2 = 0,
				name = "default:jungleleaves",
				prob = 126
			},
			{
				param2 = 0,
				name = "default:jungleleaves",
				prob = 94
			},
			{
				param2 = 0,
				name = "air",
				prob = 0
			},
			{
				param2 = 0,
				name = "air",
				prob = 0
			},
			{
				param2 = 0,
				prob = 254,
				name = "default:jungletree",
				force_place = true
			},
			{
				param2 = 0,
				name = "default:jungleleaves",
				prob = 126
			},
			{
				param2 = 0,
				name = "default:jungleleaves",
				prob = 94
			},
			{
				param2 = 0,
				name = "air",
				prob = 0
			},
			{
				param2 = 0,
				name = "air",
				prob = 0
			},
			{
				param2 = 0,
				prob = 254,
				name = "default:jungletree",
				force_place = true
			},
			{
				param2 = 0,
				name = "air",
				prob = 0
			},
			{
				param2 = 0,
				name = "air",
				prob = 0
			},
			{
				param2 = 0,
				name = "default:jungleleaves",
				prob = 94
			},
			{
				param2 = 0,
				name = "default:jungleleaves",
				prob = 126
			},
			{
				param2 = 0,
				name = "default:jungleleaves",
				prob = 126
			},
			{
				param2 = 0,
				name = "default:jungleleaves",
				prob = 126
			},
			{
				param2 = 0,
				name = "default:jungleleaves",
				prob = 94
			},
			{
				param2 = 0,
				name = "default:jungleleaves",
				prob = 94
			},
			{
				param2 = 0,
				name = "default:jungleleaves",
				prob = 126
			},
			{
				param2 = 0,
				name = "default:jungleleaves",
				prob = 126
			},
			{
				param2 = 0,
				name = "default:jungleleaves",
				prob = 126
			},
			{
				param2 = 0,
				name = "default:jungleleaves",
				prob = 94
			},
			{
				param2 = 0,
				name = "air",
				prob = 0
			},
			{
				param2 = 0,
				name = "default:jungleleaves",
				prob = 94
			},
			{
				param2 = 0,
				name = "default:jungleleaves",
				prob = 126
			},
			{
				param2 = 0,
				name = "default:jungleleaves",
				prob = 94
			},
			{
				param2 = 0,
				name = "air",
				prob = 0
			},
			{
				param2 = 0,
				name = "air",
				prob = 0
			},
			{
				param2 = 0,
				name = "air",
				prob = 0
			},
			{
				param2 = 0,
				prob = 254,
				name = "default:jungletree",
				force_place = true
			},
			{
				param2 = 0,
				name = "air",
				prob = 0
			},
			{
				param2 = 0,
				name = "air",
				prob = 0
			},
			{
				param2 = 0,
				name = "air",
				prob = 0
			},
			{
				param2 = 0,
				name = "air",
				prob = 0
			},
			{
				param2 = 0,
				prob = 254,
				name = "default:jungletree",
				force_place = true
			},
			{
				param2 = 0,
				name = "air",
				prob = 0
			},
			{
				param2 = 0,
				name = "air",
				prob = 0
			},
			{
				param2 = 0,
				name = "air",
				prob = 0
			},
			{
				param2 = 0,
				name = "air",
				prob = 0
			},
			{
				param2 = 0,
				prob = 126,
				name = "default:jungletree",
				force_place = true
			},
			{
				param2 = 0,
				name = "air",
				prob = 0
			},
			{
				param2 = 0,
				name = "air",
				prob = 0
			},
			{
				param2 = 0,
				name = "air",
				prob = 0
			},
			{
				param2 = 0,
				name = "air",
				prob = 0
			},
			{
				param2 = 0,
				name = "air",
				prob = 0
			},
			{
				param2 = 0,
				name = "air",
				prob = 0
			},
			{
				param2 = 0,
				name = "air",
				prob = 0
			},
			{
				param2 = 0,
				name = "air",
				prob = 0
			},
			{
				param2 = 0,
				name = "air",
				prob = 0
			},
			{
				param2 = 0,
				name = "air",
				prob = 0
			},
			{
				param2 = 0,
				name = "air",
				prob = 0
			},
			{
				param2 = 0,
				name = "air",
				prob = 0
			},
			{
				param2 = 0,
				name = "air",
				prob = 0
			},
			{
				param2 = 0,
				name = "air",
				prob = 0
			},
			{
				param2 = 0,
				name = "air",
				prob = 0
			},
			{
				param2 = 0,
				name = "air",
				prob = 0
			},
			{
				param2 = 0,
				name = "air",
				prob = 0
			},
			{
				param2 = 0,
				name = "air",
				prob = 0
			},
			{
				param2 = 0,
				name = "air",
				prob = 0
			},
			{
				param2 = 0,
				name = "air",
				prob = 0
			},
			{
				param2 = 0,
				name = "air",
				prob = 0
			},
			{
				param2 = 0,
				name = "air",
				prob = 0
			},
			{
				param2 = 0,
				name = "air",
				prob = 0
			},
			{
				param2 = 0,
				name = "air",
				prob = 0
			},
			{
				param2 = 0,
				name = "air",
				prob = 0
			},
			{
				param2 = 0,
				name = "air",
				prob = 0
			},
			{
				param2 = 0,
				name = "air",
				prob = 0
			},
			{
				param2 = 0,
				name = "air",
				prob = 0
			},
			{
				param2 = 0,
				name = "air",
				prob = 0
			},
			{
				param2 = 0,
				name = "default:jungleleaves",
				prob = 126
			},
			{
				param2 = 0,
				prob = 254,
				name = "default:jungletree",
				force_place = true
			},
			{
				param2 = 0,
				name = "default:jungleleaves",
				prob = 126
			},
			{
				param2 = 0,
				name = "default:jungleleaves",
				prob = 126
			},
			{
				param2 = 0,
				prob = 254,
				name = "default:jungletree",
				force_place = true
			},
			{
				param2 = 0,
				name = "default:jungleleaves",
				prob = 126
			},
			{
				param2 = 0,
				name = "air",
				prob = 0
			},
			{
				param2 = 0,
				name = "air",
				prob = 0
			},
			{
				param2 = 0,
				name = "air",
				prob = 0
			},
			{
				param2 = 0,
				name = "air",
				prob = 0
			},
			{
				param2 = 0,
				name = "air",
				prob = 0
			},
			{
				param2 = 0,
				name = "air",
				prob = 0
			},
			{
				param2 = 0,
				name = "air",
				prob = 0
			},
			{
				param2 = 0,
				name = "air",
				prob = 0
			},
			{
				param2 = 0,
				name = "air",
				prob = 0
			},
			{
				param2 = 0,
				name = "air",
				prob = 0
			},
			{
				param2 = 0,
				name = "air",
				prob = 0
			},
			{
				param2 = 0,
				name = "air",
				prob = 0
			},
			{
				param2 = 0,
				name = "air",
				prob = 0
			},
			{
				param2 = 0,
				name = "air",
				prob = 0
			},
			{
				param2 = 0,
				name = "default:jungleleaves",
				prob = 126
			},
			{
				param2 = 0,
				prob = 254,
				name = "default:jungletree",
				force_place = true
			},
			{
				param2 = 0,
				name = "default:jungleleaves",
				prob = 126
			},
			{
				param2 = 0,
				name = "air",
				prob = 0
			},
			{
				param2 = 0,
				name = "air",
				prob = 0
			},
			{
				param2 = 0,
				name = "air",
				prob = 0
			},
			{
				param2 = 0,
				name = "air",
				prob = 0
			},
			{
				param2 = 0,
				name = "air",
				prob = 0
			},
			{
				param2 = 0,
				name = "default:jungleleaves",
				prob = 94
			},
			{
				param2 = 0,
				prob = 254,
				name = "default:jungletree",
				force_place = true
			},
			{
				param2 = 0,
				name = "default:jungleleaves",
				prob = 126
			},
			{
				param2 = 0,
				prob = 254,
				name = "default:jungletree",
				force_place = true
			},
			{
				param2 = 0,
				name = "default:jungleleaves",
				prob = 94
			},
			{
				param2 = 0,
				name = "default:jungleleaves",
				prob = 94
			},
			{
				param2 = 0,
				name = "default:jungleleaves",
				prob = 126
			},
			{
				param2 = 0,
				name = "default:jungleleaves",
				prob = 126
			},
			{
				param2 = 0,
				name = "default:jungleleaves",
				prob = 126
			},
			{
				param2 = 0,
				name = "default:jungleleaves",
				prob = 94
			},
			{
				param2 = 0,
				name = "air",
				prob = 0
			},
			{
				param2 = 0,
				name = "default:jungleleaves",
				prob = 94
			},
			{
				param2 = 0,
				name = "default:jungleleaves",
				prob = 94
			},
			{
				param2 = 0,
				name = "default:jungleleaves",
				prob = 94
			},
			{
				param2 = 0,
				name = "air",
				prob = 0
			},
			{
				param2 = 0,
				name = "air",
				prob = 0
			},
			{
				param2 = 0,
				name = "air",
				prob = 0
			},
			{
				param2 = 0,
				name = "air",
				prob = 0
			},
			{
				param2 = 0,
				name = "air",
				prob = 0
			},
			{
				param2 = 0,
				name = "air",
				prob = 0
			},
			{
				param2 = 0,
				name = "air",
				prob = 0
			},
			{
				param2 = 0,
				name = "air",
				prob = 0
			},
			{
				param2 = 0,
				name = "air",
				prob = 0
			},
			{
				param2 = 0,
				name = "air",
				prob = 0
			},
			{
				param2 = 0,
				name = "air",
				prob = 0
			},
			{
				param2 = 0,
				name = "air",
				prob = 0
			},
			{
				param2 = 0,
				name = "air",
				prob = 0
			},
			{
				param2 = 0,
				name = "air",
				prob = 0
			},
			{
				param2 = 0,
				name = "air",
				prob = 0
			},
			{
				param2 = 0,
				name = "air",
				prob = 0
			},
			{
				param2 = 0,
				name = "air",
				prob = 0
			},
			{
				param2 = 0,
				name = "air",
				prob = 0
			},
			{
				param2 = 0,
				name = "air",
				prob = 0
			},
			{
				param2 = 0,
				name = "air",
				prob = 0
			},
			{
				param2 = 0,
				name = "air",
				prob = 0
			},
			{
				param2 = 0,
				name = "air",
				prob = 0
			},
			{
				param2 = 0,
				name = "air",
				prob = 0
			},
			{
				param2 = 0,
				name = "air",
				prob = 0
			},
			{
				param2 = 0,
				name = "air",
				prob = 0
			},
			{
				param2 = 0,
				name = "air",
				prob = 0
			},
			{
				param2 = 0,
				name = "air",
				prob = 0
			},
			{
				param2 = 0,
				name = "air",
				prob = 0
			},
			{
				param2 = 0,
				name = "air",
				prob = 0
			},
			{
				param2 = 0,
				name = "air",
				prob = 0
			},
			{
				param2 = 0,
				name = "air",
				prob = 0
			},
			{
				param2 = 0,
				name = "air",
				prob = 0
			},
			{
				param2 = 0,
				name = "air",
				prob = 0
			},
			{
				param2 = 0,
				name = "air",
				prob = 0
			},
			{
				param2 = 0,
				name = "air",
				prob = 0
			},
			{
				param2 = 0,
				name = "air",
				prob = 0
			},
			{
				param2 = 0,
				name = "air",
				prob = 0
			},
			{
				param2 = 0,
				name = "air",
				prob = 0
			},
			{
				param2 = 0,
				name = "air",
				prob = 0
			},
			{
				param2 = 0,
				name = "air",
				prob = 0
			},
			{
				param2 = 0,
				name = "air",
				prob = 0
			},
			{
				param2 = 0,
				name = "air",
				prob = 0
			},
			{
				param2 = 0,
				name = "air",
				prob = 0
			},
			{
				param2 = 0,
				name = "default:jungleleaves",
				prob = 94
			},
			{
				param2 = 0,
				name = "default:jungleleaves",
				prob = 126
			},
			{
				param2 = 0,
				name = "default:jungleleaves",
				prob = 94
			},
			{
				param2 = 0,
				name = "default:jungleleaves",
				prob = 94
			},
			{
				param2 = 0,
				name = "default:jungleleaves",
				prob = 126
			},
			{
				param2 = 0,
				name = "default:jungleleaves",
				prob = 94
			},
			{
				param2 = 0,
				name = "air",
				prob = 0
			},
			{
				param2 = 0,
				name = "air",
				prob = 0
			},
			{
				param2 = 0,
				name = "air",
				prob = 0
			},
			{
				param2 = 0,
				name = "air",
				prob = 0
			},
			{
				param2 = 0,
				name = "air",
				prob = 0
			},
			{
				param2 = 0,
				name = "air",
				prob = 0
			},
			{
				param2 = 0,
				name = "air",
				prob = 0
			},
			{
				param2 = 0,
				name = "air",
				prob = 0
			},
			{
				param2 = 0,
				name = "air",
				prob = 0
			},
			{
				param2 = 0,
				name = "air",
				prob = 0
			},
			{
				param2 = 0,
				name = "air",
				prob = 0
			},
			{
				param2 = 0,
				name = "air",
				prob = 0
			},
			{
				param2 = 0,
				name = "air",
				prob = 0
			},
			{
				param2 = 0,
				name = "air",
				prob = 0
			},
			{
				param2 = 0,
				name = "default:jungleleaves",
				prob = 94
			},
			{
				param2 = 0,
				name = "default:jungleleaves",
				prob = 126
			},
			{
				param2 = 0,
				name = "default:jungleleaves",
				prob = 94
			},
			{
				param2 = 0,
				name = "air",
				prob = 0
			},
			{
				param2 = 0,
				name = "air",
				prob = 0
			},
			{
				param2 = 0,
				name = "air",
				prob = 0
			},
			{
				param2 = 0,
				name = "air",
				prob = 0
			},
			{
				param2 = 0,
				name = "air",
				prob = 0
			},
			{
				param2 = 0,
				name = "default:jungleleaves",
				prob = 62
			},
			{
				param2 = 0,
				name = "default:jungleleaves",
				prob = 94
			},
			{
				param2 = 0,
				name = "default:jungleleaves",
				prob = 94
			},
			{
				param2 = 0,
				name = "default:jungleleaves",
				prob = 94
			},
			{
				param2 = 0,
				name = "default:jungleleaves",
				prob = 62
			},
			{
				param2 = 0,
				name = "default:jungleleaves",
				prob = 62
			},
			{
				param2 = 0,
				name = "default:jungleleaves",
				prob = 94
			},
			{
				param2 = 0,
				name = "default:jungleleaves",
				prob = 94
			},
			{
				param2 = 0,
				name = "default:jungleleaves",
				prob = 94
			},
			{
				param2 = 0,
				name = "default:jungleleaves",
				prob = 62
			},
			{
				param2 = 0,
				name = "air",
				prob = 0
			},
			{
				param2 = 0,
				name = "air",
				prob = 0
			},
			{
				param2 = 0,
				name = "air",
				prob = 0
			},
			{
				param2 = 0,
				name = "air",
				prob = 0
			},
			{
				param2 = 0,
				name = "air",
				prob = 0
			}
		},
		size = {
			y = 17,
			x = 5,
			z = 5
		}
	}
})
mod.register_decoration({
	y_min = 1,
	biomes = {
		"grassland",
		"deciduous_forest",
		"floatland_grassland"
	},
	noise_params = {
		offset = -0.02,
		persist = 0.6,
		seed = 1220999,
		scale = 0.04,
		spread = {
			y = 200,
			x = 200,
			z = 200
		},
		octaves = 3
	},
	y_max = 31000,
	decoration = "flowers:dandelion_yellow",
	name = "flowers:dandelion_yellow",
	sidelen = 16,
	deco_type = "simple",
	source = "default",
	place_on = {
		"default:dirt_with_grass"
	}
})
mod.register_decoration({
	y_min = 4,
	biomes = {
		"desert"
	},
	noise_params = {
		offset = -0.0003,
		persist = 0.6,
		seed = 230,
		scale = 0.0009,
		spread = {
			y = 200,
			x = 200,
			z = 200
		},
		octaves = 3
	},
	source = "default",
	y_max = 31000,
	decoration = "default:cactus",
	name = "default:cactus",
	place_on = {
		"default:desert_sand"
	},
	height_max = 5,
	deco_type = "simple",
	height = 2,
	sidelen = 16
})
mod.register_decoration({
	y_min = 1,
	biomes = {
		"savanna"
	},
	noise_params = {
		offset = 0.03,
		persist = 0.6,
		seed = 329,
		scale = 0.03,
		spread = {
			y = 200,
			x = 200,
			z = 200
		},
		octaves = 3
	},
	y_max = 31000,
	decoration = "default:dry_grass_4",
	name = "default:dry_grass_4",
	sidelen = 16,
	deco_type = "simple",
	source = "default",
	place_on = {
		"default:dirt_with_dry_grass"
	}
})
mod.register_decoration({
	y_min = 4,
	biomes = {
		"desert"
	},
	noise_params = {
		offset = -0.0003,
		persist = 0.6,
		seed = 230,
		scale = 0.0009,
		spread = {
			y = 200,
			x = 200,
			z = 200
		},
		octaves = 3
	},
	schematic = mod.path .. "/schematics/large_cactus.mts",
	rotation = "random",
	y_max = 31000,
	source = "default",
	name = "default:large_cactus",
	place_on = {
		"default:desert_sand"
	},
	sidelen = 16,
	deco_type = "schematic",
	flags = "place_center_x, place_center_z",
	schematic_array = {
		yslice_prob = {
			{
				prob = 254,
				ypos = 0
			},
			{
				prob = 254,
				ypos = 1
			},
			{
				prob = 126,
				ypos = 2
			},
			{
				prob = 254,
				ypos = 3
			},
			{
				prob = 254,
				ypos = 4
			},
			{
				prob = 254,
				ypos = 5
			},
			{
				prob = 254,
				ypos = 6
			}
		},
		data = {
			{
				param2 = 0,
				name = "air",
				prob = 0
			},
			{
				param2 = 0,
				name = "air",
				prob = 0
			},
			{
				param2 = 0,
				name = "air",
				prob = 0
			},
			{
				param2 = 0,
				name = "air",
				prob = 0
			},
			{
				param2 = 0,
				name = "air",
				prob = 0
			},
			{
				param2 = 0,
				name = "air",
				prob = 0
			},
			{
				param2 = 0,
				name = "air",
				prob = 0
			},
			{
				param2 = 0,
				name = "air",
				prob = 0
			},
			{
				param2 = 0,
				name = "air",
				prob = 0
			},
			{
				param2 = 0,
				name = "air",
				prob = 0
			},
			{
				param2 = 0,
				name = "air",
				prob = 0
			},
			{
				param2 = 0,
				name = "air",
				prob = 0
			},
			{
				param2 = 0,
				name = "air",
				prob = 0
			},
			{
				param2 = 0,
				name = "air",
				prob = 0
			},
			{
				param2 = 0,
				name = "air",
				prob = 0
			},
			{
				param2 = 0,
				name = "air",
				prob = 0
			},
			{
				param2 = 0,
				name = "air",
				prob = 0
			},
			{
				param2 = 0,
				name = "air",
				prob = 0
			},
			{
				param2 = 0,
				name = "air",
				prob = 0
			},
			{
				param2 = 0,
				name = "air",
				prob = 0
			},
			{
				param2 = 0,
				name = "air",
				prob = 0
			},
			{
				param2 = 0,
				name = "air",
				prob = 0
			},
			{
				param2 = 0,
				name = "air",
				prob = 0
			},
			{
				param2 = 0,
				name = "air",
				prob = 0
			},
			{
				param2 = 0,
				name = "air",
				prob = 0
			},
			{
				param2 = 0,
				name = "air",
				prob = 0
			},
			{
				param2 = 0,
				name = "air",
				prob = 0
			},
			{
				param2 = 0,
				name = "air",
				prob = 0
			},
			{
				param2 = 0,
				name = "air",
				prob = 0
			},
			{
				param2 = 0,
				name = "air",
				prob = 0
			},
			{
				param2 = 0,
				name = "air",
				prob = 0
			},
			{
				param2 = 0,
				name = "air",
				prob = 0
			},
			{
				param2 = 0,
				name = "air",
				prob = 0
			},
			{
				param2 = 0,
				name = "air",
				prob = 0
			},
			{
				param2 = 0,
				name = "air",
				prob = 0
			},
			{
				param2 = 0,
				name = "air",
				prob = 0
			},
			{
				param2 = 0,
				name = "air",
				prob = 0
			},
			{
				param2 = 0,
				name = "air",
				prob = 0
			},
			{
				param2 = 0,
				name = "air",
				prob = 0
			},
			{
				param2 = 0,
				name = "air",
				prob = 0
			},
			{
				param2 = 0,
				name = "air",
				prob = 0
			},
			{
				param2 = 0,
				name = "air",
				prob = 0
			},
			{
				param2 = 0,
				name = "air",
				prob = 0
			},
			{
				param2 = 0,
				name = "air",
				prob = 0
			},
			{
				param2 = 0,
				name = "air",
				prob = 0
			},
			{
				param2 = 0,
				name = "air",
				prob = 0
			},
			{
				param2 = 0,
				name = "air",
				prob = 0
			},
			{
				param2 = 0,
				name = "air",
				prob = 0
			},
			{
				param2 = 0,
				name = "air",
				prob = 0
			},
			{
				param2 = 0,
				name = "air",
				prob = 0
			},
			{
				param2 = 0,
				name = "air",
				prob = 0
			},
			{
				param2 = 0,
				name = "air",
				prob = 0
			},
			{
				param2 = 0,
				name = "air",
				prob = 0
			},
			{
				param2 = 0,
				name = "air",
				prob = 0
			},
			{
				param2 = 0,
				name = "air",
				prob = 0
			},
			{
				param2 = 0,
				name = "air",
				prob = 0
			},
			{
				param2 = 0,
				name = "air",
				prob = 0
			},
			{
				param2 = 0,
				name = "air",
				prob = 0
			},
			{
				param2 = 0,
				name = "air",
				prob = 0
			},
			{
				param2 = 0,
				name = "air",
				prob = 0
			},
			{
				param2 = 0,
				name = "air",
				prob = 0
			},
			{
				param2 = 0,
				name = "air",
				prob = 0
			},
			{
				param2 = 0,
				name = "air",
				prob = 0
			},
			{
				param2 = 0,
				name = "air",
				prob = 0
			},
			{
				param2 = 0,
				name = "air",
				prob = 0
			},
			{
				param2 = 0,
				name = "air",
				prob = 0
			},
			{
				param2 = 0,
				name = "air",
				prob = 0
			},
			{
				param2 = 0,
				name = "air",
				prob = 0
			},
			{
				param2 = 0,
				name = "air",
				prob = 0
			},
			{
				param2 = 0,
				name = "air",
				prob = 0
			},
			{
				param2 = 0,
				name = "air",
				prob = 0
			},
			{
				param2 = 0,
				name = "air",
				prob = 0
			},
			{
				param2 = 20,
				prob = 254,
				name = "default:cactus",
				force_place = true
			},
			{
				param2 = 0,
				name = "air",
				prob = 0
			},
			{
				param2 = 0,
				name = "air",
				prob = 0
			},
			{
				param2 = 0,
				name = "air",
				prob = 0
			},
			{
				param2 = 0,
				name = "air",
				prob = 0
			},
			{
				param2 = 20,
				prob = 254,
				name = "default:cactus",
				force_place = true
			},
			{
				param2 = 0,
				name = "air",
				prob = 0
			},
			{
				param2 = 0,
				name = "air",
				prob = 0
			},
			{
				param2 = 0,
				name = "air",
				prob = 0
			},
			{
				param2 = 0,
				name = "air",
				prob = 0
			},
			{
				param2 = 20,
				name = "default:cactus",
				prob = 254
			},
			{
				param2 = 0,
				name = "air",
				prob = 0
			},
			{
				param2 = 0,
				name = "air",
				prob = 0
			},
			{
				param2 = 20,
				name = "default:cactus",
				prob = 254
			},
			{
				param2 = 20,
				name = "default:cactus",
				prob = 254
			},
			{
				param2 = 20,
				name = "default:cactus",
				prob = 254
			},
			{
				param2 = 20,
				name = "default:cactus",
				prob = 254
			},
			{
				param2 = 20,
				name = "default:cactus",
				prob = 254
			},
			{
				param2 = 20,
				name = "default:cactus",
				prob = 254
			},
			{
				param2 = 0,
				name = "air",
				prob = 0
			},
			{
				param2 = 20,
				name = "default:cactus",
				prob = 254
			},
			{
				param2 = 0,
				name = "air",
				prob = 0
			},
			{
				param2 = 20,
				name = "default:cactus",
				prob = 254
			},
			{
				param2 = 20,
				name = "default:cactus",
				prob = 126
			},
			{
				param2 = 0,
				name = "air",
				prob = 0
			},
			{
				param2 = 20,
				name = "default:cactus",
				prob = 254
			},
			{
				param2 = 0,
				name = "air",
				prob = 0
			},
			{
				param2 = 20,
				name = "default:cactus",
				prob = 126
			},
			{
				param2 = 0,
				name = "air",
				prob = 0
			},
			{
				param2 = 0,
				name = "air",
				prob = 0
			},
			{
				param2 = 20,
				name = "default:cactus",
				prob = 254
			},
			{
				param2 = 0,
				name = "air",
				prob = 0
			},
			{
				param2 = 0,
				name = "air",
				prob = 0
			},
			{
				param2 = 0,
				name = "air",
				prob = 0
			},
			{
				param2 = 0,
				name = "air",
				prob = 0
			},
			{
				param2 = 0,
				name = "air",
				prob = 0
			},
			{
				param2 = 0,
				name = "air",
				prob = 0
			},
			{
				param2 = 0,
				name = "air",
				prob = 0
			},
			{
				param2 = 0,
				name = "air",
				prob = 0
			},
			{
				param2 = 0,
				name = "air",
				prob = 0
			},
			{
				param2 = 0,
				name = "air",
				prob = 0
			},
			{
				param2 = 0,
				name = "air",
				prob = 0
			},
			{
				param2 = 0,
				name = "air",
				prob = 0
			},
			{
				param2 = 0,
				name = "air",
				prob = 0
			},
			{
				param2 = 0,
				name = "air",
				prob = 0
			},
			{
				param2 = 0,
				name = "air",
				prob = 0
			},
			{
				param2 = 0,
				name = "air",
				prob = 0
			},
			{
				param2 = 0,
				name = "air",
				prob = 0
			},
			{
				param2 = 0,
				name = "air",
				prob = 0
			},
			{
				param2 = 0,
				name = "air",
				prob = 0
			},
			{
				param2 = 0,
				name = "air",
				prob = 0
			},
			{
				param2 = 0,
				name = "air",
				prob = 0
			},
			{
				param2 = 0,
				name = "air",
				prob = 0
			},
			{
				param2 = 0,
				name = "air",
				prob = 0
			},
			{
				param2 = 0,
				name = "air",
				prob = 0
			},
			{
				param2 = 0,
				name = "air",
				prob = 0
			},
			{
				param2 = 0,
				name = "air",
				prob = 0
			},
			{
				param2 = 0,
				name = "air",
				prob = 0
			},
			{
				param2 = 0,
				name = "air",
				prob = 0
			},
			{
				param2 = 0,
				name = "air",
				prob = 0
			},
			{
				param2 = 0,
				name = "air",
				prob = 0
			},
			{
				param2 = 0,
				name = "air",
				prob = 0
			},
			{
				param2 = 0,
				name = "air",
				prob = 0
			},
			{
				param2 = 0,
				name = "air",
				prob = 0
			},
			{
				param2 = 0,
				name = "air",
				prob = 0
			},
			{
				param2 = 0,
				name = "air",
				prob = 0
			},
			{
				param2 = 0,
				name = "air",
				prob = 0
			},
			{
				param2 = 0,
				name = "air",
				prob = 0
			},
			{
				param2 = 0,
				name = "air",
				prob = 0
			},
			{
				param2 = 0,
				name = "air",
				prob = 0
			},
			{
				param2 = 0,
				name = "air",
				prob = 0
			},
			{
				param2 = 0,
				name = "air",
				prob = 0
			},
			{
				param2 = 0,
				name = "air",
				prob = 0
			},
			{
				param2 = 0,
				name = "air",
				prob = 0
			},
			{
				param2 = 0,
				name = "air",
				prob = 0
			},
			{
				param2 = 0,
				name = "air",
				prob = 0
			},
			{
				param2 = 0,
				name = "air",
				prob = 0
			},
			{
				param2 = 0,
				name = "air",
				prob = 0
			},
			{
				param2 = 0,
				name = "air",
				prob = 0
			},
			{
				param2 = 0,
				name = "air",
				prob = 0
			},
			{
				param2 = 0,
				name = "air",
				prob = 0
			},
			{
				param2 = 0,
				name = "air",
				prob = 0
			},
			{
				param2 = 0,
				name = "air",
				prob = 0
			},
			{
				param2 = 0,
				name = "air",
				prob = 0
			},
			{
				param2 = 0,
				name = "air",
				prob = 0
			},
			{
				param2 = 0,
				name = "air",
				prob = 0
			},
			{
				param2 = 0,
				name = "air",
				prob = 0
			},
			{
				param2 = 0,
				name = "air",
				prob = 0
			},
			{
				param2 = 0,
				name = "air",
				prob = 0
			},
			{
				param2 = 0,
				name = "air",
				prob = 0
			},
			{
				param2 = 0,
				name = "air",
				prob = 0
			},
			{
				param2 = 0,
				name = "air",
				prob = 0
			},
			{
				param2 = 0,
				name = "air",
				prob = 0
			},
			{
				param2 = 0,
				name = "air",
				prob = 0
			},
			{
				param2 = 0,
				name = "air",
				prob = 0
			},
			{
				param2 = 0,
				name = "air",
				prob = 0
			},
			{
				param2 = 0,
				name = "air",
				prob = 0
			},
			{
				param2 = 0,
				name = "air",
				prob = 0
			},
			{
				param2 = 0,
				name = "air",
				prob = 0
			},
			{
				param2 = 0,
				name = "air",
				prob = 0
			},
			{
				param2 = 0,
				name = "air",
				prob = 0
			},
			{
				param2 = 0,
				name = "air",
				prob = 0
			},
			{
				param2 = 0,
				name = "air",
				prob = 0
			}
		},
		size = {
			y = 7,
			x = 5,
			z = 5
		}
	}
})
mod.register_decoration({
	y_min = 1,
	biomes = {
		"savanna"
	},
	noise_params = {
		offset = -0.004,
		persist = 0.7,
		seed = 90155,
		scale = 0.01,
		spread = {
			y = 100,
			x = 100,
			z = 100
		},
		octaves = 3
	},
	schematic = mod.path .. "/schematics/acacia_bush.mts",
	y_max = 31000,
	flags = "place_center_x, place_center_z",
	name = "default:acacia_bush",
	source = "default",
	sidelen = 16,
	deco_type = "schematic",
	place_on = {
		"default:dirt_with_dry_grass"
	},
	schematic_array = {
		yslice_prob = {
			{
				prob = 254,
				ypos = 0
			},
			{
				prob = 254,
				ypos = 1
			},
			{
				prob = 254,
				ypos = 2
			}
		},
		data = {
			{
				param2 = 0,
				name = "air",
				prob = 0
			},
			{
				param2 = 0,
				name = "air",
				prob = 0
			},
			{
				param2 = 0,
				name = "air",
				prob = 0
			},
			{
				param2 = 0,
				name = "default:acacia_bush_leaves",
				prob = 126
			},
			{
				param2 = 0,
				name = "default:acacia_bush_leaves",
				prob = 62
			},
			{
				param2 = 0,
				name = "default:acacia_bush_leaves",
				prob = 126
			},
			{
				param2 = 0,
				name = "default:acacia_bush_leaves",
				prob = 62
			},
			{
				param2 = 0,
				name = "default:acacia_bush_leaves",
				prob = 126
			},
			{
				param2 = 0,
				name = "default:acacia_bush_leaves",
				prob = 62
			},
			{
				param2 = 0,
				name = "air",
				prob = 0
			},
			{
				param2 = 0,
				name = "air",
				prob = 0
			},
			{
				param2 = 0,
				name = "air",
				prob = 0
			},
			{
				param2 = 0,
				name = "default:acacia_bush_leaves",
				prob = 62
			},
			{
				param2 = 0,
				prob = 254,
				name = "default:acacia_bush_stem",
				force_place = true
			},
			{
				param2 = 0,
				name = "default:acacia_bush_leaves",
				prob = 62
			},
			{
				param2 = 0,
				name = "default:acacia_bush_leaves",
				prob = 126
			},
			{
				param2 = 0,
				name = "default:acacia_bush_leaves",
				prob = 126
			},
			{
				param2 = 0,
				name = "default:acacia_bush_leaves",
				prob = 126
			},
			{
				param2 = 0,
				name = "air",
				prob = 0
			},
			{
				param2 = 0,
				name = "air",
				prob = 0
			},
			{
				param2 = 0,
				name = "air",
				prob = 0
			},
			{
				param2 = 0,
				name = "default:acacia_bush_leaves",
				prob = 126
			},
			{
				param2 = 0,
				name = "default:acacia_bush_leaves",
				prob = 62
			},
			{
				param2 = 0,
				name = "default:acacia_bush_leaves",
				prob = 126
			},
			{
				param2 = 0,
				name = "default:acacia_bush_leaves",
				prob = 62
			},
			{
				param2 = 0,
				name = "default:acacia_bush_leaves",
				prob = 126
			},
			{
				param2 = 0,
				name = "default:acacia_bush_leaves",
				prob = 62
			}
		},
		size = {
			y = 3,
			x = 3,
			z = 3
		}
	}
})
mod.register_decoration({
	y_min = 1,
	biomes = {
		"grassland",
		"deciduous_forest",
		"floatland_grassland"
	},
	noise_params = {
		offset = 0,
		persist = 0.6,
		seed = 329,
		scale = 0.06,
		spread = {
			y = 200,
			x = 200,
			z = 200
		},
		octaves = 3
	},
	y_max = 31000,
	decoration = "default:grass_3",
	name = "default:grass_3",
	sidelen = 16,
	deco_type = "simple",
	source = "default",
	place_on = {
		"default:dirt_with_grass"
	}
})
mod.register_decoration({
	y_min = 1,
	biomes = {
		"grassland",
		"deciduous_forest",
		"floatland_grassland"
	},
	noise_params = {
		offset = -0.02,
		persist = 0.6,
		seed = 800081,
		scale = 0.04,
		spread = {
			y = 200,
			x = 200,
			z = 200
		},
		octaves = 3
	},
	y_max = 31000,
	decoration = "flowers:chrysanthemum_green",
	name = "flowers:chrysanthemum_green",
	sidelen = 16,
	deco_type = "simple",
	source = "default",
	place_on = {
		"default:dirt_with_grass"
	}
})
mod.register_decoration({
	place_offset_y = -4,
	biomes = {
		"rainforest"
	},
	noise_params = {
		offset = 0,
		persist = 0.7,
		seed = 2685,
		scale = 0.0025,
		spread = {
			y = 250,
			x = 250,
			z = 250
		},
		octaves = 3
	},
	schematic = mod.path .. "/schematics/emergent_jungle_tree.mts",
	rotation = "random",
	source = "default",
	y_max = 32,
	place_on = {
		"default:dirt_with_rainforest_litter"
	},
	name = "default:emergent_jungle_tree",
	flags = "place_center_x, place_center_z",
	sidelen = 80,
	deco_type = "schematic",
	y_min = 1,
	schematic_array = {
		yslice_prob = {
			{
				prob = 254,
				ypos = 0
			},
			{
				prob = 254,
				ypos = 1
			},
			{
				prob = 254,
				ypos = 2
			},
			{
				prob = 254,
				ypos = 3
			},
			{
				prob = 254,
				ypos = 4
			},
			{
				prob = 254,
				ypos = 5
			},
			{
				prob = 254,
				ypos = 6
			},
			{
				prob = 254,
				ypos = 7
			},
			{
				prob = 254,
				ypos = 8
			},
			{
				prob = 254,
				ypos = 9
			},
			{
				prob = 254,
				ypos = 10
			},
			{
				prob = 254,
				ypos = 11
			},
			{
				prob = 254,
				ypos = 12
			},
			{
				prob = 126,
				ypos = 13
			},
			{
				prob = 126,
				ypos = 14
			},
			{
				prob = 126,
				ypos = 15
			},
			{
				prob = 126,
				ypos = 16
			},
			{
				prob = 126,
				ypos = 17
			},
			{
				prob = 126,
				ypos = 18
			},
			{
				prob = 126,
				ypos = 19
			},
			{
				prob = 126,
				ypos = 20
			},
			{
				prob = 126,
				ypos = 21
			},
			{
				prob = 126,
				ypos = 22
			},
			{
				prob = 126,
				ypos = 23
			},
			{
				prob = 126,
				ypos = 24
			},
			{
				prob = 254,
				ypos = 25
			},
			{
				prob = 254,
				ypos = 26
			},
			{
				prob = 254,
				ypos = 27
			},
			{
				prob = 254,
				ypos = 28
			},
			{
				prob = 254,
				ypos = 29
			},
			{
				prob = 254,
				ypos = 30
			},
			{
				prob = 254,
				ypos = 31
			},
			{
				prob = 254,
				ypos = 32
			},
			{
				prob = 254,
				ypos = 33
			},
			{
				prob = 254,
				ypos = 34
			},
			{
				prob = 254,
				ypos = 35
			},
			{
				prob = 254,
				ypos = 36
			}
		},
		data = {
			{
				param2 = 0,
				name = "air",
				prob = 0
			},
			{
				param2 = 0,
				name = "air",
				prob = 0
			},
			{
				param2 = 0,
				name = "air",
				prob = 0
			},
			{
				param2 = 0,
				name = "air",
				prob = 0
			},
			{
				param2 = 0,
				name = "air",
				prob = 0
			},
			{
				param2 = 0,
				name = "air",
				prob = 0
			},
			{
				param2 = 0,
				name = "air",
				prob = 0
			},
			{
				param2 = 0,
				name = "air",
				prob = 0
			},
			{
				param2 = 0,
				name = "air",
				prob = 0
			},
			{
				param2 = 0,
				name = "air",
				prob = 0
			},
			{
				param2 = 0,
				name = "air",
				prob = 0
			},
			{
				param2 = 0,
				name = "air",
				prob = 0
			},
			{
				param2 = 0,
				name = "air",
				prob = 0
			},
			{
				param2 = 0,
				name = "air",
				prob = 0
			},
			{
				param2 = 0,
				name = "air",
				prob = 0
			},
			{
				param2 = 0,
				name = "air",
				prob = 0
			},
			{
				param2 = 0,
				name = "air",
				prob = 0
			},
			{
				param2 = 0,
				name = "air",
				prob = 0
			},
			{
				param2 = 0,
				name = "air",
				prob = 0
			},
			{
				param2 = 0,
				name = "air",
				prob = 0
			},
			{
				param2 = 0,
				name = "air",
				prob = 0
			},
			{
				param2 = 0,
				prob = 254,
				name = "default:jungletree",
				force_place = true
			},
			{
				param2 = 0,
				name = "air",
				prob = 0
			},
			{
				param2 = 0,
				name = "air",
				prob = 0
			},
			{
				param2 = 0,
				name = "air",
				prob = 0
			},
			{
				param2 = 0,
				name = "air",
				prob = 0
			},
			{
				param2 = 0,
				name = "air",
				prob = 0
			},
			{
				param2 = 0,
				prob = 254,
				name = "default:jungletree",
				force_place = true
			},
			{
				param2 = 0,
				prob = 254,
				name = "default:jungletree",
				force_place = true
			},
			{
				param2 = 0,
				name = "air",
				prob = 0
			},
			{
				param2 = 0,
				name = "air",
				prob = 0
			},
			{
				param2 = 0,
				name = "air",
				prob = 0
			},
			{
				param2 = 0,
				name = "air",
				prob = 0
			},
			{
				param2 = 0,
				name = "air",
				prob = 0
			},
			{
				param2 = 0,
				prob = 254,
				name = "default:jungletree",
				force_place = true
			},
			{
				param2 = 0,
				prob = 254,
				name = "default:jungletree",
				force_place = true
			},
			{
				param2 = 0,
				name = "air",
				prob = 0
			},
			{
				param2 = 0,
				name = "air",
				prob = 0
			},
			{
				param2 = 0,
				name = "air",
				prob = 0
			},
			{
				param2 = 0,
				name = "air",
				prob = 0
			},
			{
				param2 = 0,
				name = "air",
				prob = 0
			},
			{
				param2 = 0,
				prob = 254,
				name = "default:jungletree",
				force_place = true
			},
			{
				param2 = 0,
				prob = 126,
				name = "default:jungletree",
				force_place = true
			},
			{
				param2 = 0,
				name = "air",
				prob = 0
			},
			{
				param2 = 0,
				name = "air",
				prob = 0
			},
			{
				param2 = 0,
				name = "air",
				prob = 0
			},
			{
				param2 = 0,
				name = "air",
				prob = 0
			},
			{
				param2 = 0,
				name = "air",
				prob = 0
			},
			{
				param2 = 0,
				prob = 126,
				name = "default:jungletree",
				force_place = true
			},
			{
				param2 = 0,
				name = "air",
				prob = 0
			},
			{
				param2 = 0,
				name = "air",
				prob = 0
			},
			{
				param2 = 0,
				name = "air",
				prob = 0
			},
			{
				param2 = 0,
				name = "air",
				prob = 0
			},
			{
				param2 = 0,
				name = "air",
				prob = 0
			},
			{
				param2 = 0,
				name = "air",
				prob = 0
			},
			{
				param2 = 0,
				name = "air",
				prob = 0
			},
			{
				param2 = 0,
				name = "air",
				prob = 0
			},
			{
				param2 = 0,
				name = "air",
				prob = 0
			},
			{
				param2 = 0,
				name = "air",
				prob = 0
			},
			{
				param2 = 0,
				name = "air",
				prob = 0
			},
			{
				param2 = 0,
				name = "air",
				prob = 0
			},
			{
				param2 = 0,
				name = "air",
				prob = 0
			},
			{
				param2 = 0,
				name = "air",
				prob = 0
			},
			{
				param2 = 0,
				name = "air",
				prob = 0
			},
			{
				param2 = 0,
				name = "air",
				prob = 0
			},
			{
				param2 = 0,
				name = "air",
				prob = 0
			},
			{
				param2 = 0,
				name = "air",
				prob = 0
			},
			{
				param2 = 0,
				name = "air",
				prob = 0
			},
			{
				param2 = 0,
				name = "air",
				prob = 0
			},
			{
				param2 = 0,
				name = "air",
				prob = 0
			},
			{
				param2 = 0,
				name = "air",
				prob = 0
			},
			{
				param2 = 0,
				name = "air",
				prob = 0
			},
			{
				param2 = 0,
				name = "air",
				prob = 0
			},
			{
				param2 = 0,
				name = "air",
				prob = 0
			},
			{
				param2 = 0,
				name = "air",
				prob = 0
			},
			{
				param2 = 0,
				name = "air",
				prob = 0
			},
			{
				param2 = 0,
				name = "air",
				prob = 0
			},
			{
				param2 = 0,
				name = "air",
				prob = 0
			},
			{
				param2 = 0,
				name = "air",
				prob = 0
			},
			{
				param2 = 0,
				name = "air",
				prob = 0
			},
			{
				param2 = 0,
				name = "air",
				prob = 0
			},
			{
				param2 = 0,
				name = "air",
				prob = 0
			},
			{
				param2 = 0,
				name = "air",
				prob = 0
			},
			{
				param2 = 0,
				name = "air",
				prob = 0
			},
			{
				param2 = 0,
				name = "air",
				prob = 0
			},
			{
				param2 = 0,
				name = "air",
				prob = 0
			},
			{
				param2 = 0,
				name = "air",
				prob = 0
			},
			{
				param2 = 0,
				name = "air",
				prob = 0
			},
			{
				param2 = 0,
				name = "air",
				prob = 0
			},
			{
				param2 = 0,
				name = "air",
				prob = 0
			},
			{
				param2 = 0,
				name = "air",
				prob = 0
			},
			{
				param2 = 0,
				name = "air",
				prob = 0
			},
			{
				param2 = 0,
				name = "air",
				prob = 0
			},
			{
				param2 = 0,
				name = "air",
				prob = 0
			},
			{
				param2 = 0,
				name = "air",
				prob = 0
			},
			{
				param2 = 0,
				name = "air",
				prob = 0
			},
			{
				param2 = 0,
				name = "air",
				prob = 0
			},
			{
				param2 = 0,
				name = "air",
				prob = 0
			},
			{
				param2 = 0,
				name = "air",
				prob = 0
			},
			{
				param2 = 0,
				name = "air",
				prob = 0
			},
			{
				param2 = 0,
				name = "air",
				prob = 0
			},
			{
				param2 = 0,
				name = "air",
				prob = 0
			},
			{
				param2 = 0,
				name = "air",
				prob = 0
			},
			{
				param2 = 0,
				name = "air",
				prob = 0
			},
			{
				param2 = 0,
				name = "air",
				prob = 0
			},
			{
				param2 = 0,
				name = "air",
				prob = 0
			},
			{
				param2 = 0,
				name = "air",
				prob = 0
			},
			{
				param2 = 0,
				name = "air",
				prob = 0
			},
			{
				param2 = 0,
				name = "air",
				prob = 0
			},
			{
				param2 = 0,
				name = "air",
				prob = 0
			},
			{
				param2 = 0,
				name = "air",
				prob = 0
			},
			{
				param2 = 0,
				name = "air",
				prob = 0
			},
			{
				param2 = 0,
				name = "air",
				prob = 0
			},
			{
				param2 = 0,
				name = "air",
				prob = 0
			},
			{
				param2 = 0,
				name = "air",
				prob = 0
			},
			{
				param2 = 0,
				name = "air",
				prob = 0
			},
			{
				param2 = 0,
				name = "air",
				prob = 0
			},
			{
				param2 = 0,
				name = "air",
				prob = 0
			},
			{
				param2 = 0,
				name = "air",
				prob = 0
			},
			{
				param2 = 0,
				name = "air",
				prob = 0
			},
			{
				param2 = 0,
				name = "air",
				prob = 0
			},
			{
				param2 = 0,
				name = "air",
				prob = 0
			},
			{
				param2 = 0,
				name = "air",
				prob = 0
			},
			{
				param2 = 0,
				name = "air",
				prob = 0
			},
			{
				param2 = 0,
				name = "air",
				prob = 0
			},
			{
				param2 = 0,
				name = "air",
				prob = 0
			},
			{
				param2 = 0,
				name = "air",
				prob = 0
			},
			{
				param2 = 0,
				name = "air",
				prob = 0
			},
			{
				param2 = 0,
				name = "air",
				prob = 0
			},
			{
				param2 = 0,
				name = "air",
				prob = 0
			},
			{
				param2 = 0,
				name = "air",
				prob = 0
			},
			{
				param2 = 0,
				name = "air",
				prob = 0
			},
			{
				param2 = 0,
				name = "air",
				prob = 0
			},
			{
				param2 = 0,
				name = "default:jungleleaves",
				prob = 94
			},
			{
				param2 = 0,
				name = "default:jungleleaves",
				prob = 94
			},
			{
				param2 = 0,
				name = "default:jungleleaves",
				prob = 94
			},
			{
				param2 = 0,
				name = "air",
				prob = 0
			},
			{
				param2 = 0,
				name = "air",
				prob = 0
			},
			{
				param2 = 0,
				name = "air",
				prob = 0
			},
			{
				param2 = 0,
				name = "air",
				prob = 0
			},
			{
				param2 = 0,
				name = "air",
				prob = 0
			},
			{
				param2 = 0,
				name = "air",
				prob = 0
			},
			{
				param2 = 0,
				name = "air",
				prob = 0
			},
			{
				param2 = 0,
				name = "air",
				prob = 0
			},
			{
				param2 = 0,
				name = "air",
				prob = 0
			},
			{
				param2 = 0,
				name = "air",
				prob = 0
			},
			{
				param2 = 0,
				name = "air",
				prob = 0
			},
			{
				param2 = 0,
				name = "air",
				prob = 0
			},
			{
				param2 = 0,
				name = "air",
				prob = 0
			},
			{
				param2 = 0,
				name = "air",
				prob = 0
			},
			{
				param2 = 0,
				name = "air",
				prob = 0
			},
			{
				param2 = 0,
				name = "default:jungleleaves",
				prob = 94
			},
			{
				param2 = 0,
				name = "default:jungleleaves",
				prob = 94
			},
			{
				param2 = 0,
				name = "default:jungleleaves",
				prob = 94
			},
			{
				param2 = 0,
				name = "air",
				prob = 0
			},
			{
				param2 = 0,
				name = "air",
				prob = 0
			},
			{
				param2 = 0,
				name = "air",
				prob = 0
			},
			{
				param2 = 0,
				name = "air",
				prob = 0
			},
			{
				param2 = 0,
				name = "air",
				prob = 0
			},
			{
				param2 = 0,
				name = "air",
				prob = 0
			},
			{
				param2 = 0,
				name = "air",
				prob = 0
			},
			{
				param2 = 0,
				name = "air",
				prob = 0
			},
			{
				param2 = 0,
				name = "air",
				prob = 0
			},
			{
				param2 = 0,
				name = "air",
				prob = 0
			},
			{
				param2 = 0,
				name = "air",
				prob = 0
			},
			{
				param2 = 0,
				name = "air",
				prob = 0
			},
			{
				param2 = 0,
				name = "air",
				prob = 0
			},
			{
				param2 = 0,
				name = "air",
				prob = 0
			},
			{
				param2 = 0,
				name = "air",
				prob = 0
			},
			{
				param2 = 0,
				name = "air",
				prob = 0
			},
			{
				param2 = 0,
				name = "default:jungleleaves",
				prob = 94
			},
			{
				param2 = 0,
				name = "default:jungleleaves",
				prob = 94
			},
			{
				param2 = 0,
				name = "default:jungleleaves",
				prob = 94
			},
			{
				param2 = 0,
				name = "air",
				prob = 0
			},
			{
				param2 = 0,
				name = "air",
				prob = 0
			},
			{
				param2 = 0,
				name = "air",
				prob = 0
			},
			{
				param2 = 0,
				name = "air",
				prob = 0
			},
			{
				param2 = 0,
				name = "air",
				prob = 0
			},
			{
				param2 = 0,
				name = "air",
				prob = 0
			},
			{
				param2 = 0,
				name = "air",
				prob = 0
			},
			{
				param2 = 0,
				name = "air",
				prob = 0
			},
			{
				param2 = 0,
				name = "air",
				prob = 0
			},
			{
				param2 = 0,
				name = "air",
				prob = 0
			},
			{
				param2 = 0,
				name = "air",
				prob = 0
			},
			{
				param2 = 0,
				name = "air",
				prob = 0
			},
			{
				param2 = 0,
				name = "air",
				prob = 0
			},
			{
				param2 = 0,
				name = "air",
				prob = 0
			},
			{
				param2 = 0,
				name = "air",
				prob = 0
			},
			{
				param2 = 0,
				name = "air",
				prob = 0
			},
			{
				param2 = 0,
				name = "default:jungleleaves",
				prob = 94
			},
			{
				param2 = 0,
				name = "default:jungleleaves",
				prob = 94
			},
			{
				param2 = 0,
				name = "default:jungleleaves",
				prob = 94
			},
			{
				param2 = 0,
				name = "air",
				prob = 0
			},
			{
				param2 = 0,
				name = "air",
				prob = 0
			},
			{
				param2 = 0,
				name = "air",
				prob = 0
			},
			{
				param2 = 0,
				name = "air",
				prob = 0
			},
			{
				param2 = 0,
				name = "air",
				prob = 0
			},
			{
				param2 = 0,
				name = "air",
				prob = 0
			},
			{
				param2 = 0,
				name = "air",
				prob = 0
			},
			{
				param2 = 0,
				name = "air",
				prob = 0
			},
			{
				param2 = 0,
				name = "air",
				prob = 0
			},
			{
				param2 = 0,
				name = "air",
				prob = 0
			},
			{
				param2 = 0,
				name = "air",
				prob = 0
			},
			{
				param2 = 0,
				name = "air",
				prob = 0
			},
			{
				param2 = 0,
				name = "air",
				prob = 0
			},
			{
				param2 = 0,
				name = "air",
				prob = 0
			},
			{
				param2 = 0,
				name = "air",
				prob = 0
			},
			{
				param2 = 0,
				name = "default:jungleleaves",
				prob = 94
			},
			{
				param2 = 0,
				name = "default:jungleleaves",
				prob = 94
			},
			{
				param2 = 0,
				name = "default:jungleleaves",
				prob = 94
			},
			{
				param2 = 0,
				name = "air",
				prob = 0
			},
			{
				param2 = 0,
				name = "air",
				prob = 0
			},
			{
				param2 = 0,
				name = "air",
				prob = 0
			},
			{
				param2 = 0,
				name = "air",
				prob = 0
			},
			{
				param2 = 0,
				name = "air",
				prob = 0
			},
			{
				param2 = 0,
				name = "air",
				prob = 0
			},
			{
				param2 = 0,
				name = "air",
				prob = 0
			},
			{
				param2 = 0,
				name = "air",
				prob = 0
			},
			{
				param2 = 0,
				name = "air",
				prob = 0
			},
			{
				param2 = 0,
				name = "air",
				prob = 0
			},
			{
				param2 = 0,
				name = "air",
				prob = 0
			},
			{
				param2 = 0,
				name = "air",
				prob = 0
			},
			{
				param2 = 0,
				name = "air",
				prob = 0
			},
			{
				param2 = 0,
				name = "air",
				prob = 0
			},
			{
				param2 = 0,
				name = "air",
				prob = 0
			},
			{
				param2 = 0,
				name = "default:jungleleaves",
				prob = 126
			},
			{
				param2 = 0,
				name = "default:jungleleaves",
				prob = 126
			},
			{
				param2 = 0,
				name = "default:jungleleaves",
				prob = 126
			},
			{
				param2 = 0,
				name = "default:jungleleaves",
				prob = 126
			},
			{
				param2 = 0,
				name = "default:jungleleaves",
				prob = 126
			},
			{
				param2 = 0,
				name = "air",
				prob = 0
			},
			{
				param2 = 0,
				name = "air",
				prob = 0
			},
			{
				param2 = 0,
				name = "default:jungleleaves",
				prob = 94
			},
			{
				param2 = 0,
				name = "default:jungleleaves",
				prob = 94
			},
			{
				param2 = 0,
				name = "default:jungleleaves",
				prob = 94
			},
			{
				param2 = 0,
				name = "default:jungleleaves",
				prob = 94
			},
			{
				param2 = 0,
				name = "default:jungleleaves",
				prob = 94
			},
			{
				param2 = 0,
				name = "air",
				prob = 0
			},
			{
				param2 = 0,
				name = "air",
				prob = 0
			},
			{
				param2 = 0,
				name = "default:jungleleaves",
				prob = 94
			},
			{
				param2 = 0,
				name = "default:jungleleaves",
				prob = 94
			},
			{
				param2 = 0,
				name = "default:jungleleaves",
				prob = 94
			},
			{
				param2 = 0,
				name = "default:jungleleaves",
				prob = 94
			},
			{
				param2 = 0,
				name = "default:jungleleaves",
				prob = 94
			},
			{
				param2 = 0,
				name = "air",
				prob = 0
			},
			{
				param2 = 0,
				name = "air",
				prob = 0
			},
			{
				param2 = 0,
				name = "default:jungleleaves",
				prob = 94
			},
			{
				param2 = 0,
				name = "default:jungleleaves",
				prob = 94
			},
			{
				param2 = 0,
				name = "default:jungleleaves",
				prob = 94
			},
			{
				param2 = 0,
				name = "default:jungleleaves",
				prob = 94
			},
			{
				param2 = 0,
				name = "default:jungleleaves",
				prob = 94
			},
			{
				param2 = 0,
				name = "air",
				prob = 0
			},
			{
				param2 = 0,
				name = "air",
				prob = 0
			},
			{
				param2 = 0,
				name = "air",
				prob = 0
			},
			{
				param2 = 0,
				name = "air",
				prob = 0
			},
			{
				param2 = 0,
				name = "air",
				prob = 0
			},
			{
				param2 = 0,
				name = "air",
				prob = 0
			},
			{
				param2 = 0,
				name = "air",
				prob = 0
			},
			{
				param2 = 0,
				name = "air",
				prob = 0
			},
			{
				param2 = 0,
				name = "air",
				prob = 0
			},
			{
				param2 = 0,
				name = "air",
				prob = 0
			},
			{
				param2 = 0,
				name = "air",
				prob = 0
			},
			{
				param2 = 0,
				name = "air",
				prob = 0
			},
			{
				param2 = 0,
				name = "air",
				prob = 0
			},
			{
				param2 = 0,
				name = "air",
				prob = 0
			},
			{
				param2 = 0,
				name = "air",
				prob = 0
			},
			{
				param2 = 0,
				name = "air",
				prob = 0
			},
			{
				param2 = 0,
				name = "air",
				prob = 0
			},
			{
				param2 = 0,
				prob = 254,
				name = "default:jungletree",
				force_place = true
			},
			{
				param2 = 0,
				name = "air",
				prob = 0
			},
			{
				param2 = 0,
				prob = 254,
				name = "default:jungletree",
				force_place = true
			},
			{
				param2 = 0,
				name = "air",
				prob = 0
			},
			{
				param2 = 0,
				name = "air",
				prob = 0
			},
			{
				param2 = 0,
				name = "air",
				prob = 0
			},
			{
				param2 = 0,
				prob = 254,
				name = "default:jungletree",
				force_place = true
			},
			{
				param2 = 0,
				prob = 254,
				name = "default:jungletree",
				force_place = true
			},
			{
				param2 = 0,
				name = "air",
				prob = 0
			},
			{
				param2 = 0,
				prob = 254,
				name = "default:jungletree",
				force_place = true
			},
			{
				param2 = 0,
				prob = 254,
				name = "default:jungletree",
				force_place = true
			},
			{
				param2 = 0,
				name = "air",
				prob = 0
			},
			{
				param2 = 0,
				name = "air",
				prob = 0
			},
			{
				param2 = 0,
				prob = 254,
				name = "default:jungletree",
				force_place = true
			},
			{
				param2 = 0,
				prob = 254,
				name = "default:jungletree",
				force_place = true
			},
			{
				param2 = 0,
				name = "air",
				prob = 0
			},
			{
				param2 = 0,
				prob = 254,
				name = "default:jungletree",
				force_place = true
			},
			{
				param2 = 0,
				prob = 254,
				name = "default:jungletree",
				force_place = true
			},
			{
				param2 = 0,
				name = "air",
				prob = 0
			},
			{
				param2 = 0,
				name = "air",
				prob = 0
			},
			{
				param2 = 0,
				prob = 254,
				name = "default:jungletree",
				force_place = true
			},
			{
				param2 = 0,
				prob = 254,
				name = "default:jungletree",
				force_place = true
			},
			{
				param2 = 0,
				name = "air",
				prob = 0
			},
			{
				param2 = 0,
				prob = 254,
				name = "default:jungletree",
				force_place = true
			},
			{
				param2 = 0,
				prob = 254,
				name = "default:jungletree",
				force_place = true
			},
			{
				param2 = 0,
				name = "air",
				prob = 0
			},
			{
				param2 = 0,
				name = "air",
				prob = 0
			},
			{
				param2 = 0,
				prob = 254,
				name = "default:jungletree",
				force_place = true
			},
			{
				param2 = 0,
				prob = 254,
				name = "default:jungletree",
				force_place = true
			},
			{
				param2 = 0,
				name = "air",
				prob = 0
			},
			{
				param2 = 0,
				prob = 254,
				name = "default:jungletree",
				force_place = true
			},
			{
				param2 = 0,
				prob = 254,
				name = "default:jungletree",
				force_place = true
			},
			{
				param2 = 0,
				name = "air",
				prob = 0
			},
			{
				param2 = 0,
				name = "air",
				prob = 0
			},
			{
				param2 = 0,
				prob = 254,
				name = "default:jungletree",
				force_place = true
			},
			{
				param2 = 0,
				prob = 254,
				name = "default:jungletree",
				force_place = true
			},
			{
				param2 = 0,
				name = "air",
				prob = 0
			},
			{
				param2 = 0,
				prob = 254,
				name = "default:jungletree",
				force_place = true
			},
			{
				param2 = 0,
				prob = 254,
				name = "default:jungletree",
				force_place = true
			},
			{
				param2 = 0,
				name = "air",
				prob = 0
			},
			{
				param2 = 0,
				name = "air",
				prob = 0
			},
			{
				param2 = 0,
				prob = 126,
				name = "default:jungletree",
				force_place = true
			},
			{
				param2 = 0,
				prob = 254,
				name = "default:jungletree",
				force_place = true
			},
			{
				param2 = 0,
				name = "air",
				prob = 0
			},
			{
				param2 = 0,
				prob = 254,
				name = "default:jungletree",
				force_place = true
			},
			{
				param2 = 0,
				prob = 126,
				name = "default:jungletree",
				force_place = true
			},
			{
				param2 = 0,
				name = "air",
				prob = 0
			},
			{
				param2 = 0,
				name = "air",
				prob = 0
			},
			{
				param2 = 0,
				name = "air",
				prob = 0
			},
			{
				param2 = 0,
				prob = 126,
				name = "default:jungletree",
				force_place = true
			},
			{
				param2 = 0,
				name = "air",
				prob = 0
			},
			{
				param2 = 0,
				prob = 126,
				name = "default:jungletree",
				force_place = true
			},
			{
				param2 = 0,
				name = "air",
				prob = 0
			},
			{
				param2 = 0,
				name = "air",
				prob = 0
			},
			{
				param2 = 0,
				name = "air",
				prob = 0
			},
			{
				param2 = 0,
				name = "air",
				prob = 0
			},
			{
				param2 = 0,
				name = "air",
				prob = 0
			},
			{
				param2 = 0,
				name = "air",
				prob = 0
			},
			{
				param2 = 0,
				name = "air",
				prob = 0
			},
			{
				param2 = 0,
				name = "air",
				prob = 0
			},
			{
				param2 = 0,
				name = "air",
				prob = 0
			},
			{
				param2 = 0,
				name = "air",
				prob = 0
			},
			{
				param2 = 0,
				name = "air",
				prob = 0
			},
			{
				param2 = 0,
				name = "air",
				prob = 0
			},
			{
				param2 = 0,
				name = "air",
				prob = 0
			},
			{
				param2 = 0,
				name = "air",
				prob = 0
			},
			{
				param2 = 0,
				name = "air",
				prob = 0
			},
			{
				param2 = 0,
				name = "air",
				prob = 0
			},
			{
				param2 = 0,
				name = "air",
				prob = 0
			},
			{
				param2 = 0,
				name = "air",
				prob = 0
			},
			{
				param2 = 0,
				name = "air",
				prob = 0
			},
			{
				param2 = 0,
				name = "air",
				prob = 0
			},
			{
				param2 = 0,
				name = "air",
				prob = 0
			},
			{
				param2 = 0,
				name = "air",
				prob = 0
			},
			{
				param2 = 0,
				name = "air",
				prob = 0
			},
			{
				param2 = 0,
				name = "air",
				prob = 0
			},
			{
				param2 = 0,
				name = "air",
				prob = 0
			},
			{
				param2 = 0,
				name = "air",
				prob = 0
			},
			{
				param2 = 0,
				name = "air",
				prob = 0
			},
			{
				param2 = 0,
				name = "air",
				prob = 0
			},
			{
				param2 = 0,
				name = "air",
				prob = 0
			},
			{
				param2 = 0,
				name = "air",
				prob = 0
			},
			{
				param2 = 0,
				name = "air",
				prob = 0
			},
			{
				param2 = 0,
				name = "air",
				prob = 0
			},
			{
				param2 = 0,
				name = "air",
				prob = 0
			},
			{
				param2 = 0,
				name = "air",
				prob = 0
			},
			{
				param2 = 0,
				name = "air",
				prob = 0
			},
			{
				param2 = 0,
				name = "air",
				prob = 0
			},
			{
				param2 = 0,
				name = "air",
				prob = 0
			},
			{
				param2 = 0,
				name = "air",
				prob = 0
			},
			{
				param2 = 0,
				name = "air",
				prob = 0
			},
			{
				param2 = 0,
				name = "air",
				prob = 0
			},
			{
				param2 = 0,
				name = "air",
				prob = 0
			},
			{
				param2 = 0,
				name = "air",
				prob = 0
			},
			{
				param2 = 0,
				name = "air",
				prob = 0
			},
			{
				param2 = 0,
				name = "air",
				prob = 0
			},
			{
				param2 = 0,
				name = "air",
				prob = 0
			},
			{
				param2 = 0,
				name = "air",
				prob = 0
			},
			{
				param2 = 0,
				name = "air",
				prob = 0
			},
			{
				param2 = 0,
				name = "air",
				prob = 0
			},
			{
				param2 = 0,
				name = "air",
				prob = 0
			},
			{
				param2 = 0,
				name = "air",
				prob = 0
			},
			{
				param2 = 0,
				name = "air",
				prob = 0
			},
			{
				param2 = 0,
				name = "air",
				prob = 0
			},
			{
				param2 = 0,
				name = "air",
				prob = 0
			},
			{
				param2 = 0,
				name = "air",
				prob = 0
			},
			{
				param2 = 0,
				name = "air",
				prob = 0
			},
			{
				param2 = 0,
				name = "air",
				prob = 0
			},
			{
				param2 = 0,
				name = "air",
				prob = 0
			},
			{
				param2 = 0,
				name = "air",
				prob = 0
			},
			{
				param2 = 0,
				name = "air",
				prob = 0
			},
			{
				param2 = 0,
				name = "air",
				prob = 0
			},
			{
				param2 = 0,
				name = "air",
				prob = 0
			},
			{
				param2 = 0,
				name = "air",
				prob = 0
			},
			{
				param2 = 0,
				name = "air",
				prob = 0
			},
			{
				param2 = 0,
				name = "air",
				prob = 0
			},
			{
				param2 = 0,
				name = "air",
				prob = 0
			},
			{
				param2 = 0,
				name = "air",
				prob = 0
			},
			{
				param2 = 0,
				name = "air",
				prob = 0
			},
			{
				param2 = 0,
				name = "air",
				prob = 0
			},
			{
				param2 = 0,
				name = "air",
				prob = 0
			},
			{
				param2 = 0,
				name = "air",
				prob = 0
			},
			{
				param2 = 0,
				name = "air",
				prob = 0
			},
			{
				param2 = 0,
				name = "air",
				prob = 0
			},
			{
				param2 = 0,
				name = "default:jungleleaves",
				prob = 94
			},
			{
				param2 = 0,
				prob = 254,
				name = "default:jungletree",
				force_place = true
			},
			{
				param2 = 0,
				name = "default:jungleleaves",
				prob = 94
			},
			{
				param2 = 0,
				name = "air",
				prob = 0
			},
			{
				param2 = 0,
				name = "air",
				prob = 0
			},
			{
				param2 = 0,
				name = "air",
				prob = 0
			},
			{
				param2 = 0,
				name = "air",
				prob = 0
			},
			{
				param2 = 0,
				name = "air",
				prob = 0
			},
			{
				param2 = 0,
				name = "air",
				prob = 0
			},
			{
				param2 = 0,
				name = "air",
				prob = 0
			},
			{
				param2 = 0,
				name = "air",
				prob = 0
			},
			{
				param2 = 0,
				name = "air",
				prob = 0
			},
			{
				param2 = 0,
				name = "air",
				prob = 0
			},
			{
				param2 = 0,
				name = "air",
				prob = 0
			},
			{
				param2 = 0,
				name = "air",
				prob = 0
			},
			{
				param2 = 0,
				name = "air",
				prob = 0
			},
			{
				param2 = 0,
				name = "air",
				prob = 0
			},
			{
				param2 = 0,
				name = "air",
				prob = 0
			},
			{
				param2 = 0,
				name = "default:jungleleaves",
				prob = 94
			},
			{
				param2 = 0,
				prob = 254,
				name = "default:jungletree",
				force_place = true
			},
			{
				param2 = 0,
				name = "default:jungleleaves",
				prob = 94
			},
			{
				param2 = 0,
				name = "air",
				prob = 0
			},
			{
				param2 = 0,
				name = "air",
				prob = 0
			},
			{
				param2 = 0,
				name = "air",
				prob = 0
			},
			{
				param2 = 0,
				name = "air",
				prob = 0
			},
			{
				param2 = 0,
				name = "air",
				prob = 0
			},
			{
				param2 = 0,
				name = "air",
				prob = 0
			},
			{
				param2 = 0,
				name = "air",
				prob = 0
			},
			{
				param2 = 0,
				name = "air",
				prob = 0
			},
			{
				param2 = 0,
				name = "air",
				prob = 0
			},
			{
				param2 = 0,
				name = "air",
				prob = 0
			},
			{
				param2 = 0,
				name = "air",
				prob = 0
			},
			{
				param2 = 0,
				name = "air",
				prob = 0
			},
			{
				param2 = 0,
				name = "air",
				prob = 0
			},
			{
				param2 = 0,
				name = "air",
				prob = 0
			},
			{
				param2 = 0,
				name = "air",
				prob = 0
			},
			{
				param2 = 0,
				name = "air",
				prob = 0
			},
			{
				param2 = 0,
				name = "default:jungleleaves",
				prob = 94
			},
			{
				param2 = 0,
				prob = 254,
				name = "default:jungletree",
				force_place = true
			},
			{
				param2 = 0,
				name = "default:jungleleaves",
				prob = 94
			},
			{
				param2 = 0,
				name = "air",
				prob = 0
			},
			{
				param2 = 0,
				name = "air",
				prob = 0
			},
			{
				param2 = 0,
				name = "air",
				prob = 0
			},
			{
				param2 = 0,
				name = "air",
				prob = 0
			},
			{
				param2 = 0,
				name = "air",
				prob = 0
			},
			{
				param2 = 0,
				name = "air",
				prob = 0
			},
			{
				param2 = 0,
				name = "air",
				prob = 0
			},
			{
				param2 = 0,
				name = "air",
				prob = 0
			},
			{
				param2 = 0,
				name = "air",
				prob = 0
			},
			{
				param2 = 0,
				name = "air",
				prob = 0
			},
			{
				param2 = 0,
				name = "air",
				prob = 0
			},
			{
				param2 = 0,
				name = "air",
				prob = 0
			},
			{
				param2 = 0,
				name = "air",
				prob = 0
			},
			{
				param2 = 0,
				name = "air",
				prob = 0
			},
			{
				param2 = 0,
				name = "air",
				prob = 0
			},
			{
				param2 = 0,
				name = "air",
				prob = 0
			},
			{
				param2 = 0,
				name = "default:jungleleaves",
				prob = 94
			},
			{
				param2 = 0,
				prob = 254,
				name = "default:jungletree",
				force_place = true
			},
			{
				param2 = 0,
				name = "default:jungleleaves",
				prob = 94
			},
			{
				param2 = 0,
				name = "air",
				prob = 0
			},
			{
				param2 = 0,
				name = "air",
				prob = 0
			},
			{
				param2 = 0,
				name = "air",
				prob = 0
			},
			{
				param2 = 0,
				name = "air",
				prob = 0
			},
			{
				param2 = 0,
				name = "air",
				prob = 0
			},
			{
				param2 = 0,
				name = "air",
				prob = 0
			},
			{
				param2 = 0,
				name = "air",
				prob = 0
			},
			{
				param2 = 0,
				name = "air",
				prob = 0
			},
			{
				param2 = 0,
				name = "air",
				prob = 0
			},
			{
				param2 = 0,
				name = "air",
				prob = 0
			},
			{
				param2 = 0,
				name = "air",
				prob = 0
			},
			{
				param2 = 0,
				name = "air",
				prob = 0
			},
			{
				param2 = 0,
				name = "air",
				prob = 0
			},
			{
				param2 = 0,
				name = "air",
				prob = 0
			},
			{
				param2 = 0,
				name = "air",
				prob = 0
			},
			{
				param2 = 0,
				name = "default:jungleleaves",
				prob = 94
			},
			{
				param2 = 0,
				prob = 254,
				name = "default:jungletree",
				force_place = true
			},
			{
				param2 = 0,
				name = "default:jungleleaves",
				prob = 94
			},
			{
				param2 = 0,
				name = "air",
				prob = 0
			},
			{
				param2 = 0,
				name = "air",
				prob = 0
			},
			{
				param2 = 0,
				name = "air",
				prob = 0
			},
			{
				param2 = 0,
				name = "air",
				prob = 0
			},
			{
				param2 = 0,
				name = "air",
				prob = 0
			},
			{
				param2 = 0,
				name = "air",
				prob = 0
			},
			{
				param2 = 0,
				name = "air",
				prob = 0
			},
			{
				param2 = 0,
				name = "air",
				prob = 0
			},
			{
				param2 = 0,
				name = "air",
				prob = 0
			},
			{
				param2 = 0,
				name = "air",
				prob = 0
			},
			{
				param2 = 0,
				name = "air",
				prob = 0
			},
			{
				param2 = 0,
				name = "air",
				prob = 0
			},
			{
				param2 = 0,
				name = "air",
				prob = 0
			},
			{
				param2 = 0,
				name = "air",
				prob = 0
			},
			{
				param2 = 0,
				name = "default:jungleleaves",
				prob = 126
			},
			{
				param2 = 0,
				name = "air",
				prob = 0
			},
			{
				param2 = 0,
				name = "air",
				prob = 0
			},
			{
				param2 = 0,
				name = "air",
				prob = 0
			},
			{
				param2 = 0,
				name = "air",
				prob = 0
			},
			{
				param2 = 0,
				name = "air",
				prob = 0
			},
			{
				param2 = 0,
				name = "default:jungleleaves",
				prob = 126
			},
			{
				param2 = 0,
				name = "default:jungleleaves",
				prob = 94
			},
			{
				param2 = 0,
				name = "default:jungleleaves",
				prob = 126
			},
			{
				param2 = 0,
				name = "air",
				prob = 0
			},
			{
				param2 = 0,
				name = "air",
				prob = 0
			},
			{
				param2 = 0,
				name = "air",
				prob = 0
			},
			{
				param2 = 0,
				name = "default:jungleleaves",
				prob = 126
			},
			{
				param2 = 0,
				name = "default:jungleleaves",
				prob = 94
			},
			{
				param2 = 0,
				name = "default:jungleleaves",
				prob = 94
			},
			{
				param2 = 0,
				prob = 254,
				name = "default:jungletree",
				force_place = true
			},
			{
				param2 = 0,
				name = "default:jungleleaves",
				prob = 126
			},
			{
				param2 = 0,
				name = "default:jungleleaves",
				prob = 126
			},
			{
				param2 = 0,
				name = "default:jungleleaves",
				prob = 126
			},
			{
				param2 = 0,
				prob = 254,
				name = "default:jungletree",
				force_place = true
			},
			{
				param2 = 0,
				name = "default:jungleleaves",
				prob = 94
			},
			{
				param2 = 0,
				name = "default:jungleleaves",
				prob = 94
			},
			{
				param2 = 0,
				name = "default:jungleleaves",
				prob = 126
			},
			{
				param2 = 0,
				name = "default:jungleleaves",
				prob = 126
			},
			{
				param2 = 0,
				name = "default:jungleleaves",
				prob = 126
			},
			{
				param2 = 0,
				name = "default:jungleleaves",
				prob = 126
			},
			{
				param2 = 0,
				name = "default:jungleleaves",
				prob = 126
			},
			{
				param2 = 0,
				name = "default:jungleleaves",
				prob = 94
			},
			{
				param2 = 0,
				name = "air",
				prob = 0
			},
			{
				param2 = 0,
				name = "default:jungleleaves",
				prob = 94
			},
			{
				param2 = 0,
				name = "default:jungleleaves",
				prob = 94
			},
			{
				param2 = 0,
				name = "default:jungleleaves",
				prob = 94
			},
			{
				param2 = 0,
				name = "default:jungleleaves",
				prob = 94
			},
			{
				param2 = 0,
				name = "default:jungleleaves",
				prob = 94
			},
			{
				param2 = 0,
				name = "air",
				prob = 0
			},
			{
				param2 = 0,
				name = "air",
				prob = 0
			},
			{
				param2 = 0,
				name = "air",
				prob = 0
			},
			{
				param2 = 0,
				prob = 254,
				name = "default:jungletree",
				force_place = true
			},
			{
				param2 = 0,
				name = "air",
				prob = 0
			},
			{
				param2 = 0,
				prob = 254,
				name = "default:jungletree",
				force_place = true
			},
			{
				param2 = 0,
				name = "air",
				prob = 0
			},
			{
				param2 = 0,
				name = "air",
				prob = 0
			},
			{
				param2 = 0,
				name = "air",
				prob = 0
			},
			{
				param2 = 0,
				prob = 254,
				name = "default:jungletree",
				force_place = true
			},
			{
				param2 = 0,
				prob = 254,
				name = "default:jungletree",
				force_place = true
			},
			{
				param2 = 0,
				name = "air",
				prob = 0
			},
			{
				param2 = 0,
				prob = 254,
				name = "default:jungletree",
				force_place = true
			},
			{
				param2 = 0,
				prob = 254,
				name = "default:jungletree",
				force_place = true
			},
			{
				param2 = 0,
				name = "air",
				prob = 0
			},
			{
				param2 = 0,
				name = "air",
				prob = 0
			},
			{
				param2 = 0,
				prob = 254,
				name = "default:jungletree",
				force_place = true
			},
			{
				param2 = 0,
				prob = 254,
				name = "default:jungletree",
				force_place = true
			},
			{
				param2 = 0,
				name = "air",
				prob = 0
			},
			{
				param2 = 0,
				prob = 254,
				name = "default:jungletree",
				force_place = true
			},
			{
				param2 = 0,
				prob = 254,
				name = "default:jungletree",
				force_place = true
			},
			{
				param2 = 0,
				name = "air",
				prob = 0
			},
			{
				param2 = 0,
				name = "air",
				prob = 0
			},
			{
				param2 = 0,
				prob = 254,
				name = "default:jungletree",
				force_place = true
			},
			{
				param2 = 0,
				prob = 254,
				name = "default:jungletree",
				force_place = true
			},
			{
				param2 = 0,
				name = "air",
				prob = 0
			},
			{
				param2 = 0,
				prob = 254,
				name = "default:jungletree",
				force_place = true
			},
			{
				param2 = 0,
				prob = 254,
				name = "default:jungletree",
				force_place = true
			},
			{
				param2 = 0,
				name = "air",
				prob = 0
			},
			{
				param2 = 0,
				name = "air",
				prob = 0
			},
			{
				param2 = 0,
				prob = 254,
				name = "default:jungletree",
				force_place = true
			},
			{
				param2 = 0,
				prob = 254,
				name = "default:jungletree",
				force_place = true
			},
			{
				param2 = 0,
				prob = 254,
				name = "default:jungletree",
				force_place = true
			},
			{
				param2 = 0,
				prob = 254,
				name = "default:jungletree",
				force_place = true
			},
			{
				param2 = 0,
				prob = 254,
				name = "default:jungletree",
				force_place = true
			},
			{
				param2 = 0,
				name = "air",
				prob = 0
			},
			{
				param2 = 0,
				name = "air",
				prob = 0
			},
			{
				param2 = 0,
				prob = 254,
				name = "default:jungletree",
				force_place = true
			},
			{
				param2 = 0,
				prob = 254,
				name = "default:jungletree",
				force_place = true
			},
			{
				param2 = 0,
				prob = 254,
				name = "default:jungletree",
				force_place = true
			},
			{
				param2 = 0,
				prob = 254,
				name = "default:jungletree",
				force_place = true
			},
			{
				param2 = 0,
				prob = 254,
				name = "default:jungletree",
				force_place = true
			},
			{
				param2 = 0,
				name = "air",
				prob = 0
			},
			{
				param2 = 0,
				name = "air",
				prob = 0
			},
			{
				param2 = 0,
				prob = 254,
				name = "default:jungletree",
				force_place = true
			},
			{
				param2 = 0,
				prob = 254,
				name = "default:jungletree",
				force_place = true
			},
			{
				param2 = 0,
				prob = 254,
				name = "default:jungletree",
				force_place = true
			},
			{
				param2 = 0,
				prob = 254,
				name = "default:jungletree",
				force_place = true
			},
			{
				param2 = 0,
				prob = 254,
				name = "default:jungletree",
				force_place = true
			},
			{
				param2 = 0,
				name = "air",
				prob = 0
			},
			{
				param2 = 0,
				name = "air",
				prob = 0
			},
			{
				param2 = 0,
				prob = 254,
				name = "default:jungletree",
				force_place = true
			},
			{
				param2 = 0,
				prob = 254,
				name = "default:jungletree",
				force_place = true
			},
			{
				param2 = 0,
				prob = 254,
				name = "default:jungletree",
				force_place = true
			},
			{
				param2 = 0,
				prob = 254,
				name = "default:jungletree",
				force_place = true
			},
			{
				param2 = 0,
				prob = 254,
				name = "default:jungletree",
				force_place = true
			},
			{
				param2 = 0,
				name = "air",
				prob = 0
			},
			{
				param2 = 0,
				name = "air",
				prob = 0
			},
			{
				param2 = 0,
				prob = 126,
				name = "default:jungletree",
				force_place = true
			},
			{
				param2 = 0,
				prob = 254,
				name = "default:jungletree",
				force_place = true
			},
			{
				param2 = 0,
				prob = 254,
				name = "default:jungletree",
				force_place = true
			},
			{
				param2 = 0,
				prob = 254,
				name = "default:jungletree",
				force_place = true
			},
			{
				param2 = 0,
				prob = 126,
				name = "default:jungletree",
				force_place = true
			},
			{
				param2 = 0,
				name = "air",
				prob = 0
			},
			{
				param2 = 0,
				name = "air",
				prob = 0
			},
			{
				param2 = 0,
				name = "air",
				prob = 0
			},
			{
				param2 = 0,
				prob = 254,
				name = "default:jungletree",
				force_place = true
			},
			{
				param2 = 0,
				prob = 254,
				name = "default:jungletree",
				force_place = true
			},
			{
				param2 = 0,
				prob = 254,
				name = "default:jungletree",
				force_place = true
			},
			{
				param2 = 0,
				name = "air",
				prob = 0
			},
			{
				param2 = 0,
				name = "air",
				prob = 0
			},
			{
				param2 = 0,
				name = "air",
				prob = 0
			},
			{
				param2 = 0,
				name = "air",
				prob = 0
			},
			{
				param2 = 0,
				prob = 254,
				name = "default:jungletree",
				force_place = true
			},
			{
				param2 = 0,
				prob = 254,
				name = "default:jungletree",
				force_place = true
			},
			{
				param2 = 0,
				prob = 254,
				name = "default:jungletree",
				force_place = true
			},
			{
				param2 = 0,
				name = "air",
				prob = 0
			},
			{
				param2 = 0,
				name = "air",
				prob = 0
			},
			{
				param2 = 0,
				name = "air",
				prob = 0
			},
			{
				param2 = 0,
				name = "air",
				prob = 0
			},
			{
				param2 = 0,
				prob = 254,
				name = "default:jungletree",
				force_place = true
			},
			{
				param2 = 0,
				prob = 254,
				name = "default:jungletree",
				force_place = true
			},
			{
				param2 = 0,
				prob = 254,
				name = "default:jungletree",
				force_place = true
			},
			{
				param2 = 0,
				name = "air",
				prob = 0
			},
			{
				param2 = 0,
				name = "air",
				prob = 0
			},
			{
				param2 = 0,
				name = "air",
				prob = 0
			},
			{
				param2 = 0,
				name = "air",
				prob = 0
			},
			{
				param2 = 0,
				prob = 254,
				name = "default:jungletree",
				force_place = true
			},
			{
				param2 = 0,
				prob = 254,
				name = "default:jungletree",
				force_place = true
			},
			{
				param2 = 0,
				prob = 254,
				name = "default:jungletree",
				force_place = true
			},
			{
				param2 = 0,
				name = "air",
				prob = 0
			},
			{
				param2 = 0,
				name = "air",
				prob = 0
			},
			{
				param2 = 0,
				name = "air",
				prob = 0
			},
			{
				param2 = 0,
				name = "air",
				prob = 0
			},
			{
				param2 = 0,
				prob = 254,
				name = "default:jungletree",
				force_place = true
			},
			{
				param2 = 0,
				prob = 254,
				name = "default:jungletree",
				force_place = true
			},
			{
				param2 = 0,
				prob = 254,
				name = "default:jungletree",
				force_place = true
			},
			{
				param2 = 0,
				name = "air",
				prob = 0
			},
			{
				param2 = 0,
				name = "air",
				prob = 0
			},
			{
				param2 = 0,
				name = "air",
				prob = 0
			},
			{
				param2 = 0,
				name = "air",
				prob = 0
			},
			{
				param2 = 0,
				prob = 254,
				name = "default:jungletree",
				force_place = true
			},
			{
				param2 = 0,
				prob = 254,
				name = "default:jungletree",
				force_place = true
			},
			{
				param2 = 0,
				prob = 254,
				name = "default:jungletree",
				force_place = true
			},
			{
				param2 = 0,
				name = "air",
				prob = 0
			},
			{
				param2 = 0,
				name = "air",
				prob = 0
			},
			{
				param2 = 0,
				name = "air",
				prob = 0
			},
			{
				param2 = 0,
				name = "air",
				prob = 0
			},
			{
				param2 = 0,
				prob = 254,
				name = "default:jungletree",
				force_place = true
			},
			{
				param2 = 0,
				prob = 254,
				name = "default:jungletree",
				force_place = true
			},
			{
				param2 = 0,
				prob = 254,
				name = "default:jungletree",
				force_place = true
			},
			{
				param2 = 0,
				name = "air",
				prob = 0
			},
			{
				param2 = 0,
				name = "air",
				prob = 0
			},
			{
				param2 = 0,
				name = "air",
				prob = 0
			},
			{
				param2 = 0,
				name = "air",
				prob = 0
			},
			{
				param2 = 0,
				prob = 254,
				name = "default:jungletree",
				force_place = true
			},
			{
				param2 = 0,
				prob = 254,
				name = "default:jungletree",
				force_place = true
			},
			{
				param2 = 0,
				prob = 254,
				name = "default:jungletree",
				force_place = true
			},
			{
				param2 = 0,
				name = "air",
				prob = 0
			},
			{
				param2 = 0,
				name = "air",
				prob = 0
			},
			{
				param2 = 0,
				name = "air",
				prob = 0
			},
			{
				param2 = 0,
				name = "air",
				prob = 0
			},
			{
				param2 = 0,
				prob = 254,
				name = "default:jungletree",
				force_place = true
			},
			{
