-- Duane's mapgen ethereal_biomes.lua

-- This information was adapted from Ethereal NG, distributed
--  under the MIT License (see LICENSE), and copyrighted by TenPlus1.


local mod = mapgen
local mod_name = 'mapgen'


mod.register_biome({
	y_min = -192,
	source = 'ethereal',
	depth_filler = 2,
	node_filler = 'default:sand',
	humidity_point = 10,
	name = 'fiery_ocean',
	node_top = 'default:sand',
	y_max = 4,
	depth_top = 1,
	heat_point = 75
})
mod.register_biome({
	y_min = -192,
	source = 'ethereal',
	depth_filler = 2,
	node_filler = 'default:sand',
	humidity_point = 35,
	name = 'grove_ocean',
	node_top = 'default:sand',
	y_max = 2,
	depth_top = 1,
	heat_point = 45
})
mod.register_biome({
	y_min = -192,
	source = 'ethereal',
	depth_filler = 2,
	node_filler = 'default:sand',
	humidity_point = 20,
	name = 'sandstone_ocean',
	node_top = 'default:sand',
	y_max = 2,
	depth_top = 1,
	heat_point = 50
})
mod.register_biome({
	y_min = 3,
	source = 'ethereal',
	depth_filler = 3,
	node_filler = 'default:dirt',
	humidity_point = 40,
	name = 'grassy',
	node_top = 'default:dirt_with_grass',
	y_max = 91,
	depth_top = 1,
	heat_point = 13
})
mod.register_biome({
	y_min = 40,
	source = 'ethereal',
	depth_filler = 2,
	node_filler = 'default:dirt',
	humidity_point = 40,
	name = 'alpine',
	node_top = 'default:dirt_with_snow',
	y_max = 140,
	depth_top = 1,
	heat_point = 10
})
mod.register_biome({
	y_min = 1,
	source = 'ethereal',
	depth_filler = 3,
	node_filler = 'default:dirt',
	humidity_point = 60,
	name = 'junglee',
	node_top = 'default:dirt_with_rainforest_litter',
	y_max = 71,
	depth_top = 1,
	heat_point = 30
})
mod.register_biome({
	y_min = 3,
	source = 'ethereal',
	depth_filler = 3,
	node_filler = 'default:dirt',
	humidity_point = 35,
	name = 'grove',
	node_top = 'ethereal:grove_dirt',
	y_max = 23,
	depth_top = 1,
	heat_point = 45
})
mod.register_biome({
	y_min = 1,
	source = 'ethereal',
	depth_filler = 3,
	node_filler = 'default:dirt',
	humidity_point = 40,
	name = 'frost',
	node_top = 'ethereal:crystal_dirt',
	y_max = 71,
	depth_top = 1,
	heat_point = 10
})
mod.register_biome({
	y_min = 3,
	source = 'ethereal',
	depth_filler = 3,
	node_filler = 'default:dirt',
	humidity_point = 65,
	name = 'clearing',
	node_top = 'default:dirt_with_grass',
	y_max = 71,
	depth_top = 1,
	heat_point = 45
})
mod.register_biome({
	y_min = 3,
	source = 'ethereal',
	depth_filler = 3,
	node_filler = 'default:dirt',
	humidity_point = 25,
	name = 'plains',
	node_top = 'ethereal:dry_dirt',
	y_max = 25,
	depth_top = 1,
	heat_point = 65
})
mod.register_biome({
	y_min = 3,
	source = 'ethereal',
	depth_filler = 3,
	node_filler = 'default:dirt',
	humidity_point = 75,
	name = 'sakura',
	node_top = 'ethereal:bamboo_dirt',
	y_max = 25,
	depth_top = 1,
	heat_point = 45
})
mod.register_biome({
	y_min = 1,
	source = 'ethereal',
	depth_filler = 3,
	node_filler = 'default:dirt',
	humidity_point = 40,
	name = 'grassytwo',
	node_top = 'default:dirt_with_grass',
	y_max = 91,
	depth_top = 1,
	heat_point = 15
})
mod.register_biome({
	y_min = -192,
	source = 'ethereal',
	depth_filler = 2,
	node_filler = 'default:sand',
	humidity_point = 40,
	name = 'frost_ocean',
	node_top = 'default:sand',
	y_max = 1,
	depth_top = 1,
	heat_point = 10
})
mod.register_biome({
	y_min = -192,
	source = 'ethereal',
	depth_filler = 2,
	node_filler = 'default:sand',
	humidity_point = 25,
	name = 'plains_ocean',
	node_top = 'default:sand',
	y_max = 2,
	depth_top = 1,
	heat_point = 55
})
mod.register_biome({
	y_min = 1,
	source = 'ethereal',
	depth_filler = 3,
	node_filler = 'default:dirt',
	humidity_point = 50,
	name = 'jumble',
	node_top = 'default:dirt_with_grass',
	y_max = 71,
	depth_top = 1,
	heat_point = 25
})
mod.register_biome({
	y_min = -192,
	source = 'ethereal',
	depth_filler = 2,
	node_filler = 'default:sand',
	humidity_point = 30,
	name = 'grayness_ocean',
	node_top = 'default:silver_sand',
	y_max = 1,
	depth_top = 2,
	heat_point = 15
})
mod.register_biome({
	y_min = -192,
	source = 'ethereal',
	depth_filler = 2,
	node_filler = 'default:sand',
	humidity_point = 28,
	name = 'mesa_ocean',
	node_top = 'default:sand',
	y_max = 1,
	depth_top = 1,
	heat_point = 25
})
mod.register_biome({
	y_min = -112,
	source = 'ethereal',
	depth_filler = 3,
	vertical_blend = 1,
	node_filler = 'default:sand',
	depth_top = 1,
	humidity_point = 40,
	heat_point = 0,
	node_top = 'default:sand',
	node_riverbed = 'default:gravel',
	y_max = -4,
	depth_riverbed = 2,
	name = 'tundra_ocean'
})
mod.register_biome({
	y_min = 4,
	source = 'ethereal',
	depth_filler = 8,
	node_filler = 'air',
	humidity_point = 25,
	name = 'caves',
	node_top = 'default:desert_stone',
	y_max = 41,
	depth_top = 3,
	heat_point = 15
})
mod.register_biome({
	y_min = 25,
	source = 'ethereal',
	depth_filler = 3,
	node_filler = 'default:dirt',
	humidity_point = 75,
	name = 'bamboo',
	node_top = 'ethereal:bamboo_dirt',
	y_max = 70,
	depth_top = 1,
	heat_point = 45
})
mod.register_biome({
	y_min = 2,
	source = 'ethereal',
	depth_filler = 1,
	vertical_blend = 4,
	node_filler = 'default:permafrost',
	depth_top = 1,
	humidity_point = 40,
	heat_point = 0,
	node_top = 'default:permafrost_with_stones',
	node_riverbed = 'default:gravel',
	y_max = 46,
	depth_riverbed = 2,
	name = 'tundra'
})
mod.register_biome({
	y_min = 47,
	source = 'ethereal',
	node_dust = 'default:snow',
	humidity_point = 40,
	heat_point = 0,
	node_riverbed = 'default:gravel',
	y_max = 180,
	depth_riverbed = 2,
	name = 'tundra_highland'
})
mod.register_biome({
	y_min = 3,
	node_stone = 'default:desert_stone',
	depth_filler = 3,
	node_filler = 'default:desert_sand',
	depth_top = 1,
	heat_point = 35,
	node_top = 'default:desert_sand',
	source = 'ethereal',
	y_max = 23,
	humidity_point = 20,
	name = 'desert'
})
mod.register_biome({
	y_min = -192,
	source = 'ethereal',
	depth_filler = 2,
	node_filler = 'default:sand',
	humidity_point = 25,
	name = 'savannah_ocean',
	node_top = 'default:sand',
	y_max = 1,
	depth_top = 1,
	heat_point = 55
})
mod.register_biome({
	y_min = -192,
	node_stone = 'default:desert_stone',
	depth_filler = 2,
	node_filler = 'default:sand',
	depth_top = 1,
	heat_point = 35,
	node_top = 'default:sand',
	source = 'ethereal',
	y_max = 3,
	humidity_point = 20,
	name = 'desert_ocean'
})
mod.register_biome({
	y_min = -192,
	source = 'ethereal',
	depth_filler = 2,
	node_filler = 'default:clay',
	humidity_point = 90,
	name = 'swamp_ocean',
	node_top = 'default:sand',
	y_max = 1,
	depth_top = 2,
	heat_point = 80
})
mod.register_biome({
	y_min = 3,
	source = 'ethereal',
	depth_filler = 3,
	node_filler = 'default:dirt',
	humidity_point = 25,
	name = 'savannah',
	node_top = 'default:dirt_with_dry_grass',
	y_max = 50,
	depth_top = 1,
	heat_point = 55
})
mod.register_biome({
	y_min = -192,
	source = 'ethereal',
	depth_filler = 2,
	node_filler = 'default:sand',
	humidity_point = 55,
	name = 'mushroom_ocean',
	node_top = 'default:sand',
	y_max = 2,
	depth_top = 1,
	heat_point = 45
})
mod.register_biome({
	y_min = 1,
	source = 'ethereal',
	depth_filler = 3,
	node_filler = 'default:dirt',
	humidity_point = 90,
	name = 'swamp',
	node_top = 'default:dirt_with_grass',
	y_max = 7,
	depth_top = 1,
	heat_point = 80
})
mod.register_biome({
	y_min = 1,
	source = 'ethereal',
	depth_filler = 2,
	node_filler = 'default:clay',
	humidity_point = 2,
	name = 'sandclay',
	node_top = 'default:sand',
	y_max = 11,
	depth_top = 3,
	heat_point = 65
})
mod.register_biome({
	y_min = -192,
	source = 'ethereal',
	depth_filler = 2,
	node_filler = 'default:sand',
	humidity_point = 40,
	name = 'grassytwo_ocean',
	node_top = 'default:sand',
	y_max = 1,
	depth_top = 1,
	heat_point = 15
})
mod.register_biome({
	y_min = 1,
	source = 'ethereal',
	depth_filler = 1,
	node_filler = 'default:gravel',
	humidity_point = 38,
	name = 'quicksand',
	node_top = 'ethereal:quicksand2',
	y_max = 1,
	depth_top = 3,
	heat_point = 50
})
mod.register_biome({
	y_min = 3,
	source = 'ethereal',
	depth_filler = 3,
	node_filler = 'default:dirt',
	humidity_point = 40,
	name = 'prairie',
	node_top = 'ethereal:prairie_dirt',
	y_max = 26,
	depth_top = 1,
	heat_point = 20
})
mod.register_biome({
	y_min = -112,
	source = 'ethereal',
	node_dust = 'default:snowblock',
	depth_filler = 3,
	node_filler = 'default:sand',
	depth_top = 1,
	name = 'glacier_ocean',
	node_top = 'default:sand',
	y_max = -9,
	heat_point = 0,
	humidity_point = 50
})
mod.register_biome({
	y_min = 3,
	node_stone = 'default:sandstone',
	depth_filler = 1,
	node_filler = 'default:sandstone',
	depth_top = 1,
	heat_point = 50,
	node_top = 'default:sandstone',
	source = 'ethereal',
	y_max = 23,
	humidity_point = 20,
	name = 'sandstone'
})
mod.register_biome({
	y_min = 3,
	source = 'ethereal',
	depth_filler = 3,
	node_filler = 'default:dirt',
	humidity_point = 55,
	name = 'mushroom',
	node_top = 'ethereal:mushroom_dirt',
	y_max = 50,
	depth_top = 1,
	heat_point = 45
})
mod.register_biome({
	y_min = -192,
	source = 'ethereal',
	depth_filler = 2,
	node_filler = 'default:sand',
	humidity_point = 60,
	name = 'junglee_ocean',
	node_top = 'default:sand',
	y_max = 1,
	depth_top = 1,
	heat_point = 30
})
mod.register_biome({
	y_min = -31000,
	name = 'underground',
	source = 'ethereal',
	heat_point = 50,
	y_max = -192,
	humidity_point = 50
})
mod.register_biome({
	y_min = -192,
	source = 'ethereal',
	depth_filler = 2,
	node_filler = 'default:sand',
	humidity_point = 50,
	name = 'jumble_ocean',
	node_top = 'default:sand',
	y_max = 1,
	depth_top = 1,
	heat_point = 25
})
mod.register_biome({
	y_min = -8,
	depth_water_top = 10,
	node_dust = 'default:snowblock',
	depth_filler = 3,
	node_filler = 'default:snowblock',
	depth_top = 1,
	node_top = 'default:snowblock',
	node_water_top = 'default:ice',
	node_river_water = 'default:ice',
	node_stone = 'default:ice',
	y_max = 31000,
	heat_point = 0,
	source = 'ethereal',
	node_riverbed = 'default:gravel',
	humidity_point = 50,
	depth_riverbed = 2,
	name = 'glacier'
})
mod.register_biome({
	y_min = 2,
	source = 'ethereal',
	depth_filler = 3,
	node_filler = 'default:dirt',
	humidity_point = 30,
	name = 'grayness',
	node_top = 'ethereal:gray_dirt',
	y_max = 41,
	depth_top = 1,
	heat_point = 15
})
mod.register_biome({
	y_min = -192,
	source = 'ethereal',
	depth_filler = 2,
	node_filler = 'default:sand',
	humidity_point = 40,
	name = 'prairie_ocean',
	node_top = 'default:sand',
	y_max = 1,
	depth_top = 1,
	heat_point = 20
})
mod.register_biome({
	y_min = 5,
	source = 'ethereal',
	depth_filler = 3,
	node_filler = 'default:dirt',
	humidity_point = 10,
	name = 'fiery',
	node_top = 'ethereal:fiery_dirt',
	y_max = 20,
	depth_top = 1,
	heat_point = 75
})
mod.register_biome({
	y_min = -3,
	source = 'ethereal',
	depth_filler = 2,
	vertical_blend = 1,
	node_filler = 'default:gravel',
	depth_top = 1,
	humidity_point = 40,
	heat_point = 0,
	node_top = 'default:gravel',
	node_riverbed = 'default:gravel',
	y_max = 1,
	depth_riverbed = 2,
	name = 'tundra_beach'
})
mod.register_biome({
	y_min = 4,
	source = 'ethereal',
	depth_filler = 2,
	node_filler = 'default:dirt',
	humidity_point = 40,
	name = 'snowy',
	node_top = 'default:dirt_with_coniferous_litter',
	y_max = 40,
	depth_top = 1,
	heat_point = 10
})
mod.register_biome({
	y_min = -192,
	source = 'ethereal',
	depth_filler = 2,
	node_filler = 'default:sand',
	humidity_point = 75,
	name = 'sakura_ocean',
	node_top = 'default:sand',
	y_max = 2,
	depth_top = 1,
	heat_point = 45
})
mod.register_biome({
	y_min = 1,
	source = 'ethereal',
	depth_filler = 15,
	node_filler = 'bakedclay:orange',
	humidity_point = 28,
	name = 'mesa',
	node_top = 'default:dirt_with_dry_grass',
	y_max = 71,
	depth_top = 1,
	heat_point = 25
})
mod.register_biome({
	y_min = -31000,
	source = 'ethereal',
	depth_filler = 1,
	node_filler = 'default:gravel',
	humidity_point = 40,
	name = 'grassy_ocean',
	node_top = 'defaut:sand',
	y_max = 3,
	depth_top = 2,
	heat_point = 13
})
mod.register_biome({
	y_min = 140,
	source = 'ethereal',
	depth_filler = 2,
	node_filler = 'default:snowblock',
	humidity_point = 50,
	name = 'mountain',
	node_top = 'default:snow',
	y_max = 31000,
	depth_top = 1,
	heat_point = 50
})
mod.register_decoration({
	y_min = 1,
	biomes = {
		'grove'
	},
	schematic = {
		yslice_prob = {
			{
				prob = 127,
				ypos = 0
			}
		},
		data = {
			{
				param1 = 0,
				name = 'air',
				prob = 0
			},
			{
				param1 = 0,
				name = 'air',
				prob = 0
			},
			{
				param1 = 0,
				name = 'air',
				prob = 0
			},
			{
				param1 = 0,
				name = 'air',
				prob = 0
			},
			{
				param1 = 0,
				name = 'air',
				prob = 0
			},
			{
				param1 = 0,
				name = 'air',
				prob = 0
			},
			{
				param1 = 0,
				name = 'air',
				prob = 0
			},
			{
				param1 = 0,
				name = 'air',
				prob = 0
			},
			{
				param1 = 0,
				name = 'air',
				prob = 0
			},
			{
				param1 = 0,
				name = 'air',
				prob = 0
			},
			{
				param1 = 0,
				name = 'air',
				prob = 0
			},
			{
				param1 = 0,
				name = 'air',
				prob = 0
			},
			{
				param1 = 0,
				name = 'air',
				prob = 0
			},
			{
				param1 = 0,
				name = 'air',
				prob = 0
			},
			{
				param1 = 0,
				name = 'air',
				prob = 0
			},
			{
				param1 = 0,
				name = 'air',
				prob = 0
			},
			{
				param1 = 0,
				name = 'air',
				prob = 0
			},
			{
				param1 = 0,
				name = 'air',
				prob = 0
			},
			{
				param1 = 0,
				name = 'air',
				prob = 0
			},
			{
				param1 = 0,
				name = 'air',
				prob = 0
			},
			{
				param1 = 0,
				name = 'air',
				prob = 0
			},
			{
				param1 = 0,
				name = 'air',
				prob = 0
			},
			{
				param1 = 0,
				name = 'air',
				prob = 0
			},
			{
				param1 = 0,
				name = 'air',
				prob = 0
			},
			{
				param1 = 0,
				name = 'air',
				prob = 0
			},
			{
				param1 = 0,
				name = 'air',
				prob = 0
			},
			{
				param1 = 0,
				name = 'air',
				prob = 0
			},
			{
				param1 = 0,
				name = 'air',
				prob = 0
			},
			{
				param1 = 0,
				name = 'air',
				prob = 0
			},
			{
				param1 = 0,
				name = 'air',
				prob = 0
			},
			{
				param1 = 0,
				name = 'air',
				prob = 0
			},
			{
				param1 = 0,
				name = 'air',
				prob = 0
			},
			{
				param1 = 0,
				name = 'air',
				prob = 0
			},
			{
				param1 = 0,
				name = 'air',
				prob = 0
			},
			{
				param1 = 0,
				name = 'air',
				prob = 0
			},
			{
				param1 = 0,
				name = 'air',
				prob = 0
			},
			{
				param1 = 0,
				name = 'air',
				prob = 0
			},
			{
				param1 = 0,
				name = 'air',
				prob = 0
			},
			{
				param1 = 0,
				name = 'air',
				prob = 0
			},
			{
				param1 = 0,
				name = 'air',
				prob = 0
			},
			{
				param1 = 0,
				name = 'air',
				prob = 0
			},
			{
				param1 = 0,
				name = 'air',
				prob = 0
			},
			{
				param1 = 0,
				name = 'air',
				prob = 0
			},
			{
				param1 = 0,
				name = 'air',
				prob = 0
			},
			{
				param1 = 0,
				name = 'air',
				prob = 0
			},
			{
				name = 'ethereal:bananaleaves',
				param1 = 180
			},
			{
				param1 = 0,
				name = 'air',
				prob = 0
			},
			{
				param1 = 0,
				name = 'air',
				prob = 0
			},
			{
				param1 = 0,
				name = 'air',
				prob = 0
			},
			{
				param1 = 0,
				name = 'air',
				prob = 0
			},
			{
				param1 = 0,
				name = 'air',
				prob = 0
			},
			{
				param1 = 0,
				name = 'air',
				prob = 0
			},
			{
				name = 'ethereal:bananaleaves',
				param1 = 255
			},
			{
				param1 = 0,
				name = 'air',
				prob = 0
			},
			{
				param1 = 0,
				name = 'air',
				prob = 0
			},
			{
				param1 = 0,
				name = 'air',
				prob = 0
			},
			{
				param1 = 0,
				name = 'air',
				prob = 0
			},
			{
				param1 = 0,
				name = 'air',
				prob = 0
			},
			{
				param1 = 0,
				name = 'air',
				prob = 0
			},
			{
				param1 = 0,
				name = 'air',
				prob = 0
			},
			{
				param1 = 0,
				name = 'air',
				prob = 0
			},
			{
				param1 = 0,
				name = 'air',
				prob = 0
			},
			{
				param1 = 0,
				name = 'air',
				prob = 0
			},
			{
				param1 = 0,
				name = 'air',
				prob = 0
			},
			{
				param1 = 0,
				name = 'air',
				prob = 0
			},
			{
				param1 = 0,
				name = 'air',
				prob = 0
			},
			{
				param1 = 0,
				name = 'air',
				prob = 0
			},
			{
				param1 = 0,
				name = 'air',
				prob = 0
			},
			{
				param1 = 0,
				name = 'air',
				prob = 0
			},
			{
				param1 = 0,
				name = 'air',
				prob = 0
			},
			{
				param1 = 0,
				name = 'air',
				prob = 0
			},
			{
				param1 = 0,
				name = 'air',
				prob = 0
			},
			{
				param1 = 0,
				name = 'air',
				prob = 0
			},
			{
				param1 = 0,
				name = 'air',
				prob = 0
			},
			{
				param1 = 0,
				name = 'air',
				prob = 0
			},
			{
				param1 = 0,
				name = 'air',
				prob = 0
			},
			{
				param1 = 0,
				name = 'air',
				prob = 0
			},
			{
				param1 = 0,
				name = 'air',
				prob = 0
			},
			{
				param1 = 0,
				name = 'air',
				prob = 0
			},
			{
				param1 = 0,
				name = 'air',
				prob = 0
			},
			{
				param1 = 0,
				name = 'air',
				prob = 0
			},
			{
				param1 = 0,
				name = 'air',
				prob = 0
			},
			{
				param1 = 0,
				name = 'air',
				prob = 0
			},
			{
				param1 = 0,
				name = 'air',
				prob = 0
			},
			{
				param1 = 0,
				name = 'air',
				prob = 0
			},
			{
				param1 = 0,
				name = 'air',
				prob = 0
			},
			{
				param1 = 0,
				name = 'air',
				prob = 0
			},
			{
				name = 'ethereal:banana',
				param1 = 70
			},
			{
				param1 = 0,
				name = 'air',
				prob = 0
			},
			{
				param1 = 0,
				name = 'air',
				prob = 0
			},
			{
				param1 = 0,
				name = 'air',
				prob = 0
			},
			{
				param1 = 0,
				name = 'air',
				prob = 0
			},
			{
				param1 = 0,
				name = 'air',
				prob = 0
			},
			{
				param1 = 0,
				name = 'air',
				prob = 0
			},
			{
				name = 'ethereal:banana',
				param1 = 255
			},
			{
				param1 = 0,
				name = 'air',
				prob = 0
			},
			{
				param1 = 0,
				name = 'air',
				prob = 0
			},
			{
				param1 = 0,
				name = 'air',
				prob = 0
			},
			{
				param1 = 0,
				name = 'air',
				prob = 0
			},
			{
				param1 = 0,
				name = 'air',
				prob = 0
			},
			{
				param1 = 0,
				name = 'air',
				prob = 0
			},
			{
				name = 'ethereal:bananaleaves',
				param1 = 255
			},
			{
				param1 = 0,
				name = 'air',
				prob = 0
			},
			{
				param1 = 0,
				name = 'air',
				prob = 0
			},
			{
				param1 = 0,
				name = 'air',
				prob = 0
			},
			{
				param1 = 0,
				name = 'air',
				prob = 0
			},
			{
				param1 = 0,
				name = 'air',
				prob = 0
			},
			{
				param1 = 0,
				name = 'air',
				prob = 0
			},
			{
				param1 = 0,
				name = 'air',
				prob = 0
			},
			{
				param1 = 0,
				name = 'air',
				prob = 0
			},
			{
				param1 = 0,
				name = 'air',
				prob = 0
			},
			{
				param1 = 0,
				name = 'air',
				prob = 0
			},
			{
				param1 = 0,
				name = 'air',
				prob = 0
			},
			{
				param1 = 0,
				name = 'air',
				prob = 0
			},
			{
				param1 = 0,
				name = 'air',
				prob = 0
			},
			{
				param1 = 0,
				name = 'air',
				prob = 0
			},
			{
				param1 = 0,
				name = 'air',
				prob = 0
			},
			{
				param1 = 0,
				name = 'air',
				prob = 0
			},
			{
				param1 = 0,
				name = 'air',
				prob = 0
			},
			{
				param1 = 0,
				name = 'air',
				prob = 0
			},
			{
				param1 = 0,
				name = 'air',
				prob = 0
			},
			{
				param1 = 0,
				name = 'air',
				prob = 0
			},
			{
				param1 = 0,
				name = 'air',
				prob = 0
			},
			{
				param1 = 0,
				name = 'air',
				prob = 0
			},
			{
				param1 = 0,
				name = 'air',
				prob = 0
			},
			{
				param1 = 0,
				name = 'air',
				prob = 0
			},
			{
				param1 = 0,
				name = 'air',
				prob = 0
			},
			{
				param1 = 0,
				name = 'air',
				prob = 0
			},
			{
				param1 = 0,
				name = 'air',
				prob = 0
			},
			{
				param1 = 0,
				name = 'air',
				prob = 0
			},
			{
				param1 = 0,
				name = 'air',
				prob = 0
			},
			{
				param1 = 0,
				name = 'air',
				prob = 0
			},
			{
				param1 = 0,
				name = 'air',
				prob = 0
			},
			{
				param1 = 0,
				name = 'air',
				prob = 0
			},
			{
				param1 = 0,
				name = 'air',
				prob = 0
			},
			{
				param1 = 0,
				name = 'air',
				prob = 0
			},
			{
				param1 = 0,
				name = 'air',
				prob = 0
			},
			{
				param1 = 0,
				name = 'air',
				prob = 0
			},
			{
				param1 = 0,
				name = 'air',
				prob = 0
			},
			{
				param1 = 0,
				name = 'air',
				prob = 0
			},
			{
				param1 = 0,
				name = 'air',
				prob = 0
			},
			{
				param1 = 0,
				name = 'air',
				prob = 0
			},
			{
				name = 'ethereal:banana',
				param1 = 70
			},
			{
				name = 'ethereal:banana_trunk',
				param1 = 255
			},
			{
				name = 'ethereal:banana',
				param1 = 70
			},
			{
				param1 = 0,
				name = 'air',
				prob = 0
			},
			{
				param1 = 0,
				name = 'air',
				prob = 0
			},
			{
				param1 = 0,
				name = 'air',
				prob = 0
			},
			{
				param1 = 0,
				name = 'air',
				prob = 0
			},
			{
				name = 'ethereal:banana',
				param1 = 255
			},
			{
				name = 'ethereal:bananaleaves',
				param1 = 255
			},
			{
				name = 'ethereal:banana',
				param1 = 255
			},
			{
				param1 = 0,
				name = 'air',
				prob = 0
			},
			{
				param1 = 0,
				name = 'air',
				prob = 0
			},
			{
				param1 = 0,
				name = 'air',
				prob = 0
			},
			{
				name = 'ethereal:bananaleaves',
				param1 = 255
			},
			{
				name = 'ethereal:bananaleaves',
				param1 = 255
			},
			{
				name = 'ethereal:bananaleaves',
				param1 = 255
			},
			{
				name = 'ethereal:bananaleaves',
				param1 = 255
			},
			{
				name = 'ethereal:bananaleaves',
				param1 = 255
			},
			{
				param1 = 0,
				name = 'air',
				prob = 0
			},
			{
				name = 'ethereal:bananaleaves',
				param1 = 255
			},
			{
				name = 'ethereal:bananaleaves',
				param1 = 180
			},
			{
				param1 = 0,
				name = 'air',
				prob = 0
			},
			{
				name = 'ethereal:bananaleaves',
				param1 = 255
			},
			{
				param1 = 0,
				name = 'air',
				prob = 0
			},
			{
				name = 'ethereal:bananaleaves',
				param1 = 180
			},
			{
				name = 'ethereal:bananaleaves',
				param1 = 255
			},
			{
				param1 = 0,
				name = 'air',
				prob = 0
			},
			{
				param1 = 0,
				name = 'air',
				prob = 0
			},
			{
				param1 = 0,
				name = 'air',
				prob = 0
			},
			{
				name = 'ethereal:banana_trunk',
				param1 = 255
			},
			{
				param1 = 0,
				name = 'air',
				prob = 0
			},
			{
				param1 = 0,
				name = 'air',
				prob = 0
			},
			{
				param1 = 0,
				name = 'air',
				prob = 0
			},
			{
				param1 = 0,
				name = 'air',
				prob = 0
			},
			{
				param1 = 0,
				name = 'air',
				prob = 0
			},
			{
				param1 = 0,
				name = 'air',
				prob = 0
			},
			{
				name = 'ethereal:banana_trunk',
				param1 = 255
			},
			{
				param1 = 0,
				name = 'air',
				prob = 0
			},
			{
				param1 = 0,
				name = 'air',
				prob = 0
			},
			{
				param1 = 0,
				name = 'air',
				prob = 0
			},
			{
				param1 = 0,
				name = 'air',
				prob = 0
			},
			{
				param1 = 0,
				name = 'air',
				prob = 0
			},
			{
				param1 = 0,
				name = 'air',
				prob = 0
			},
			{
				name = 'ethereal:banana_trunk',
				param1 = 255
			},
			{
				param1 = 0,
				name = 'air',
				prob = 0
			},
			{
				param1 = 0,
				name = 'air',
				prob = 0
			},
			{
				param1 = 0,
				name = 'air',
				prob = 0
			},
			{
				param1 = 0,
				name = 'air',
				prob = 0
			},
			{
				param1 = 0,
				name = 'air',
				prob = 0
			},
			{
				param1 = 0,
				name = 'air',
				prob = 0
			},
			{
				name = 'ethereal:banana_trunk',
				param1 = 255
			},
			{
				param1 = 0,
				name = 'air',
				prob = 0
			},
			{
				param1 = 0,
				name = 'air',
				prob = 0
			},
			{
				param1 = 0,
				name = 'air',
				prob = 0
			},
			{
				param1 = 0,
				name = 'air',
				prob = 0
			},
			{
				param1 = 0,
				name = 'air',
				prob = 0
			},
			{
				param1 = 0,
				name = 'air',
				prob = 0
			},
			{
				name = 'ethereal:banana',
				param1 = 70
			},
			{
				param1 = 0,
				name = 'air',
				prob = 0
			},
			{
				param1 = 0,
				name = 'air',
				prob = 0
			},
			{
				param1 = 0,
				name = 'air',
				prob = 0
			},
			{
				param1 = 0,
				name = 'air',
				prob = 0
			},
			{
				param1 = 0,
				name = 'air',
				prob = 0
			},
			{
				param1 = 0,
				name = 'air',
				prob = 0
			},
			{
				name = 'ethereal:banana',
				param1 = 255
			},
			{
				param1 = 0,
				name = 'air',
				prob = 0
			},
			{
				param1 = 0,
				name = 'air',
				prob = 0
			},
			{
				param1 = 0,
				name = 'air',
				prob = 0
			},
			{
				param1 = 0,
				name = 'air',
				prob = 0
			},
			{
				param1 = 0,
				name = 'air',
				prob = 0
			},
			{
				param1 = 0,
				name = 'air',
				prob = 0
			},
			{
				name = 'ethereal:bananaleaves',
				param1 = 255
			},
			{
				param1 = 0,
				name = 'air',
				prob = 0
			},
			{
				param1 = 0,
				name = 'air',
				prob = 0
			},
			{
				param1 = 0,
				name = 'air',
				prob = 0
			},
			{
				param1 = 0,
				name = 'air',
				prob = 0
			},
			{
				param1 = 0,
				name = 'air',
				prob = 0
			},
			{
				param1 = 0,
				name = 'air',
				prob = 0
			},
			{
				param1 = 0,
				name = 'air',
				prob = 0
			},
			{
				param1 = 0,
				name = 'air',
				prob = 0
			},
			{
				param1 = 0,
				name = 'air',
				prob = 0
			},
			{
				param1 = 0,
				name = 'air',
				prob = 0
			},
			{
				param1 = 0,
				name = 'air',
				prob = 0
			},
			{
				param1 = 0,
				name = 'air',
				prob = 0
			},
			{
				param1 = 0,
				name = 'air',
				prob = 0
			},
			{
				param1 = 0,
				name = 'air',
				prob = 0
			},
			{
				param1 = 0,
				name = 'air',
				prob = 0
			},
			{
				param1 = 0,
				name = 'air',
				prob = 0
			},
			{
				param1 = 0,
				name = 'air',
				prob = 0
			},
			{
				param1 = 0,
				name = 'air',
				prob = 0
			},
			{
				param1 = 0,
				name = 'air',
				prob = 0
			},
			{
				param1 = 0,
				name = 'air',
				prob = 0
			},
			{
				param1 = 0,
				name = 'air',
				prob = 0
			},
			{
				param1 = 0,
				name = 'air',
				prob = 0
			},
			{
				param1 = 0,
				name = 'air',
				prob = 0
			},
			{
				param1 = 0,
				name = 'air',
				prob = 0
			},
			{
				param1 = 0,
				name = 'air',
				prob = 0
			},
			{
				param1 = 0,
				name = 'air',
				prob = 0
			},
			{
				param1 = 0,
				name = 'air',
				prob = 0
			},
			{
				param1 = 0,
				name = 'air',
				prob = 0
			},
			{
				param1 = 0,
				name = 'air',
				prob = 0
			},
			{
				param1 = 0,
				name = 'air',
				prob = 0
			},
			{
				param1 = 0,
				name = 'air',
				prob = 0
			},
			{
				param1 = 0,
				name = 'air',
				prob = 0
			},
			{
				param1 = 0,
				name = 'air',
				prob = 0
			},
			{
				param1 = 0,
				name = 'air',
				prob = 0
			},
			{
				param1 = 0,
				name = 'air',
				prob = 0
			},
			{
				param1 = 0,
				name = 'air',
				prob = 0
			},
			{
				param1 = 0,
				name = 'air',
				prob = 0
			},
			{
				param1 = 0,
				name = 'air',
				prob = 0
			},
			{
				param1 = 0,
				name = 'air',
				prob = 0
			},
			{
				param1 = 0,
				name = 'air',
				prob = 0
			},
			{
				param1 = 0,
				name = 'air',
				prob = 0
			},
			{
				param1 = 0,
				name = 'air',
				prob = 0
			},
			{
				param1 = 0,
				name = 'air',
				prob = 0
			},
			{
				param1 = 0,
				name = 'air',
				prob = 0
			},
			{
				param1 = 0,
				name = 'air',
				prob = 0
			},
			{
				param1 = 0,
				name = 'air',
				prob = 0
			},
			{
				param1 = 0,
				name = 'air',
				prob = 0
			},
			{
				param1 = 0,
				name = 'air',
				prob = 0
			},
			{
				param1 = 0,
				name = 'air',
				prob = 0
			},
			{
				param1 = 0,
				name = 'air',
				prob = 0
			},
			{
				param1 = 0,
				name = 'air',
				prob = 0
			},
			{
				param1 = 0,
				name = 'air',
				prob = 0
			},
			{
				param1 = 0,
				name = 'air',
				prob = 0
			},
			{
				param1 = 0,
				name = 'air',
				prob = 0
			},
			{
				param1 = 0,
				name = 'air',
				prob = 0
			},
			{
				name = 'ethereal:bananaleaves',
				param1 = 255
			},
			{
				param1 = 0,
				name = 'air',
				prob = 0
			},
			{
				param1 = 0,
				name = 'air',
				prob = 0
			},
			{
				param1 = 0,
				name = 'air',
				prob = 0
			},
			{
				param1 = 0,
				name = 'air',
				prob = 0
			},
			{
				param1 = 0,
				name = 'air',
				prob = 0
			},
			{
				param1 = 0,
				name = 'air',
				prob = 0
			},
			{
				name = 'ethereal:bananaleaves',
				param1 = 180
			},
			{
				param1 = 0,
				name = 'air',
				prob = 0
			},
			{
				param1 = 0,
				name = 'air',
				prob = 0
			},
			{
				param1 = 0,
				name = 'air',
				prob = 0
			},
			{
				param1 = 0,
				name = 'air',
				prob = 0
			},
			{
				param1 = 0,
				name = 'air',
				prob = 0
			},
			{
				param1 = 0,
				name = 'air',
				prob = 0
			},
			{
				param1 = 0,
				name = 'air',
				prob = 0
			},
			{
				param1 = 0,
				name = 'air',
				prob = 0
			},
			{
				param1 = 0,
				name = 'air',
				prob = 0
			},
			{
				param1 = 0,
				name = 'air',
				prob = 0
			},
			{
				param1 = 0,
				name = 'air',
				prob = 0
			},
			{
				param1 = 0,
				name = 'air',
				prob = 0
			},
			{
				param1 = 0,
				name = 'air',
				prob = 0
			},
			{
				param1 = 0,
				name = 'air',
				prob = 0
			},
			{
				param1 = 0,
				name = 'air',
				prob = 0
			},
			{
				param1 = 0,
				name = 'air',
				prob = 0
			},
			{
				param1 = 0,
				name = 'air',
				prob = 0
			},
			{
				param1 = 0,
				name = 'air',
				prob = 0
			},
			{
				param1 = 0,
				name = 'air',
				prob = 0
			},
			{
				param1 = 0,
				name = 'air',
				prob = 0
			},
			{
				param1 = 0,
				name = 'air',
				prob = 0
			},
			{
				param1 = 0,
				name = 'air',
				prob = 0
			},
			{
				param1 = 0,
				name = 'air',
				prob = 0
			},
			{
				param1 = 0,
				name = 'air',
				prob = 0
			},
			{
				param1 = 0,
				name = 'air',
				prob = 0
			},
			{
				param1 = 0,
				name = 'air',
				prob = 0
			},
			{
				param1 = 0,
				name = 'air',
				prob = 0
			},
			{
				param1 = 0,
				name = 'air',
				prob = 0
			},
			{
				param1 = 0,
				name = 'air',
				prob = 0
			},
			{
				param1 = 0,
				name = 'air',
				prob = 0
			},
			{
				param1 = 0,
				name = 'air',
				prob = 0
			},
			{
				param1 = 0,
				name = 'air',
				prob = 0
			},
			{
				param1 = 0,
				name = 'air',
				prob = 0
			},
			{
				param1 = 0,
				name = 'air',
				prob = 0
			},
			{
				param1 = 0,
				name = 'air',
				prob = 0
			},
			{
				param1 = 0,
				name = 'air',
				prob = 0
			},
			{
				param1 = 0,
				name = 'air',
				prob = 0
			},
			{
				param1 = 0,
				name = 'air',
				prob = 0
			},
			{
				param1 = 0,
				name = 'air',
				prob = 0
			},
			{
				param1 = 0,
				name = 'air',
				prob = 0
			},
			{
				param1 = 0,
				name = 'air',
				prob = 0
			},
			{
				param1 = 0,
				name = 'air',
				prob = 0
			},
			{
				param1 = 0,
				name = 'air',
				prob = 0
			},
			{
				param1 = 0,
				name = 'air',
				prob = 0
			},
			{
				param1 = 0,
				name = 'air',
				prob = 0
			},
			{
				param1 = 0,
				name = 'air',
				prob = 0
			},
			{
				param1 = 0,
				name = 'air',
				prob = 0
			},
			{
				param1 = 0,
				name = 'air',
				prob = 0
			},
			{
				param1 = 0,
				name = 'air',
				prob = 0
			},
			{
				param1 = 0,
				name = 'air',
				prob = 0
			},
			{
				param1 = 0,
				name = 'air',
				prob = 0
			},
			{
				param1 = 0,
				name = 'air',
				prob = 0
			},
			{
				param1 = 0,
				name = 'air',
				prob = 0
			},
			{
				param1 = 0,
				name = 'air',
				prob = 0
			},
			{
				param1 = 0,
				name = 'air',
				prob = 0
			},
			{
				name = 'ethereal:bananaleaves',
				param1 = 255
			},
			{
				param1 = 0,
				name = 'air',
				prob = 0
			},
			{
				param1 = 0,
				name = 'air',
				prob = 0
			},
			{
				param1 = 0,
				name = 'air',
				prob = 0
			},
			{
				param1 = 0,
				name = 'air',
				prob = 0
			},
			{
				param1 = 0,
				name = 'air',
				prob = 0
			},
			{
				param1 = 0,
				name = 'air',
				prob = 0
			},
			{
				param1 = 0,
				name = 'air',
				prob = 0
			},
			{
				param1 = 0,
				name = 'air',
				prob = 0
			},
			{
				param1 = 0,
				name = 'air',
				prob = 0
			},
			{
				param1 = 0,
				name = 'air',
				prob = 0
			},
			{
				param1 = 0,
				name = 'air',
				prob = 0
			},
			{
				param1 = 0,
				name = 'air',
				prob = 0
			},
			{
				param1 = 0,
				name = 'air',
				prob = 0
			},
			{
				param1 = 0,
				name = 'air',
				prob = 0
			},
			{
				param1 = 0,
				name = 'air',
				prob = 0
			},
			{
				param1 = 0,
				name = 'air',
				prob = 0
			},
			{
				param1 = 0,
				name = 'air',
				prob = 0
			},
			{
				param1 = 0,
				name = 'air',
				prob = 0
			},
			{
				param1 = 0,
				name = 'air',
				prob = 0
			},
			{
				param1 = 0,
				name = 'air',
				prob = 0
			},
			{
				param1 = 0,
				name = 'air',
				prob = 0
			},
			{
				param1 = 0,
				name = 'air',
				prob = 0
			},
			{
				param1 = 0,
				name = 'air',
				prob = 0
			},
			{
				param1 = 0,
				name = 'air',
				prob = 0
			},
			{
				param1 = 0,
				name = 'air',
				prob = 0
			},
			{
				param1 = 0,
				name = 'air',
				prob = 0
			},
			{
				param1 = 0,
				name = 'air',
				prob = 0
			},
			{
				param1 = 0,
				name = 'air',
				prob = 0
			},
			{
				param1 = 0,
				name = 'air',
				prob = 0
			},
			{
				param1 = 0,
				name = 'air',
				prob = 0
			},
			{
				param1 = 0,
				name = 'air',
				prob = 0
			},
			{
				param1 = 0,
				name = 'air',
				prob = 0
			},
			{
				param1 = 0,
				name = 'air',
				prob = 0
			},
			{
				param1 = 0,
				name = 'air',
				prob = 0
			},
			{
				param1 = 0,
				name = 'air',
				prob = 0
			},
			{
				param1 = 0,
				name = 'air',
				prob = 0
			},
			{
				param1 = 0,
				name = 'air',
				prob = 0
			},
			{
				param1 = 0,
				name = 'air',
				prob = 0
			},
			{
				param1 = 0,
				name = 'air',
				prob = 0
			},
			{
				param1 = 0,
				name = 'air',
				prob = 0
			},
			{
				param1 = 0,
				name = 'air',
				prob = 0
			},
			{
				param1 = 0,
				name = 'air',
				prob = 0
			},
			{
				param1 = 0,
				name = 'air',
				prob = 0
			},
			{
				param1 = 0,
				name = 'air',
				prob = 0
			},
			{
				param1 = 0,
				name = 'air',
				prob = 0
			},
			{
				param1 = 0,
				name = 'air',
				prob = 0
			},
			{
				param1 = 0,
				name = 'air',
				prob = 0
			},
			{
				param1 = 0,
				name = 'air',
				prob = 0
			},
			{
				param1 = 0,
				name = 'air',
				prob = 0
			},
			{
				param1 = 0,
				name = 'air',
				prob = 0
			},
			{
				param1 = 0,
				name = 'air',
				prob = 0
			},
			{
				param1 = 0,
				name = 'air',
				prob = 0
			},
			{
				param1 = 0,
				name = 'air',
				prob = 0
			},
			{
				param1 = 0,
				name = 'air',
				prob = 0
			},
			{
				param1 = 0,
				name = 'air',
				prob = 0
			},
			{
				param1 = 0,
				name = 'air',
				prob = 0
			},
			{
				param1 = 0,
				name = 'air',
				prob = 0
			},
			{
				param1 = 0,
				name = 'air',
				prob = 0
			},
			{
				param1 = 0,
				name = 'air',
				prob = 0
			}
		},
		size = {
			y = 8,
			x = 7,
			z = 7
		}
	},
	y_max = 100,
	flags = 'place_center_x, place_center_z',
	place_on = {
		'ethereal:grove_dirt'
	},
	fill_ratio = 0.015,
	sidelen = 80,
	deco_type = 'schematic',
	source = 'ethereal',
	schematic_array = {
		yslice_prob = {
			{
				prob = 127,
				ypos = 0
			}
		},
		data = {
			{
				param1 = 0,
				name = 'air',
				prob = 0
			},
			{
				param1 = 0,
				name = 'air',
				prob = 0
			},
			{
				param1 = 0,
				name = 'air',
				prob = 0
			},
			{
				param1 = 0,
				name = 'air',
				prob = 0
			},
			{
				param1 = 0,
				name = 'air',
				prob = 0
			},
			{
				param1 = 0,
				name = 'air',
				prob = 0
			},
			{
				param1 = 0,
				name = 'air',
				prob = 0
			},
			{
				param1 = 0,
				name = 'air',
				prob = 0
			},
			{
				param1 = 0,
				name = 'air',
				prob = 0
			},
			{
				param1 = 0,
				name = 'air',
				prob = 0
			},
			{
				param1 = 0,
				name = 'air',
				prob = 0
			},
			{
				param1 = 0,
				name = 'air',
				prob = 0
			},
			{
				param1 = 0,
				name = 'air',
				prob = 0
			},
			{
				param1 = 0,
				name = 'air',
				prob = 0
			},
			{
				param1 = 0,
				name = 'air',
				prob = 0
			},
			{
				param1 = 0,
				name = 'air',
				prob = 0
			},
			{
				param1 = 0,
				name = 'air',
				prob = 0
			},
			{
				param1 = 0,
				name = 'air',
				prob = 0
			},
			{
				param1 = 0,
				name = 'air',
				prob = 0
			},
			{
				param1 = 0,
				name = 'air',
				prob = 0
			},
			{
				param1 = 0,
				name = 'air',
				prob = 0
			},
			{
				param1 = 0,
				name = 'air',
				prob = 0
			},
			{
				param1 = 0,
				name = 'air',
				prob = 0
			},
			{
				param1 = 0,
				name = 'air',
				prob = 0
			},
			{
				param1 = 0,
				name = 'air',
				prob = 0
			},
			{
				param1 = 0,
				name = 'air',
				prob = 0
			},
			{
				param1 = 0,
				name = 'air',
				prob = 0
			},
			{
				param1 = 0,
				name = 'air',
				prob = 0
			},
			{
				param1 = 0,
				name = 'air',
				prob = 0
			},
			{
				param1 = 0,
				name = 'air',
				prob = 0
			},
			{
				param1 = 0,
				name = 'air',
				prob = 0
			},
			{
				param1 = 0,
				name = 'air',
				prob = 0
			},
			{
				param1 = 0,
				name = 'air',
				prob = 0
			},
			{
				param1 = 0,
				name = 'air',
				prob = 0
			},
			{
				param1 = 0,
				name = 'air',
				prob = 0
			},
			{
				param1 = 0,
				name = 'air',
				prob = 0
			},
			{
				param1 = 0,
				name = 'air',
				prob = 0
			},
			{
				param1 = 0,
				name = 'air',
				prob = 0
			},
			{
				param1 = 0,
				name = 'air',
				prob = 0
			},
			{
				param1 = 0,
				name = 'air',
				prob = 0
			},
			{
				param1 = 0,
				name = 'air',
				prob = 0
			},
			{
				param1 = 0,
				name = 'air',
				prob = 0
			},
			{
				param1 = 0,
				name = 'air',
				prob = 0
			},
			{
				param1 = 0,
				name = 'air',
				prob = 0
			},
			{
				param1 = 0,
				name = 'air',
				prob = 0
			},
			{
				name = 'ethereal:bananaleaves',
				param1 = 180
			},
			{
				param1 = 0,
				name = 'air',
				prob = 0
			},
			{
				param1 = 0,
				name = 'air',
				prob = 0
			},
			{
				param1 = 0,
				name = 'air',
				prob = 0
			},
			{
				param1 = 0,
				name = 'air',
				prob = 0
			},
			{
				param1 = 0,
				name = 'air',
				prob = 0
			},
			{
				param1 = 0,
				name = 'air',
				prob = 0
			},
			{
				name = 'ethereal:bananaleaves',
				param1 = 255
			},
			{
				param1 = 0,
				name = 'air',
				prob = 0
			},
			{
				param1 = 0,
				name = 'air',
				prob = 0
			},
			{
				param1 = 0,
				name = 'air',
				prob = 0
			},
			{
				param1 = 0,
				name = 'air',
				prob = 0
			},
			{
				param1 = 0,
				name = 'air',
				prob = 0
			},
			{
				param1 = 0,
				name = 'air',
				prob = 0
			},
			{
				param1 = 0,
				name = 'air',
				prob = 0
			},
			{
				param1 = 0,
				name = 'air',
				prob = 0
			},
			{
				param1 = 0,
				name = 'air',
				prob = 0
			},
			{
				param1 = 0,
				name = 'air',
				prob = 0
			},
			{
				param1 = 0,
				name = 'air',
				prob = 0
			},
			{
				param1 = 0,
				name = 'air',
				prob = 0
			},
			{
				param1 = 0,
				name = 'air',
				prob = 0
			},
			{
				param1 = 0,
				name = 'air',
				prob = 0
			},
			{
				param1 = 0,
				name = 'air',
				prob = 0
			},
			{
				param1 = 0,
				name = 'air',
				prob = 0
			},
			{
				param1 = 0,
				name = 'air',
				prob = 0
			},
			{
				param1 = 0,
				name = 'air',
				prob = 0
			},
			{
				param1 = 0,
				name = 'air',
				prob = 0
			},
			{
				param1 = 0,
				name = 'air',
				prob = 0
			},
			{
				param1 = 0,
				name = 'air',
				prob = 0
			},
			{
				param1 = 0,
				name = 'air',
				prob = 0
			},
			{
				param1 = 0,
				name = 'air',
				prob = 0
			},
			{
				param1 = 0,
				name = 'air',
				prob = 0
			},
			{
				param1 = 0,
				name = 'air',
				prob = 0
			},
			{
				param1 = 0,
				name = 'air',
				prob = 0
			},
			{
				param1 = 0,
				name = 'air',
				prob = 0
			},
			{
				param1 = 0,
				name = 'air',
				prob = 0
			},
			{
				param1 = 0,
				name = 'air',
				prob = 0
			},
			{
				param1 = 0,
				name = 'air',
				prob = 0
			},
			{
				param1 = 0,
				name = 'air',
				prob = 0
			},
			{
				param1 = 0,
				name = 'air',
				prob = 0
			},
			{
				param1 = 0,
				name = 'air',
				prob = 0
			},
			{
				param1 = 0,
				name = 'air',
				prob = 0
			},
			{
				name = 'ethereal:banana',
				param1 = 70
			},
			{
				param1 = 0,
				name = 'air',
				prob = 0
			},
			{
				param1 = 0,
				name = 'air',
				prob = 0
			},
			{
				param1 = 0,
				name = 'air',
				prob = 0
			},
			{
				param1 = 0,
				name = 'air',
				prob = 0
			},
			{
				param1 = 0,
				name = 'air',
				prob = 0
			},
			{
				param1 = 0,
				name = 'air',
				prob = 0
			},
			{
				name = 'ethereal:banana',
				param1 = 255
			},
			{
				param1 = 0,
				name = 'air',
				prob = 0
			},
			{
				param1 = 0,
				name = 'air',
				prob = 0
			},
			{
				param1 = 0,
				name = 'air',
				prob = 0
			},
			{
				param1 = 0,
				name = 'air',
				prob = 0
			},
			{
				param1 = 0,
				name = 'air',
				prob = 0
			},
			{
				param1 = 0,
				name = 'air',
				prob = 0
			},
			{
				name = 'ethereal:bananaleaves',
				param1 = 255
			},
			{
				param1 = 0,
				name = 'air',
				prob = 0
			},
			{
				param1 = 0,
				name = 'air',
				prob = 0
			},
			{
				param1 = 0,
				name = 'air',
				prob = 0
			},
			{
				param1 = 0,
				name = 'air',
				prob = 0
			},
			{
				param1 = 0,
				name = 'air',
				prob = 0
			},
			{
				param1 = 0,
				name = 'air',
				prob = 0
			},
			{
				param1 = 0,
				name = 'air',
				prob = 0
			},
			{
				param1 = 0,
				name = 'air',
				prob = 0
			},
			{
				param1 = 0,
				name = 'air',
				prob = 0
			},
			{
				param1 = 0,
				name = 'air',
				prob = 0
			},
			{
				param1 = 0,
				name = 'air',
				prob = 0
			},
			{
				param1 = 0,
				name = 'air',
				prob = 0
			},
			{
				param1 = 0,
				name = 'air',
				prob = 0
			},
			{
				param1 = 0,
				name = 'air',
				prob = 0
			},
			{
				param1 = 0,
				name = 'air',
				prob = 0
			},
			{
				param1 = 0,
				name = 'air',
				prob = 0
			},
			{
				param1 = 0,
				name = 'air',
				prob = 0
			},
			{
				param1 = 0,
				name = 'air',
				prob = 0
			},
			{
				param1 = 0,
				name = 'air',
				prob = 0
			},
			{
				param1 = 0,
				name = 'air',
				prob = 0
			},
			{
				param1 = 0,
				name = 'air',
				prob = 0
			},
			{
				param1 = 0,
				name = 'air',
				prob = 0
			},
			{
				param1 = 0,
				name = 'air',
				prob = 0
			},
			{
				param1 = 0,
				name = 'air',
				prob = 0
			},
			{
				param1 = 0,
				name = 'air',
				prob = 0
			},
			{
				param1 = 0,
				name = 'air',
				prob = 0
			},
			{
				param1 = 0,
				name = 'air',
				prob = 0
			},
			{
				param1 = 0,
				name = 'air',
				prob = 0
			},
			{
				param1 = 0,
				name = 'air',
				prob = 0
			},
			{
				param1 = 0,
				name = 'air',
				prob = 0
			},
			{
				param1 = 0,
				name = 'air',
				prob = 0
			},
			{
				param1 = 0,
				name = 'air',
				prob = 0
			},
			{
				param1 = 0,
				name = 'air',
				prob = 0
			},
			{
				param1 = 0,
				name = 'air',
				prob = 0
			},
			{
				param1 = 0,
				name = 'air',
				prob = 0
			},
			{
				param1 = 0,
				name = 'air',
				prob = 0
			},
			{
				param1 = 0,
				name = 'air',
				prob = 0
			},
			{
				param1 = 0,
				name = 'air',
				prob = 0
			},
			{
				param1 = 0,
				name = 'air',
				prob = 0
			},
			{
				param1 = 0,
				name = 'air',
				prob = 0
			},
			{
				name = 'ethereal:banana',
				param1 = 70
			},
			{
				name = 'ethereal:banana_trunk',
				param1 = 255
			},
			{
				name = 'ethereal:banana',
				param1 = 70
			},
			{
				param1 = 0,
				name = 'air',
				prob = 0
			},
			{
				param1 = 0,
				name = 'air',
				prob = 0
			},
			{
				param1 = 0,
				name = 'air',
				prob = 0
			},
			{
				param1 = 0,
				name = 'air',
				prob = 0
			},
			{
				name = 'ethereal:banana',
				param1 = 255
			},
			{
				name = 'ethereal:bananaleaves',
				param1 = 255
			},
			{
				name = 'ethereal:banana',
				param1 = 255
			},
			{
				param1 = 0,
				name = 'air',
				prob = 0
			},
			{
				param1 = 0,
				name = 'air',
				prob = 0
			},
			{
				param1 = 0,
				name = 'air',
				prob = 0
			},
			{
				name = 'ethereal:bananaleaves',
				param1 = 255
			},
			{
				name = 'ethereal:bananaleaves',
				param1 = 255
			},
			{
				name = 'ethereal:bananaleaves',
				param1 = 255
			},
			{
				name = 'ethereal:bananaleaves',
				param1 = 255
			},
			{
				name = 'ethereal:bananaleaves',
				param1 = 255
			},
			{
				param1 = 0,
				name = 'air',
				prob = 0
			},
			{
				name = 'ethereal:bananaleaves',
				param1 = 255
			},
			{
				name = 'ethereal:bananaleaves',
				param1 = 180
			},
			{
				param1 = 0,
				name = 'air',
				prob = 0
			},
			{
				name = 'ethereal:bananaleaves',
				param1 = 255
			},
			{
				param1 = 0,
				name = 'air',
				prob = 0
			},
			{
				name = 'ethereal:bananaleaves',
				param1 = 180
			},
			{
				name = 'ethereal:bananaleaves',
				param1 = 255
			},
			{
				param1 = 0,
				name = 'air',
				prob = 0
			},
			{
				param1 = 0,
				name = 'air',
				prob = 0
			},
			{
				param1 = 0,
				name = 'air',
				prob = 0
			},
			{
				name = 'ethereal:banana_trunk',
				param1 = 255
			},
			{
				param1 = 0,
				name = 'air',
				prob = 0
			},
			{
				param1 = 0,
				name = 'air',
				prob = 0
			},
			{
				param1 = 0,
				name = 'air',
				prob = 0
			},
			{
				param1 = 0,
				name = 'air',
				prob = 0
			},
			{
				param1 = 0,
				name = 'air',
				prob = 0
			},
			{
				param1 = 0,
				name = 'air',
				prob = 0
			},
			{
				name = 'ethereal:banana_trunk',
				param1 = 255
			},
			{
				param1 = 0,
				name = 'air',
				prob = 0
			},
			{
				param1 = 0,
				name = 'air',
				prob = 0
			},
			{
				param1 = 0,
				name = 'air',
				prob = 0
			},
			{
				param1 = 0,
				name = 'air',
				prob = 0
			},
			{
				param1 = 0,
				name = 'air',
				prob = 0
			},
			{
				param1 = 0,
				name = 'air',
				prob = 0
			},
			{
				name = 'ethereal:banana_trunk',
				param1 = 255
			},
			{
				param1 = 0,
				name = 'air',
				prob = 0
			},
			{
				param1 = 0,
				name = 'air',
				prob = 0
			},
			{
				param1 = 0,
				name = 'air',
				prob = 0
			},
			{
				param1 = 0,
				name = 'air',
				prob = 0
			},
			{
				param1 = 0,
				name = 'air',
				prob = 0
			},
			{
				param1 = 0,
				name = 'air',
				prob = 0
			},
			{
				name = 'ethereal:banana_trunk',
				param1 = 255
			},
			{
				param1 = 0,
				name = 'air',
				prob = 0
			},
			{
				param1 = 0,
				name = 'air',
				prob = 0
			},
			{
				param1 = 0,
				name = 'air',
				prob = 0
			},
			{
				param1 = 0,
				name = 'air',
				prob = 0
			},
			{
				param1 = 0,
				name = 'air',
				prob = 0
			},
			{
				param1 = 0,
				name = 'air',
				prob = 0
			},
			{
				name = 'ethereal:banana',
				param1 = 70
			},
			{
				param1 = 0,
				name = 'air',
				prob = 0
			},
			{
				param1 = 0,
				name = 'air',
				prob = 0
			},
			{
				param1 = 0,
				name = 'air',
				prob = 0
			},
			{
				param1 = 0,
				name = 'air',
				prob = 0
			},
			{
				param1 = 0,
				name = 'air',
				prob = 0
			},
			{
				param1 = 0,
				name = 'air',
				prob = 0
			},
			{
				name = 'ethereal:banana',
				param1 = 255
			},
			{
				param1 = 0,
				name = 'air',
				prob = 0
			},
			{
				param1 = 0,
				name = 'air',
				prob = 0
			},
			{
				param1 = 0,
				name = 'air',
				prob = 0
			},
			{
				param1 = 0,
				name = 'air',
				prob = 0
			},
			{
				param1 = 0,
				name = 'air',
				prob = 0
			},
			{
				param1 = 0,
				name = 'air',
				prob = 0
			},
			{
				name = 'ethereal:bananaleaves',
				param1 = 255
			},
			{
				param1 = 0,
				name = 'air',
				prob = 0
			},
			{
				param1 = 0,
				name = 'air',
				prob = 0
			},
			{
				param1 = 0,
				name = 'air',
				prob = 0
			},
			{
				param1 = 0,
				name = 'air',
				prob = 0
			},
			{
				param1 = 0,
				name = 'air',
				prob = 0
			},
			{
				param1 = 0,
				name = 'air',
				prob = 0
			},
			{
				param1 = 0,
				name = 'air',
				prob = 0
			},
			{
				param1 = 0,
				name = 'air',
				prob = 0
			},
			{
				param1 = 0,
				name = 'air',
				prob = 0
			},
			{
				param1 = 0,
				name = 'air',
				prob = 0
			},
			{
				param1 = 0,
				name = 'air',
				prob = 0
			},
			{
				param1 = 0,
				name = 'air',
				prob = 0
			},
			{
				param1 = 0,
				name = 'air',
				prob = 0
			},
			{
				param1 = 0,
				name = 'air',
				prob = 0
			},
			{
				param1 = 0,
				name = 'air',
				prob = 0
			},
			{
				param1 = 0,
				name = 'air',
				prob = 0
			},
			{
				param1 = 0,
				name = 'air',
				prob = 0
			},
			{
				param1 = 0,
				name = 'air',
				prob = 0
			},
			{
				param1 = 0,
				name = 'air',
				prob = 0
			},
			{
				param1 = 0,
				name = 'air',
				prob = 0
			},
			{
				param1 = 0,
				name = 'air',
				prob = 0
			},
			{
				param1 = 0,
				name = 'air',
				prob = 0
			},
			{
				param1 = 0,
				name = 'air',
				prob = 0
			},
			{
				param1 = 0,
				name = 'air',
				prob = 0
			},
			{
				param1 = 0,
				name = 'air',
				prob = 0
			},
			{
				param1 = 0,
				name = 'air',
				prob = 0
			},
			{
				param1 = 0,
				name = 'air',
				prob = 0
			},
			{
				param1 = 0,
				name = 'air',
				prob = 0
			},
			{
				param1 = 0,
				name = 'air',
				prob = 0
			},
			{
				param1 = 0,
				name = 'air',
				prob = 0
			},
			{
				param1 = 0,
				name = 'air',
				prob = 0
			},
			{
				param1 = 0,
				name = 'air',
				prob = 0
			},
			{
				param1 = 0,
				name = 'air',
				prob = 0
			},
			{
				param1 = 0,
				name = 'air',
				prob = 0
			},
			{
				param1 = 0,
				name = 'air',
				prob = 0
			},
			{
				param1 = 0,
				name = 'air',
				prob = 0
			},
			{
				param1 = 0,
				name = 'air',
				prob = 0
			},
			{
				param1 = 0,
				name = 'air',
				prob = 0
			},
			{
				param1 = 0,
				name = 'air',
				prob = 0
			},
			{
				param1 = 0,
				name = 'air',
				prob = 0
			},
			{
				param1 = 0,
				name = 'air',
				prob = 0
			},
			{
				param1 = 0,
				name = 'air',
				prob = 0
			},
			{
				param1 = 0,
				name = 'air',
				prob = 0
			},
			{
				param1 = 0,
				name = 'air',
				prob = 0
			},
			{
				param1 = 0,
				name = 'air',
				prob = 0
			},
			{
				param1 = 0,
				name = 'air',
				prob = 0
			},
			{
				param1 = 0,
				name = 'air',
				prob = 0
			},
			{
				param1 = 0,
				name = 'air',
				prob = 0
			},
			{
				param1 = 0,
				name = 'air',
				prob = 0
			},
			{
				param1 = 0,
				name = 'air',
				prob = 0
			},
			{
				param1 = 0,
				name = 'air',
				prob = 0
			},
			{
				param1 = 0,
				name = 'air',
				prob = 0
			},
			{
				param1 = 0,
				name = 'air',
				prob = 0
			},
			{
				param1 = 0,
				name = 'air',
				prob = 0
			},
			{
				param1 = 0,
				name = 'air',
				prob = 0
			},
			{
				name = 'ethereal:bananaleaves',
				param1 = 255
			},
			{
				param1 = 0,
				name = 'air',
				prob = 0
			},
			{
				param1 = 0,
				name = 'air',
				prob = 0
			},
			{
				param1 = 0,
				name = 'air',
				prob = 0
			},
			{
				param1 = 0,
				name = 'air',
				prob = 0
			},
			{
				param1 = 0,
				name = 'air',
				prob = 0
			},
			{
				param1 = 0,
				name = 'air',
				prob = 0
			},
			{
				name = 'ethereal:bananaleaves',
				param1 = 180
			},
			{
				param1 = 0,
				name = 'air',
				prob = 0
			},
			{
				param1 = 0,
				name = 'air',
				prob = 0
			},
			{
				param1 = 0,
				name = 'air',
				prob = 0
			},
			{
				param1 = 0,
				name = 'air',
				prob = 0
			},
			{
				param1 = 0,
				name = 'air',
				prob = 0
			},
			{
				param1 = 0,
				name = 'air',
				prob = 0
			},
			{
				param1 = 0,
				name = 'air',
				prob = 0
			},
			{
				param1 = 0,
				name = 'air',
				prob = 0
			},
			{
				param1 = 0,
				name = 'air',
				prob = 0
			},
			{
				param1 = 0,
				name = 'air',
				prob = 0
			},
			{
				param1 = 0,
				name = 'air',
				prob = 0
			},
			{
				param1 = 0,
				name = 'air',
				prob = 0
			},
			{
				param1 = 0,
				name = 'air',
				prob = 0
			},
			{
				param1 = 0,
				name = 'air',
				prob = 0
			},
			{
				param1 = 0,
				name = 'air',
				prob = 0
			},
			{
				param1 = 0,
				name = 'air',
				prob = 0
			},
			{
				param1 = 0,
				name = 'air',
				prob = 0
			},
			{
				param1 = 0,
				name = 'air',
				prob = 0
			},
			{
				param1 = 0,
				name = 'air',
				prob = 0
			},
			{
				param1 = 0,
				name = 'air',
				prob = 0
			},
			{
				param1 = 0,
				name = 'air',
				prob = 0
			},
			{
				param1 = 0,
				name = 'air',
				prob = 0
			},
			{
				param1 = 0,
				name = 'air',
				prob = 0
			},
			{
				param1 = 0,
				name = 'air',
				prob = 0
			},
			{
				param1 = 0,
				name = 'air',
				prob = 0
			},
			{
				param1 = 0,
				name = 'air',
				prob = 0
			},
			{
				param1 = 0,
				name = 'air',
				prob = 0
			},
			{
				param1 = 0,
				name = 'air',
				prob = 0
			},
			{
				param1 = 0,
				name = 'air',
				prob = 0
			},
			{
				param1 = 0,
				name = 'air',
				prob = 0
			},
			{
				param1 = 0,
				name = 'air',
				prob = 0
			},
			{
				param1 = 0,
				name = 'air',
				prob = 0
			},
			{
				param1 = 0,
				name = 'air',
				prob = 0
			},
			{
				param1 = 0,
				name = 'air',
				prob = 0
			},
			{
				param1 = 0,
				name = 'air',
				prob = 0
			},
			{
				param1 = 0,
				name = 'air',
				prob = 0
			},
			{
				param1 = 0,
				name = 'air',
				prob = 0
			},
			{
				param1 = 0,
				name = 'air',
				prob = 0
			},
			{
				param1 = 0,
				name = 'air',
				prob = 0
			},
			{
				param1 = 0,
				name = 'air',
				prob = 0
			},
			{
				param1 = 0,
				name = 'air',
				prob = 0
			},
			{
				param1 = 0,
				name = 'air',
				prob = 0
			},
			{
				param1 = 0,
				name = 'air',
				prob = 0
			},
			{
				param1 = 0,
				name = 'air',
				prob = 0
			},
			{
				param1 = 0,
				name = 'air',
				prob = 0
			},
			{
				param1 = 0,
				name = 'air',
				prob = 0
			},
			{
				param1 = 0,
				name = 'air',
				prob = 0
			},
			{
				param1 = 0,
				name = 'air',
				prob = 0
			},
			{
				param1 = 0,
				name = 'air',
				prob = 0
			},
			{
				param1 = 0,
				name = 'air',
				prob = 0
			},
			{
				param1 = 0,
				name = 'air',
				prob = 0
			},
			{
				param1 = 0,
				name = 'air',
				prob = 0
			},
			{
				param1 = 0,
				name = 'air',
				prob = 0
			},
			{
				param1 = 0,
				name = 'air',
				prob = 0
			},
			{
				param1 = 0,
				name = 'air',
				prob = 0
			},
			{
				name = 'ethereal:bananaleaves',
				param1 = 255
			},
			{
				param1 = 0,
				name = 'air',
				prob = 0
			},
			{
				param1 = 0,
				name = 'air',
				prob = 0
			},
			{
				param1 = 0,
				name = 'air',
				prob = 0
			},
			{
				param1 = 0,
				name = 'air',
				prob = 0
			},
			{
				param1 = 0,
				name = 'air',
				prob = 0
			},
			{
				param1 = 0,
				name = 'air',
				prob = 0
			},
			{
				param1 = 0,
				name = 'air',
				prob = 0
			},
			{
				param1 = 0,
				name = 'air',
				prob = 0
			},
			{
				param1 = 0,
				name = 'air',
				prob = 0
			},
			{
				param1 = 0,
				name = 'air',
				prob = 0
			},
			{
				param1 = 0,
				name = 'air',
				prob = 0
			},
			{
				param1 = 0,
				name = 'air',
				prob = 0
			},
			{
				param1 = 0,
				name = 'air',
				prob = 0
			},
			{
				param1 = 0,
				name = 'air',
				prob = 0
			},
			{
				param1 = 0,
				name = 'air',
				prob = 0
			},
			{
				param1 = 0,
				name = 'air',
				prob = 0
			},
			{
				param1 = 0,
				name = 'air',
				prob = 0
			},
			{
				param1 = 0,
				name = 'air',
				prob = 0
			},
			{
				param1 = 0,
				name = 'air',
				prob = 0
			},
			{
				param1 = 0,
				name = 'air',
				prob = 0
			},
			{
				param1 = 0,
				name = 'air',
				prob = 0
			},
			{
				param1 = 0,
				name = 'air',
				prob = 0
			},
			{
				param1 = 0,
				name = 'air',
				prob = 0
			},
			{
				param1 = 0,
				name = 'air',
				prob = 0
			},
			{
				param1 = 0,
				name = 'air',
				prob = 0
			},
			{
				param1 = 0,
				name = 'air',
				prob = 0
			},
			{
				param1 = 0,
				name = 'air',
				prob = 0
			},
			{
				param1 = 0,
				name = 'air',
				prob = 0
			},
			{
				param1 = 0,
				name = 'air',
				prob = 0
			},
			{
				param1 = 0,
				name = 'air',
				prob = 0
			},
			{
				param1 = 0,
				name = 'air',
				prob = 0
			},
			{
				param1 = 0,
				name = 'air',
				prob = 0
			},
			{
				param1 = 0,
				name = 'air',
				prob = 0
			},
			{
				param1 = 0,
				name = 'air',
				prob = 0
			},
			{
				param1 = 0,
				name = 'air',
				prob = 0
			},
			{
				param1 = 0,
				name = 'air',
				prob = 0
			},
			{
				param1 = 0,
				name = 'air',
				prob = 0
			},
			{
				param1 = 0,
				name = 'air',
				prob = 0
			},
			{
				param1 = 0,
				name = 'air',
				prob = 0
			},
			{
				param1 = 0,
				name = 'air',
				prob = 0
			},
			{
				param1 = 0,
				name = 'air',
				prob = 0
			},
			{
				param1 = 0,
				name = 'air',
				prob = 0
			},
			{
				param1 = 0,
				name = 'air',
				prob = 0
			},
			{
				param1 = 0,
				name = 'air',
				prob = 0
			},
			{
				param1 = 0,
				name = 'air',
				prob = 0
			},
			{
				param1 = 0,
				name = 'air',
				prob = 0
			},
			{
				param1 = 0,
				name = 'air',
				prob = 0
			},
			{
				param1 = 0,
				name = 'air',
				prob = 0
			},
			{
				param1 = 0,
				name = 'air',
				prob = 0
			},
			{
				param1 = 0,
				name = 'air',
				prob = 0
			},
			{
				param1 = 0,
				name = 'air',
				prob = 0
			},
			{
				param1 = 0,
				name = 'air',
				prob = 0
			},
			{
				param1 = 0,
				name = 'air',
				prob = 0
			},
			{
				param1 = 0,
				name = 'air',
				prob = 0
			},
			{
				param1 = 0,
				name = 'air',
				prob = 0
			},
			{
				param1 = 0,
				name = 'air',
				prob = 0
			},
			{
				param1 = 0,
				name = 'air',
				prob = 0
			},
			{
				param1 = 0,
				name = 'air',
				prob = 0
			},
			{
				param1 = 0,
				name = 'air',
				prob = 0
			}
		},
		size = {
			y = 8,
			x = 7,
			z = 7
		}
	}
})
mod.register_decoration({
	y_min = 1,
	biomes = {
		'sandstone_ocean'
	},
	schematic = {
		yslice_prob = {
			{
				prob = 127,
				ypos = 3
			}
		},
		data = {
			{
				prob = 0,
				name = 'air',
				param = 0
			},
			{
				prob = 0,
				name = 'air',
				param = 0
			},
			{
				prob = 0,
				name = 'air',
				param = 0
			},
			{
				prob = 0,
				name = 'air',
				param = 0
			},
			{
				prob = 0,
				name = 'air',
				param = 0
			},
			{
				prob = 0,
				name = 'air',
				param = 0
			},
			{
				prob = 0,
				name = 'air',
				param = 0
			},
			{
				prob = 0,
				name = 'air',
				param = 0
			},
			{
				prob = 0,
				name = 'air',
				param = 0
			},
			{
				prob = 0,
				name = 'air',
				param = 0
			},
			{
				prob = 0,
				name = 'air',
				param = 0
			},
			{
				prob = 0,
				name = 'air',
				param = 0
			},
			{
				prob = 0,
				name = 'air',
				param = 0
			},
			{
				prob = 0,
				name = 'air',
				param = 0
			},
			{
				prob = 0,
				name = 'air',
				param = 0
			},
			{
				prob = 0,
				name = 'air',
				param = 0
			},
			{
				prob = 0,
				name = 'air',
				param = 0
			},
			{
				prob = 0,
				name = 'air',
				param = 0
			},
			{
				prob = 0,
				name = 'air',
				param = 0
			},
			{
				prob = 0,
				name = 'air',
				param = 0
			},
			{
				prob = 0,
				name = 'air',
				param = 0
			},
			{
				prob = 0,
				name = 'air',
				param = 0
			},
			{
				prob = 0,
				name = 'air',
				param = 0
			},
			{
				prob = 0,
				name = 'air',
				param = 0
			},
			{
				prob = 0,
				name = 'air',
				param = 0
			},
			{
				prob = 0,
				name = 'air',
				param = 0
			},
			{
				prob = 0,
				name = 'air',
				param = 0
			},
			{
				prob = 0,
				name = 'air',
				param = 0
			},
			{
				prob = 0,
				name = 'air',
				param = 0
			},
			{
				prob = 0,
				name = 'air',
				param = 0
			},
			{
				prob = 0,
				name = 'air',
				param = 0
			},
			{
				prob = 0,
				name = 'air',
				param = 0
			},
			{
				prob = 0,
				name = 'air',
				param = 0
			},
			{
				prob = 0,
				name = 'air',
				param = 0
			},
			{
				prob = 0,
				name = 'air',
				param = 0
			},
			{
				prob = 0,
				name = 'air',
				param = 0
			},
			{
				prob = 0,
				name = 'air',
				param = 0
			},
			{
				prob = 0,
				name = 'air',
				param = 0
			},
			{
				prob = 0,
				name = 'air',
				param = 0
			},
			{
				prob = 0,
				name = 'air',
				param = 0
			},
			{
				prob = 0,
				name = 'air',
				param = 0
			},
			{
				prob = 0,
				name = 'air',
				param = 0
			},
			{
				prob = 0,
				name = 'air',
				param = 0
			},
			{
				prob = 0,
				name = 'air',
				param = 0
			},
			{
				prob = 0,
				name = 'air',
				param = 0
			},
			{
				prob = 0,
				name = 'air',
				param = 0
			},
			{
				prob = 0,
				name = 'air',
				param = 0
			},
			{
				prob = 0,
				name = 'air',
				param = 0
			},
			{
				prob = 0,
				name = 'air',
				param = 0
			},
			{
				prob = 0,
				name = 'air',
				param = 0
			},
			{
				prob = 0,
				name = 'air',
				param = 0
			},
			{
				prob = 0,
				name = 'air',
				param = 0
			},
			{
				prob = 0,
				name = 'air',
				param = 0
			},
			{
				prob = 0,
				name = 'air',
				param = 0
			},
			{
				prob = 0,
				name = 'air',
				param = 0
			},
			{
				prob = 0,
				name = 'air',
				param = 0
			},
			{
				prob = 0,
				name = 'air',
				param = 0
			},
			{
				prob = 0,
				name = 'air',
				param = 0
			},
			{
				prob = 0,
				name = 'air',
				param = 0
			},
			{
				prob = 0,
				name = 'air',
				param = 0
			},
			{
				prob = 0,
				name = 'air',
				param = 0
			},
			{
				prob = 0,
				name = 'air',
				param = 0
			},
			{
				prob = 0,
				name = 'air',
				param = 0
			},
			{
				prob = 0,
				name = 'air',
				param = 0
			},
			{
				prob = 0,
				name = 'air',
				param = 0
			},
			{
				prob = 0,
				name = 'air',
				param = 0
			},
			{
				prob = 0,
				name = 'air',
				param = 0
			},
			{
				prob = 0,
				name = 'air',
				param = 0
			},
			{
				prob = 0,
				name = 'air',
				param = 0
			},
			{
				prob = 0,
				name = 'air',
				param = 0
			},
			{
				prob = 0,
				name = 'air',
				param = 0
			},
			{
				prob = 0,
				name = 'air',
				param = 0
			},
			{
				prob = 0,
				name = 'air',
				param = 0
			},
			{
				prob = 0,
				name = 'air',
				param = 0
			},
			{
				prob = 0,
				name = 'air',
				param = 0
			},
			{
				prob = 0,
				name = 'air',
				param = 0
			},
			{
				prob = 0,
				name = 'air',
				param = 0
			},
			{
				prob = 0,
				name = 'air',
				param = 0
			},
			{
				prob = 0,
				name = 'air',
				param = 0
			},
			{
				prob = 0,
				name = 'air',
				param = 0
			},
			{
				prob = 0,
				name = 'air',
				param = 0
			},
			{
				prob = 0,
				name = 'air',
				param = 0
			},
			{
				prob = 0,
				name = 'air',
				param = 0
			},
			{
				prob = 0,
				name = 'air',
				param = 0
			},
			{
				prob = 0,
				name = 'air',
				param = 0
			},
			{
				prob = 0,
				name = 'air',
				param = 0
			},
			{
				prob = 0,
				name = 'air',
				param = 0
			},
			{
				prob = 0,
				name = 'air',
				param = 0
			},
			{
				prob = 0,
				name = 'air',
				param = 0
			},
			{
				prob = 0,
				name = 'air',
				param = 0
			},
			{
				prob = 0,
				name = 'air',
				param = 0
			},
			{
				prob = 0,
				name = 'air',
				param = 0
			},
			{
				prob = 0,
				name = 'air',
				param = 0
			},
			{
				prob = 0,
				name = 'air',
				param = 0
			},
			{
				prob = 0,
				name = 'air',
				param = 0
			},
			{
				prob = 0,
				name = 'air',
				param = 0
			},
			{
				prob = 0,
				name = 'air',
				param = 0
			},
			{
				prob = 0,
				name = 'air',
				param = 0
			},
			{
				prob = 0,
				name = 'air',
				param = 0
			},
			{
				prob = 0,
				name = 'air',
				param = 0
			},
			{
				prob = 0,
				name = 'air',
				param = 0
			},
			{
				prob = 0,
				name = 'air',
				param = 0
			},
			{
				prob = 0,
				name = 'air',
				param = 0
			},
			{
				prob = 0,
				name = 'air',
				param = 0
			},
			{
				prob = 0,
				name = 'air',
				param = 0
			},
			{
				prob = 0,
				name = 'air',
				param = 0
			},
			{
				prob = 0,
				name = 'air',
				param = 0
			},
			{
				prob = 0,
				name = 'air',
				param = 0
			},
			{
				prob = 0,
				name = 'air',
				param = 0
			},
			{
				prob = 0,
				name = 'air',
				param = 0
			},
			{
				prob = 0,
				name = 'air',
				param = 0
			},
			{
				prob = 0,
				name = 'air',
				param = 0
			},
			{
				prob = 0,
				name = 'air',
				param = 0
			},
			{
				prob = 0,
				name = 'air',
				param = 0
			},
			{
				prob = 0,
				name = 'air',
				param = 0
			},
			{
				prob = 0,
				name = 'air',
				param = 0
			},
			{
				prob = 0,
				name = 'air',
				param = 0
			},
			{
				prob = 0,
				name = 'air',
				param = 0
			},
			{
				prob = 0,
				name = 'air',
				param = 0
			},
			{
				prob = 0,
				name = 'air',
				param = 0
			},
			{
				prob = 0,
				name = 'air',
				param = 0
			},
			{
				prob = 0,
				name = 'air',
				param = 0
			},
			{
				prob = 0,
				name = 'air',
				param = 0
			},
			{
				prob = 0,
				name = 'air',
				param = 0
			},
			{
				prob = 0,
				name = 'air',
				param = 0
			},
			{
				prob = 0,
				name = 'air',
				param = 0
			},
			{
				prob = 0,
				name = 'air',
				param = 0
			},
			{
				prob = 0,
				name = 'air',
				param = 0
			},
			{
				prob = 0,
				name = 'air',
				param = 0
			},
			{
				prob = 0,
				name = 'air',
				param = 0
			},
			{
				prob = 0,
				name = 'air',
				param = 0
			},
			{
				name = 'ethereal:palmleaves',
				param = 191
			},
			{
				prob = 0,
				name = 'air',
				param = 0
			},
			{
				prob = 0,
				name = 'air',
				param = 0
			},
			{
				prob = 0,
				name = 'air',
				param = 0
			},
			{
				prob = 0,
				name = 'air',
				param = 0
			},
			{
				prob = 0,
				name = 'air',
				param = 0
			},
			{
				prob = 0,
				name = 'air',
				param = 0
			},
			{
				prob = 0,
				name = 'air',
				param = 0
			},
			{
				prob = 0,
				name = 'air',
				param = 0
			},
			{
				name = 'ethereal:palmleaves',
				param = 255
			},
			{
				prob = 0,
				name = 'air',
				param = 0
			},
			{
				prob = 0,
				name = 'air',
				param = 0
			},
			{
				prob = 0,
				name = 'air',
				param = 0
			},
			{
				prob = 0,
				name = 'air',
				param = 0
			},
			{
				prob = 0,
				name = 'air',
				param = 0
			},
			{
				prob = 0,
				name = 'air',
				param = 0
			},
			{
				prob = 0,
				name = 'air',
				param = 0
			},
			{
				prob = 0,
				name = 'air',
				param = 0
			},
			{
				prob = 0,
				name = 'air',
				param = 0
			},
			{
				prob = 0,
				name = 'air',
				param = 0
			},
			{
				prob = 0,
				name = 'air',
				param = 0
			},
			{
				prob = 0,
				name = 'air',
				param = 0
			},
			{
				prob = 0,
				name = 'air',
				param = 0
			},
			{
				prob = 0,
				name = 'air',
				param = 0
			},
			{
				prob = 0,
				name = 'air',
				param = 0
			},
			{
				prob = 0,
				name = 'air',
				param = 0
			},
			{
				prob = 0,
				name = 'air',
				param = 0
			},
			{
				prob = 0,
				name = 'air',
				param = 0
			},
			{
				prob = 0,
				name = 'air',
				param = 0
			},
			{
				prob = 0,
				name = 'air',
				param = 0
			},
			{
				prob = 0,
				name = 'air',
				param = 0
			},
			{
				prob = 0,
				name = 'air',
				param = 0
			},
			{
				prob = 0,
				name = 'air',
				param = 0
			},
			{
				prob = 0,
				name = 'air',
				param = 0
			},
			{
				prob = 0,
				name = 'air',
				param = 0
			},
			{
				prob = 0,
				name = 'air',
				param = 0
			},
			{
				prob = 0,
				name = 'air',
				param = 0
			},
			{
				prob = 0,
				name = 'air',
				param = 0
			},
			{
				prob = 0,
				name = 'air',
				param = 0
			},
			{
				prob = 0,
				name = 'air',
				param = 0
			},
			{
				prob = 0,
				name = 'air',
				param = 0
			},
			{
				prob = 0,
				name = 'air',
				param = 0
			},
			{
				prob = 0,
				name = 'air',
				param = 0
			},
			{
				prob = 0,
				name = 'air',
				param = 0
			},
			{
				prob = 0,
				name = 'air',
				param = 0
			},
			{
				prob = 0,
				name = 'air',
				param = 0
			},
			{
				prob = 0,
				name = 'air',
				param = 0
			},
			{
				prob = 0,
				name = 'air',
				param = 0
			},
			{
				prob = 0,
				name = 'air',
				param = 0
			},
			{
				prob = 0,
				name = 'air',
				param = 0
			},
			{
				prob = 0,
				name = 'air',
				param = 0
			},
			{
				prob = 0,
				name = 'air',
				param = 0
			},
			{
				prob = 0,
				name = 'air',
				param = 0
			},
			{
				prob = 0,
				name = 'air',
				param = 0
			},
			{
				prob = 0,
				name = 'air',
				param = 0
			},
			{
				prob = 0,
				name = 'air',
				param = 0
			},
			{
				prob = 0,
				name = 'air',
				param = 0
			},
			{
				prob = 0,
				name = 'air',
				param = 0
			},
			{
				prob = 0,
				name = 'air',
				param = 0
			},
			{
				prob = 0,
				name = 'air',
				param = 0
			},
			{
				prob = 0,
				name = 'air',
				param = 0
			},
			{
				prob = 0,
				name = 'air',
				param = 0
			},
			{
				prob = 0,
				name = 'air',
				param = 0
			},
			{
				prob = 0,
				name = 'air',
				param = 0
			},
			{
				prob = 0,
				name = 'air',
				param = 0
			},
			{
				prob = 0,
				name = 'air',
				param = 0
			},
			{
				prob = 0,
				name = 'air',
				param = 0
			},
			{
				prob = 0,
				name = 'air',
				param = 0
			},
			{
				prob = 0,
				name = 'air',
				param = 0
			},
			{
				prob = 0,
				name = 'air',
				param = 0
			},
			{
				prob = 0,
				name = 'air',
				param = 0
			},
			{
				prob = 0,
				name = 'air',
				param = 0
			},
			{
				prob = 0,
				name = 'air',
				param = 0
			},
			{
				prob = 0,
				name = 'air',
				param = 0
			},
			{
				prob = 0,
				name = 'air',
				param = 0
			},
			{
				prob = 0,
				name = 'air',
				param = 0
			},
			{
				prob = 0,
				name = 'air',
				param = 0
			},
			{
				prob = 0,
				name = 'air',
				param = 0
			},
			{
				prob = 0,
				name = 'air',
				param = 0
			},
			{
				prob = 0,
				name = 'air',
				param = 0
			},
			{
				prob = 0,
				name = 'air',
				param = 0
			},
			{
				prob = 0,
				name = 'air',
				param = 0
			},
			{
				prob = 0,
				name = 'air',
				param = 0
			},
			{
				prob = 0,
				name = 'air',
				param = 0
			},
			{
				prob = 0,
				name = 'air',
				param = 0
			},
			{
				prob = 0,
				name = 'air',
				param = 0
			},
			{
				prob = 0,
				name = 'air',
				param = 0
			},
			{
				prob = 0,
				name = 'air',
				param = 0
			},
			{
				prob = 0,
				name = 'air',
				param = 0
			},
			{
				prob = 0,
				name = 'air',
				param = 0
			},
			{
				name = 'ethereal:palmleaves',
				param = 255
			},
			{
				prob = 0,
				name = 'air',
				param = 0
			},
			{
				prob = 0,
				name = 'air',
				param = 0
			},
			{
				prob = 0,
				name = 'air',
				param = 0
			},
			{
				prob = 0,
				name = 'air',
				param = 0
			},
			{
				prob = 0,
				name = 'air',
				param = 0
			},
			{
				prob = 0,
				name = 'air',
				param = 0
			},
			{
				prob = 0,
				name = 'air',
				param = 0
			},
			{
				prob = 0,
				name = 'air',
				param = 0
			},
			{
				name = 'ethereal:palmleaves',
				param = 255
			},
			{
				prob = 0,
				name = 'air',
				param = 0
			},
			{
				prob = 0,
				name = 'air',
				param = 0
			},
			{
				prob = 0,
				name = 'air',
				param = 0
			},
			{
				prob = 0,
				name = 'air',
				param = 0
			},
			{
				prob = 0,
				name = 'air',
				param = 0
			},
			{
				prob = 0,
				name = 'air',
				param = 0
			},
			{
				prob = 0,
				name = 'air',
				param = 0
			},
			{
				prob = 0,
				name = 'air',
				param = 0
			},
			{
				prob = 0,
				name = 'air',
				param = 0
			},
			{
				prob = 0,
				name = 'air',
				param = 0
			},
			{
				prob = 0,
				name = 'air',
				param = 0
			},
			{
				prob = 0,
				name = 'air',
				param = 0
			},
			{
				prob = 0,
				name = 'air',
				param = 0
			},
			{
				prob = 0,
				name = 'air',
				param = 0
			},
			{
				prob = 0,
				name = 'air',
				param = 0
			},
			{
				prob = 0,
				name = 'air',
				param = 0
			},
			{
				prob = 0,
				name = 'air',
				param = 0
			},
			{
				prob = 0,
				name = 'air',
				param = 0
			},
			{
				prob = 0,
				name = 'air',
				param = 0
			},
			{
				prob = 0,
				name = 'air',
				param = 0
			},
			{
				prob = 0,
				name = 'air',
				param = 0
			},
			{
				prob = 0,
				name = 'air',
				param = 0
			},
			{
				prob = 0,
				name = 'air',
				param = 0
			},
			{
				prob = 0,
				name = 'air',
				param = 0
			},
			{
				prob = 0,
				name = 'air',
				param = 0
			},
			{
				prob = 0,
				name = 'air',
				param = 0
			},
			{
				prob = 0,
				name = 'air',
				param = 0
			},
			{
				prob = 0,
				name = 'air',
				param = 0
			},
			{
				prob = 0,
				name = 'air',
				param = 0
			},
			{
				prob = 0,
				name = 'air',
				param = 0
			},
			{
				prob = 0,
				name = 'air',
				param = 0
			},
			{
				prob = 0,
				name = 'air',
				param = 0
			},
			{
				prob = 0,
				name = 'air',
				param = 0
			},
			{
				prob = 0,
				name = 'air',
				param = 0
			},
			{
				prob = 0,
				name = 'air',
				param = 0
			},
			{
				prob = 0,
				name = 'air',
				param = 0
			},
			{
				prob = 0,
				name = 'air',
				param = 0
			},
			{
				prob = 0,
				name = 'air',
				param = 0
			},
			{
				prob = 0,
				name = 'air',
				param = 0
			},
			{
				prob = 0,
				name = 'air',
				param = 0
			},
			{
				prob = 0,
				name = 'air',
				param = 0
			},
			{
				prob = 0,
				name = 'air',
				param = 0
			},
			{
				prob = 0,
				name = 'air',
				param = 0
			},
			{
				prob = 0,
				name = 'air',
				param = 0
			},
			{
				prob = 0,
				name = 'air',
				param = 0
			},
			{
				prob = 0,
				name = 'air',
				param = 0
			},
			{
				prob = 0,
				name = 'air',
				param = 0
			},
			{
				prob = 0,
				name = 'air',
				param = 0
			},
			{
				prob = 0,
				name = 'air',
				param = 0
			},
			{
				prob = 0,
				name = 'air',
				param = 0
			},
			{
				prob = 0,
				name = 'air',
				param = 0
			},
			{
				prob = 0,
				name = 'air',
				param = 0
			},
			{
				prob = 0,
				name = 'air',
				param = 0
			},
			{
				prob = 0,
				name = 'air',
				param = 0
			},
			{
				prob = 0,
				name = 'air',
				param = 0
			},
			{
				prob = 0,
				name = 'air',
				param = 0
			},
			{
				prob = 0,
				name = 'air',
				param = 0
			},
			{
				prob = 0,
				name = 'air',
				param = 0
			},
			{
				prob = 0,
				name = 'air',
				param = 0
			},
			{
				prob = 0,
				name = 'air',
				param = 0
			},
			{
				prob = 0,
				name = 'air',
				param = 0
			},
			{
				prob = 0,
				name = 'air',
				param = 0
			},
			{
				prob = 0,
				name = 'air',
				param = 0
			},
			{
				prob = 0,
				name = 'air',
				param = 0
			},
			{
				prob = 0,
				name = 'air',
				param = 0
			},
			{
				prob = 0,
				name = 'air',
				param = 0
			},
			{
				prob = 0,
				name = 'air',
				param = 0
			},
			{
				prob = 0,
				name = 'air',
				param = 0
			},
			{
				prob = 0,
				name = 'air',
				param = 0
			},
			{
				prob = 0,
				name = 'air',
				param = 0
			},
			{
				prob = 0,
				name = 'air',
				param = 0
			},
			{
				name = 'ethereal:coconut',
				param = 127
			},
			{
				prob = 0,
				name = 'air',
				param = 0
			},
			{
				prob = 0,
				name = 'air',
				param = 0
			},
			{
				prob = 0,
				name = 'air',
				param = 0
			},
			{
				prob = 0,
				name = 'air',
				param = 0
			},
			{
				prob = 0,
				name = 'air',
				param = 0
			},
			{
				prob = 0,
				name = 'air',
				param = 0
			},
			{
				prob = 0,
				name = 'air',
				param = 0
			},
			{
				prob = 0,
				name = 'air',
				param = 0
			},
			{
				name = 'ethereal:palmleaves',
				param = 255
			},
			{
				prob = 0,
				name = 'air',
				param = 0
			},
			{
				prob = 0,
				name = 'air',
				param = 0
			},
			{
				prob = 0,
				name = 'air',
				param = 0
			},
			{
				prob = 0,
				name = 'air',
				param = 0
			},
			{
				prob = 0,
				name = 'air',
				param = 0
			},
			{
				prob = 0,
				name = 'air',
				param = 0
			},
			{
				prob = 0,
				name = 'air',
				param = 0
			},
			{
				prob = 0,
				name = 'air',
				param = 0
			},
			{
				prob = 0,
				name = 'air',
				param = 0
			},
			{
				prob = 0,
				name = 'air',
				param = 0
			},
			{
				prob = 0,
				name = 'air',
				param = 0
			},
			{
				prob = 0,
				name = 'air',
				param = 0
			},
			{
				prob = 0,
				name = 'air',
				param = 0
			},
			{
				prob = 0,
				name = 'air',
				param = 0
			},
			{
				prob = 0,
				name = 'air',
				param = 0
			},
			{
				prob = 0,
				name = 'air',
				param = 0
			},
			{
				name = 'ethereal:palm_trunk',
				param = 255
			},
			{
				prob = 0,
				name = 'air',
				param = 0
			},
			{
				prob = 0,
				name = 'air',
				param = 0
			},
			{
				prob = 0,
				name = 'air',
				param = 0
			},
			{
				prob = 0,
				name = 'air',
				param = 0
			},
			{
				prob = 0,
				name = 'air',
				param = 0
			},
			{
				prob = 0,
				name = 'air',
				param = 0
			},
			{
				prob = 0,
				name = 'air',
				param = 0
			},
			{
				prob = 0,
				name = 'air',
				param = 0
			},
			{
				name = 'ethereal:palm_trunk',
				param = 255
			},
			{
				prob = 0,
				name = 'air',
				param = 0
			},
			{
				prob = 0,
				name = 'air',
				param = 0
			},
			{
				prob = 0,
				name = 'air',
				param = 0
			},
			{
				prob = 0,
				name = 'air',
				param = 0
			},
			{
				prob = 0,
				name = 'air',
				param = 0
			},
			{
				prob = 0,
				name = 'air',
				param = 0
			},
			{
				prob = 0,
				name = 'air',
				param = 0
			},
			{
				prob = 0,
				name = 'air',
				param = 0
			},
			{
				name = 'ethereal:palm_trunk',
				param = 255
			},
			{
				prob = 0,
				name = 'air',
				param = 0
			},
			{
				prob = 0,
				name = 'air',
				param = 0
			},
			{
				prob = 0,
				name = 'air',
				param = 0
			},
			{
				prob = 0,
				name = 'air',
				param = 0
			},
			{
				prob = 0,
				name = 'air',
				param = 0
			},
			{
				prob = 0,
				name = 'air',
				param = 0
			},
			{
				prob = 0,
				name = 'air',
				param = 0
			},
			{
				prob = 0,
				name = 'air',
				param = 0
			},
			{
				name = 'ethereal:palm_trunk',
				param = 255
			},
			{
				name = 'ethereal:palm_trunk',
				param = 191
			},
			{
				prob = 0,
				name = 'air',
				param = 0
			},
			{
				prob = 0,
				name = 'air',
				param = 0
			},
			{
				prob = 0,
				name = 'air',
				param = 0
			},
			{
				prob = 0,
				name = 'air',
				param = 0
			},
			{
				prob = 0,
				name = 'air',
				param = 0
			},
			{
				prob = 0,
				name = 'air',
				param = 0
			},
			{
				prob = 0,
				name = 'air',
				param = 0
			},
			{
				prob = 0,
				name = 'air',
				param = 0
			},
			{
				name = 'ethereal:palm_trunk',
				param = 255
			},
			{
				prob = 0,
				name = 'air',
				param = 0
			},
			{
				prob = 0,
				name = 'air',
				param = 0
			},
			{
				prob = 0,
				name = 'air',
				param = 0
			},
			{
				prob = 0,
				name = 'air',
				param = 0
			},
			{
				prob = 0,
				name = 'air',
				param = 0
			},
			{
				name = 'ethereal:palmleaves',
				param = 191
			},
			{
				prob = 0,
				name = 'air',
				param = 0
			},
			{
				prob = 0,
				name = 'air',
				param = 0
			},
			{
				name = 'ethereal:palm_trunk',
				param = 255
			},
			{
				prob = 0,
				name = 'air',
				param = 0
			},
			{
				prob = 0,
				name = 'air',
				param = 0
			},
			{
				name = 'ethereal:palmleaves',
				param = 191
			},
			{
				prob = 0,
				name = 'air',
				param = 0
			},
			{
				prob = 0,
				name = 'air',
				param = 0
			},
			{
				name = 'ethereal:palmleaves',
				param = 255
			},
			{
				name = 'ethereal:palmleaves',
				param = 255
			},
			{
				name = 'ethereal:coconut',
				param = 127
			},
			{
				name = 'ethereal:palm_trunk',
				param = 255
			},
			{
				name = 'ethereal:coconut',
				param = 127
			},
			{
				name = 'ethereal:palmleaves',
				param = 255
			},
			{
				name = 'ethereal:palmleaves',
				param = 255
			},
			{
				prob = 0,
				name = 'air',
				param = 0
			},
			{
				prob = 0,
				name = 'air',
				param = 0
			},
			{
				prob = 0,
				name = 'air',
				param = 0
			},
			{
				name = 'ethereal:palmleaves',
				param = 255
			},
			{
				name = 'ethereal:palmleaves',
				param = 255
			},
			{
				name = 'ethereal:palmleaves',
				param = 255
			},
			{
				name = 'ethereal:palmleaves',
				param = 255
			},
			{
				name = 'ethereal:palmleaves',
				param = 255
			},
			{
				prob = 0,
				name = 'air',
				param = 0
			},
			{
				prob = 0,
				name = 'air',
				param = 0
			},
			{
				prob = 0,
				name = 'air',
				param = 0
			},
			{
				prob = 0,
				name = 'air',
				param = 0
			},
			{
				prob = 0,
				name = 'air',
				param = 0
			},
			{
				prob = 0,
				name = 'air',
				param = 0
			},
			{
				name = 'ethereal:palmleaves',
				param = 255
			},
			{
				prob = 0,
				name = 'air',
				param = 0
			},
			{
				prob = 0,
				name = 'air',
				param = 0
			},
			{
				prob = 0,
				name = 'air',
				param = 0
			},
			{
				prob = 0,
				name = 'air',
				param = 0
			},
			{
				prob = 0,
				name = 'air',
				param = 0
			},
			{
				prob = 0,
				name = 'air',
				param = 0
			},
			{
				prob = 0,
				name = 'air',
				param = 0
			},
			{
				prob = 0,
				name = 'air',
				param = 0
			},
			{
				prob = 0,
				name = 'air',
				param = 0
			},
			{
				prob = 0,
				name = 'air',
				param = 0
			},
			{
				prob = 0,
				name = 'air',
				param = 0
			},
			{
				prob = 0,
				name = 'air',
				param = 0
			},
			{
				prob = 0,
				name = 'air',
				param = 0
			},
			{
				prob = 0,
				name = 'air',
				param = 0
			},
			{
				prob = 0,
				name = 'air',
				param = 0
			},
			{
				prob = 0,
				name = 'air',
				param = 0
			},
			{
				prob = 0,
				name = 'air',
				param = 0
			},
			{
				prob = 0,
				name = 'air',
				param = 0
			},
			{
				prob = 0,
				name = 'air',
				param = 0
			},
			{
				prob = 0,
				name = 'air',
				param = 0
			},
			{
				prob = 0,
				name = 'air',
				param = 0
			},
			{
				prob = 0,
				name = 'air',
				param = 0
			},
			{
				prob = 0,
				name = 'air',
				param = 0
			},
			{
				prob = 0,
				name = 'air',
				param = 0
			},
			{
				prob = 0,
				name = 'air',
				param = 0
			},
			{
				prob = 0,
				name = 'air',
				param = 0
			},
			{
				prob = 0,
				name = 'air',
				param = 0
			},
			{
				prob = 0,
				name = 'air',
				param = 0
			},
			{
				prob = 0,
				name = 'air',
				param = 0
			},
			{
				prob = 0,
				name = 'air',
				param = 0
			},
			{
				prob = 0,
				name = 'air',
				param = 0
			},
			{
				prob = 0,
				name = 'air',
				param = 0
			},
			{
				prob = 0,
				name = 'air',
				param = 0
			},
			{
				prob = 0,
				name = 'air',
				param = 0
			},
			{
				prob = 0,
				name = 'air',
				param = 0
			},
			{
				prob = 0,
				name = 'air',
				param = 0
			},
			{
				prob = 0,
				name = 'air',
				param = 0
			},
			{
				prob = 0,
				name = 'air',
				param = 0
			},
			{
				prob = 0,
				name = 'air',
				param = 0
			},
			{
				prob = 0,
				name = 'air',
				param = 0
			},
			{
				prob = 0,
				name = 'air',
				param = 0
			},
			{
				prob = 0,
				name = 'air',
				param = 0
			},
			{
				prob = 0,
				name = 'air',
				param = 0
			},
			{
				prob = 0,
				name = 'air',
				param = 0
			},
			{
				prob = 0,
				name = 'air',
				param = 0
			},
			{
				prob = 0,
				name = 'air',
				param = 0
			},
			{
				prob = 0,
				name = 'air',
				param = 0
			},
			{
				prob = 0,
				name = 'air',
				param = 0
			},
			{
				prob = 0,
				name = 'air',
				param = 0
			},
			{
				prob = 0,
				name = 'air',
				param = 0
			},
			{
				prob = 0,
				name = 'air',
				param = 0
			},
			{
				prob = 0,
				name = 'air',
				param = 0
			},
			{
				prob = 0,
				name = 'air',
				param = 0
			},
			{
				prob = 0,
				name = 'air',
				param = 0
			},
			{
				prob = 0,
				name = 'air',
				param = 0
			},
			{
				prob = 0,
				name = 'air',
				param = 0
			},
			{
				prob = 0,
				name = 'air',
				param = 0
			},
			{
				prob = 0,
				name = 'air',
				param = 0
			},
			{
				prob = 0,
				name = 'air',
				param = 0
			},
			{
				prob = 0,
				name = 'air',
				param = 0
			},
			{
				prob = 0,
				name = 'air',
				param = 0
			},
			{
				prob = 0,
				name = 'air',
				param = 0
			},
			{
				name = 'ethereal:coconut',
				param = 127
			},
			{
				prob = 0,
				name = 'air',
				param = 0
			},
			{
				prob = 0,
				name = 'air',
				param = 0
			},
			{
				prob = 0,
				name = 'air',
				param = 0
			},
			{
				prob = 0,
				name = 'air',
				param = 0
			},
			{
				prob = 0,
				name = 'air',
				param = 0
			},
			{
				prob = 0,
				name = 'air',
				param = 0
			},
			{
				prob = 0,
				name = 'air',
				param = 0
			},
			{
				prob = 0,
				name = 'air',
				param = 0
			},
			{
				name = 'ethereal:palmleaves',
				param = 255
			},
			{
				prob = 0,
				name = 'air',
				param = 0
			},
			{
				prob = 0,
				name = 'air',
				param = 0
			},
			{
				prob = 0,
				name = 'air',
				param = 0
			},
			{
				prob = 0,
				name = 'air',
				param = 0
			},
			{
				prob = 0,
				name = 'air',
				param = 0
			},
			{
				prob = 0,
				name = 'air',
				param = 0
			},
			{
				prob = 0,
				name = 'air',
				param = 0
			},
			{
				prob = 0,
				name = 'air',
				param = 0
			},
			{
				prob = 0,
				name = 'air',
				param = 0
			},
			{
				prob = 0,
				name = 'air',
				param = 0
			},
			{
				prob = 0,
				name = 'air',
				param = 0
			},
			{
				prob = 0,
				name = 'air',
				param = 0
			},
			{
				prob = 0,
				name = 'air',
				param = 0
			},
			{
				prob = 0,
				name = 'air',
				param = 0
			},
			{
				prob = 0,
				name = 'air',
				param = 0
			},
			{
				prob = 0,
				name = 'air',
				param = 0
			},
			{
				prob = 0,
				name = 'air',
				param = 0
			},
			{
				prob = 0,
				name = 'air',
				param = 0
			},
			{
				prob = 0,
				name = 'air',
				param = 0
			},
			{
				prob = 0,
				name = 'air',
				param = 0
			},
			{
				prob = 0,
				name = 'air',
				param = 0
			},
			{
				prob = 0,
				name = 'air',
				param = 0
			},
			{
				prob = 0,
				name = 'air',
				param = 0
			},
			{
				prob = 0,
				name = 'air',
				param = 0
			},
			{
				prob = 0,
				name = 'air',
				param = 0
			},
			{
				prob = 0,
				name = 'air',
				param = 0
			},
			{
				prob = 0,
				name = 'air',
				param = 0
			},
			{
				prob = 0,
				name = 'air',
				param = 0
			},
			{
				prob = 0,
				name = 'air',
				param = 0
			},
			{
				prob = 0,
				name = 'air',
				param = 0
			},
			{
				prob = 0,
				name = 'air',
				param = 0
			},
			{
				prob = 0,
				name = 'air',
				param = 0
			},
			{
				prob = 0,
				name = 'air',
				param = 0
			},
			{
				prob = 0,
				name = 'air',
				param = 0
			},
			{
				prob = 0,
				name = 'air',
				param = 0
			},
			{
				prob = 0,
				name = 'air',
				param = 0
			},
			{
				prob = 0,
				name = 'air',
				param = 0
			},
			{
				prob = 0,
				name = 'air',
				param = 0
			},
			{
				prob = 0,
				name = 'air',
				param = 0
			},
			{
				prob = 0,
				name = 'air',
				param = 0
			},
			{
				prob = 0,
				name = 'air',
				param = 0
			},
			{
				prob = 0,
				name = 'air',
				param = 0
			},
			{
				prob = 0,
				name = 'air',
				param = 0
			},
			{
				prob = 0,
				name = 'air',
				param = 0
			},
			{
				prob = 0,
				name = 'air',
				param = 0
			},
			{
				prob = 0,
				name = 'air',
				param = 0
			},
			{
				prob = 0,
				name = 'air',
				param = 0
			},
			{
				prob = 0,
				name = 'air',
				param = 0
			},
			{
				prob = 0,
				name = 'air',
				param = 0
			},
			{
				prob = 0,
				name = 'air',
				param = 0
			},
			{
				prob = 0,
				name = 'air',
				param = 0
			},
			{
				prob = 0,
				name = 'air',
				param = 0
			},
			{
				prob = 0,
				name = 'air',
				param = 0
			},
			{
				prob = 0,
				name = 'air',
				param = 0
			},
			{
				prob = 0,
				name = 'air',
				param = 0
			},
			{
				prob = 0,
				name = 'air',
				param = 0
			},
			{
				prob = 0,
				name = 'air',
				param = 0
			},
			{
				prob = 0,
				name = 'air',
				param = 0
			},
			{
				prob = 0,
				name = 'air',
				param = 0
			},
			{
				prob = 0,
				name = 'air',
				param = 0
			},
			{
				prob = 0,
				name = 'air',
				param = 0
			},
			{
				prob = 0,
				name = 'air',
				param = 0
			},
			{
				prob = 0,
				name = 'air',
				param = 0
			},
			{
				prob = 0,
				name = 'air',
				param = 0
			},
			{
				prob = 0,
				name = 'air',
				param = 0
			},
			{
				prob = 0,
				name = 'air',
				param = 0
			},
			{
				prob = 0,
				name = 'air',
				param = 0
			},
			{
				prob = 0,
				name = 'air',
				param = 0
			},
			{
				prob = 0,
				name = 'air',
				param = 0
			},
			{
				prob = 0,
				name = 'air',
				param = 0
			},
			{
				prob = 0,
				name = 'air',
				param = 0
			},
			{
				name = 'ethereal:palmleaves',
				param = 255
			},
			{
				prob = 0,
				name = 'air',
				param = 0
			},
			{
				prob = 0,
				name = 'air',
				param = 0
			},
			{
				prob = 0,
				name = 'air',
				param = 0
			},
			{
				prob = 0,
				name = 'air',
				param = 0
			},
			{
				prob = 0,
				name = 'air',
				param = 0
			},
			{
				prob = 0,
				name = 'air',
				param = 0
			},
			{
				prob = 0,
				name = 'air',
				param = 0
			},
			{
				prob = 0,
				name = 'air',
				param = 0
			},
			{
				name = 'ethereal:palmleaves',
				param = 255
			},
			{
				prob = 0,
				name = 'air',
				param = 0
			},
			{
				prob = 0,
				name = 'air',
				param = 0
			},
			{
				prob = 0,
				name = 'air',
				param = 0
			},
			{
				prob = 0,
				name = 'air',
				param = 0
			},
			{
				prob = 0,
				name = 'air',
				param = 0
			},
			{
				prob = 0,
				name = 'air',
				param = 0
			},
			{
				prob = 0,
				name = 'air',
				param = 0
			},
			{
				prob = 0,
				name = 'air',
				param = 0
			},
			{
				prob = 0,
				name = 'air',
				param = 0
			},
			{
				prob = 0,
				name = 'air',
				param = 0
			},
			{
				prob = 0,
				name = 'air',
				param = 0
			},
			{
				prob = 0,
				name = 'air',
				param = 0
			},
			{
				prob = 0,
				name = 'air',
				param = 0
			},
			{
				prob = 0,
				name = 'air',
				param = 0
			},
			{
				prob = 0,
				name = 'air',
				param = 0
			},
			{
				prob = 0,
				name = 'air',
				param = 0
			},
			{
				prob = 0,
				name = 'air',
				param = 0
			},
			{
				prob = 0,
				name = 'air',
				param = 0
			},
			{
				prob = 0,
				name = 'air',
				param = 0
			},
			{
				prob = 0,
				name = 'air',
				param = 0
			},
			{
				prob = 0,
				name = 'air',
				param = 0
			},
			{
				prob = 0,
				name = 'air',
				param = 0
			},
			{
				prob = 0,
				name = 'air',
				param = 0
			},
			{
				prob = 0,
				name = 'air',
				param = 0
			},
			{
				prob = 0,
				name = 'air',
				param = 0
			},
			{
				prob = 0,
				name = 'air',
				param = 0
			},
			{
				prob = 0,
				name = 'air',
				param = 0
			},
			{
				prob = 0,
				name = 'air',
				param = 0
			},
			{
				prob = 0,
				name = 'air',
				param = 0
			},
			{
				prob = 0,
				name = 'air',
				param = 0
			},
			{
				prob = 0,
				name = 'air',
				param = 0
			},
			{
				prob = 0,
				name = 'air',
				param = 0
			},
			{
				prob = 0,
				name = 'air',
				param = 0
			},
			{
				prob = 0,
				name = 'air',
				param = 0
			},
			{
				prob = 0,
				name = 'air',
				param = 0
			},
			{
				prob = 0,
				name = 'air',
				param = 0
			},
			{
				prob = 0,
				name = 'air',
				param = 0
			},
			{
				prob = 0,
				name = 'air',
				param = 0
			},
			{
				prob = 0,
				name = 'air',
				param = 0
			},
			{
				prob = 0,
				name = 'air',
				param = 0
			},
			{
				prob = 0,
				name = 'air',
				param = 0
			},
			{
				prob = 0,
				name = 'air',
				param = 0
			},
			{
				prob = 0,
				name = 'air',
				param = 0
			},
			{
				prob = 0,
				name = 'air',
				param = 0
			},
			{
				prob = 0,
				name = 'air',
				param = 0
			},
			{
				prob = 0,
				name = 'air',
				param = 0
			},
			{
				prob = 0,
				name = 'air',
				param = 0
			},
			{
				prob = 0,
				name = 'air',
				param = 0
			},
			{
				prob = 0,
				name = 'air',
				param = 0
			},
			{
				prob = 0,
				name = 'air',
				param = 0
			},
			{
				prob = 0,
				name = 'air',
				param = 0
			},
			{
				prob = 0,
				name = 'air',
				param = 0
			},
			{
				prob = 0,
				name = 'air',
				param = 0
			},
			{
				prob = 0,
				name = 'air',
				param = 0
			},
			{
				prob = 0,
				name = 'air',
				param = 0
			},
			{
				prob = 0,
				name = 'air',
				param = 0
			},
			{
				prob = 0,
				name = 'air',
				param = 0
			},
			{
				prob = 0,
				name = 'air',
				param = 0
			},
			{
				prob = 0,
				name = 'air',
				param = 0
			},
			{
				prob = 0,
				name = 'air',
				param = 0
			},
			{
				prob = 0,
				name = 'air',
				param = 0
			},
			{
				prob = 0,
				name = 'air',
				param = 0
			},
			{
				name = 'ethereal:palmleaves',
				param = 191
			},
			{
				prob = 0,
				name = 'air',
				param = 0
			},
			{
				prob = 0,
				name = 'air',
				param = 0
			},
			{
				prob = 0,
				name = 'air',
				param = 0
			},
			{
				prob = 0,
				name = 'air',
				param = 0
			},
			{
				prob = 0,
				name = 'air',
				param = 0
			},
			{
				prob = 0,
				name = 'air',
				param = 0
			},
			{
				prob = 0,
				name = 'air',
				param = 0
			},
			{
				prob = 0,
				name = 'air',
				param = 0
			},
			{
				name = 'ethereal:palmleaves',
				param = 255
			},
			{
				prob = 0,
				name = 'air',
				param = 0
			},
			{
				prob = 0,
				name = 'air',
				param = 0
			},
			{
				prob = 0,
				name = 'air',
				param = 0
			},
			{
				prob = 0,
				name = 'air',
				param = 0
			},
			{
				prob = 0,
				name = 'air',
				param = 0
			},
			{
				prob = 0,
				name = 'air',
				param = 0
			},
			{
				prob = 0,
				name = 'air',
				param = 0
			},
			{
				prob = 0,
				name = 'air',
				param = 0
			},
			{
				prob = 0,
				name = 'air',
				param = 0
			},
			{
				prob = 0,
				name = 'air',
				param = 0
			},
			{
				prob = 0,
				name = 'air',
				param = 0
			},
			{
				prob = 0,
				name = 'air',
				param = 0
			},
			{
				prob = 0,
				name = 'air',
				param = 0
			},
			{
				prob = 0,
				name = 'air',
				param = 0
			},
			{
				prob = 0,
				name = 'air',
				param = 0
			},
			{
				prob = 0,
				name = 'air',
				param = 0
			},
			{
				prob = 0,
				name = 'air',
				param = 0
			},
			{
				prob = 0,
				name = 'air',
				param = 0
			},
			{
				prob = 0,
				name = 'air',
				param = 0
			},
			{
				prob = 0,
				name = 'air',
				param = 0
			},
			{
				prob = 0,
				name = 'air',
				param = 0
			},
			{
				prob = 0,
				name = 'air',
				param = 0
			},
			{
				prob = 0,
				name = 'air',
				param = 0
			},
			{
				prob = 0,
				name = 'air',
				param = 0
			},
			{
				prob = 0,
				name = 'air',
				param = 0
			},
			{
				prob = 0,
				name = 'air',
				param = 0
			},
			{
				prob = 0,
				name = 'air',
				param = 0
			},
			{
				prob = 0,
				name = 'air',
				param = 0
			},
			{
				prob = 0,
				name = 'air',
				param = 0
			},
			{
				prob = 0,
				name = 'air',
				param = 0
			},
			{
				prob = 0,
				name = 'air',
				param = 0
			},
			{
				prob = 0,
				name = 'air',
				param = 0
			},
			{
				prob = 0,
				name = 'air',
				param = 0
			},
			{
				prob = 0,
				name = 'air',
				param = 0
			},
			{
				prob = 0,
				name = 'air',
				param = 0
			},
			{
				prob = 0,
				name = 'air',
				param = 0
			},
			{
				prob = 0,
				name = 'air',
				param = 0
			},
			{
				prob = 0,
				name = 'air',
				param = 0
			},
			{
				prob = 0,
				name = 'air',
				param = 0
			},
			{
				prob = 0,
				name = 'air',
				param = 0
			},
			{
				prob = 0,
				name = 'air',
				param = 0
			},
			{
				prob = 0,
				name = 'air',
				param = 0
			},
			{
				prob = 0,
				name = 'air',
				param = 0
			},
			{
				prob = 0,
				name = 'air',
				param = 0
			},
			{
				prob = 0,
				name = 'air',
				param = 0
			},
			{
				prob = 0,
				name = 'air',
				param = 0
			},
			{
				prob = 0,
				name = 'air',
				param = 0
			},
			{
				prob = 0,
				name = 'air',
				param = 0
			},
			{
				prob = 0,
				name = 'air',
				param = 0
			},
			{
				prob = 0,
				name = 'air',
				param = 0
			},
			{
				prob = 0,
				name = 'air',
				param = 0
			},
			{
				prob = 0,
				name = 'air',
				param = 0
			},
			{
				prob = 0,
				name = 'air',
				param = 0
			},
			{
				prob = 0,
				name = 'air',
				param = 0
			},
			{
				prob = 0,
				name = 'air',
				param = 0
			},
			{
				prob = 0,
				name = 'air',
				param = 0
			},
			{
				prob = 0,
				name = 'air',
				param = 0
			},
			{
				prob = 0,
				name = 'air',
				param = 0
			},
			{
				prob = 0,
				name = 'air',
				param = 0
			},
			{
				prob = 0,
				name = 'air',
				param = 0
			},
			{
				prob = 0,
				name = 'air',
				param = 0
			},
			{
				prob = 0,
				name = 'air',
				param = 0
			},
			{
				prob = 0,
				name = 'air',
				param = 0
			},
			{
				prob = 0,
				name = 'air',
				param = 0
			},
			{
				prob = 0,
				name = 'air',
				param = 0
			},
			{
				prob = 0,
				name = 'air',
				param = 0
			},
			{
				prob = 0,
				name = 'air',
				param = 0
			},
			{
				prob = 0,
				name = 'air',
				param = 0
			},
			{
				prob = 0,
				name = 'air',
				param = 0
			},
			{
				prob = 0,
				name = 'air',
				param = 0
			},
			{
				prob = 0,
				name = 'air',
				param = 0
			},
			{
				prob = 0,
				name = 'air',
				param = 0
			},
			{
				prob = 0,
				name = 'air',
				param = 0
			},
			{
				prob = 0,
				name = 'air',
				param = 0
			},
			{
				prob = 0,
				name = 'air',
				param = 0
			},
			{
				prob = 0,
				name = 'air',
				param = 0
			},
			{
				prob = 0,
				name = 'air',
				param = 0
			},
			{
				prob = 0,
				name = 'air',
				param = 0
			},
			{
				prob = 0,
				name = 'air',
				param = 0
			},
			{
				prob = 0,
				name = 'air',
				param = 0
			},
			{
				prob = 0,
				name = 'air',
				param = 0
			},
			{
				prob = 0,
				name = 'air',
				param = 0
			},
			{
				prob = 0,
				name = 'air',
				param = 0
			},
			{
				prob = 0,
				name = 'air',
				param = 0
			},
			{
				prob = 0,
				name = 'air',
				param = 0
			},
			{
				prob = 0,
				name = 'air',
				param = 0
			},
			{
				prob = 0,
				name = 'air',
				param = 0
			},
			{
				prob = 0,
				name = 'air',
				param = 0
			},
			{
				prob = 0,
				name = 'air',
				param = 0
			},
			{
				prob = 0,
				name = 'air',
				param = 0
			},
			{
				prob = 0,
				name = 'air',
				param = 0
			},
			{
				prob = 0,
				name = 'air',
				param = 0
			},
			{
				prob = 0,
				name = 'air',
				param = 0
			},
			{
				prob = 0,
				name = 'air',
				param = 0
			},
			{
				prob = 0,
				name = 'air',
				param = 0
			},
			{
				prob = 0,
				name = 'air',
				param = 0
			},
			{
				prob = 0,
				name = 'air',
				param = 0
			},
			{
				prob = 0,
				name = 'air',
				param = 0
			},
			{
				prob = 0,
